Workbook
Name BaseYear: 'Cover Page'!$C$63
Name CompanyName: 'Cover Page'!$B$2
Name CurrentPrice: 'DCF & Sensitivity'!$D$55
Name ExitMultiple: Assumptions!$D$89
Name FirstForecastYear: 'Cover Page'!$C$64
Name NetDebt: 'DCF & Sensitivity'!$D$48
Name ScenarioRange: Assumptions!$E$9:$G$9
Name SharesOut: 'DCF & Sensitivity'!$D$51
Name TaxRate: 'DCF & Sensitivity'!$D$16
Name TerminalGrowth: Assumptions!$D$88
Name Ticker: 'Cover Page'!$B$3
Name WACC: Assumptions!$D$87

Sheet Cover Page
B2: BRINKER INTERNATIONAL, INC.
B3: NYSE: EAT
B4: Casual Dining — Chili's Grill & Bar, Maggiano's Little Italy
B6: Company Overview
B7: Sector | C7: Consumer Discretionary: Casual Dining Restaurants
B8: Brands | C8: Chili's Grill & Bar (1,576 restaurants), Maggiano's Little Italy (52 restaurants)
B9: Footprint | C9: 1,628 system-wide units; 1,162 Co-owned + 466 franchised; US + 27 intl countries
B10: Revenue Model | C10: ~99% Company sales (food/beverage/banquet); ~1% franchise royalties & fees
B11: Capital Structure | C11: $426M LT debt ($350M 8.25% sr notes due 2030 + finance leases); $1.0B revolver undrawn; $507M buyback authority
B13: Valuation Snapshot
B14: Current Share Price | C14: ='DCF & Sensitivity'!D55 -> 168
B15: Base Case (Perpetuity Growth) | C15: ='DCF & Sensitivity'!D53 -> 103.57659
B16: Base Case (Exit Multiple, 11x) | C16: ='DCF & Sensitivity'!D54 -> 157.48607
B17: Upside/(Downside) vs Market (Blended) | C17: =AVERAGE(C15:C16)/C14-1 -> -0.22302781
B19: Key Assumptions
B20: WACC | C20: =Assumptions!D87 -> 0.10509837
B21: Terminal Growth Rate | C21: =Assumptions!D88 -> 0.025
B22: Exit EV/EBITDA Multiple | C22: =Assumptions!D89 -> 11
B23: Terminal Rest. Op. Margin | C23: =Assumptions!M39 -> 0.165
B24: Net Debt ($M) | C24: ='DCF & Sensitivity'!D48 -> 407.1
B25: Diluted Shares Outstanding (M) | C25: ='DCF & Sensitivity'!D51 -> 45.5
B27: Table of Contents
B28: › Summary
B29: Scenario Summary
B30: SWOT
B31: › Valuation
B32: Assumptions
B33: Revenue Build
B34: Income Statement
B35: Balance Sheet
B36: Cash Flow
B37: DCF & Sensitivity
B38: Comps
... B45: › Color Coding
B46: Blue text | C46: Hardcoded inputs and assumptions. Scenario drivers, historical data, WACC components.
B47: Black text | C47: Formulas and calculations that reference cells within the same sheet.
B48: Green text | C48: Cross-sheet links. Formulas pulling values from other tabs.
B49: › Number Conventions
B50: Amounts | C50: All $ values in millions ($M) unless labeled per-share ($/sh). Units column on each sheet confirms.
B51: Percentages | C51: Stored as decimals (0.125 = 12.5%) and displayed with 0.0% format
...

Sheet Scenario Summary
B2: Scenario Summary
B3: Brinker International (EAT)
B4: Bear / Base / Bull scenarios side-by-side. Valuation from Shadow DCF tab (simplified model, scenario-specific drivers). Current market: $168/sh.
B5: The valuation outputs (share price & FY30E) values are simplified views of bear, base, and bull that reconcile within a material percentage of main model
B7: Valuation Summary | C7: Units | D7: Bear | E7: Base | F7: Bull | G7: Range (Bull − Bear)
B8: Implied Price — Perpetuity | C8: $/sh | D8: ='Shadow DCF'!D126 -> 49.300117 | E8: ='Shadow DCF'!E126 -> 99.477411 | F8: ='Shadow DCF'!F126 -> 169.69318 | G8: =F8-D8 -> 120.39306
B9: Implied Price — Exit Multiple | C9: $/sh | D9: ='Shadow DCF'!D127 -> 89.857388 | E9: ='Shadow DCF'!E127 -> 152.74057 | F9: ='Shadow DCF'!F127 -> 244.45682 | G9: =F9-D9 -> 154.59943
B10: Blended (avg of two methods) | C10: $/sh | D10: ='Shadow DCF'!D128 -> 69.578753 | E10: ='Shadow DCF'!E128 -> 126.10899 | F10: ='Shadow DCF'!F128 -> 207.075 | G10: =F10-D10 -> 137.49625
B11: Current Share Price | C11: $/sh | D11: ='DCF & Sensitivity'!$D$55 -> 168 | E11: ='DCF & Sensitivity'!$D$55 -> 168 | F11: ='DCF & Sensitivity'!$D$55 -> 168 | G11: —
B12: Upside / (Downside) vs. market | C12: % | D12: =D10/D11-1 -> -0.58584076 | E12: =E10/E11-1 -> -0.24935123 | F12: =F10/F11-1 -> 0.23258929 | G12: =F12-D12 -> 0.81843005
B14: Scenario Drivers | C14: Units | D14: Bear | E14: Base | F14: Bull | G14: ="FY"&TEXT(MOD('Cover Page'!$C$64-1,100),"00")&"A" -> FY25A
B15: Chili's Same-Store Sales | C15: % | D15: =Assumptions!E11 -> 0.01 | E15: =Assumptions!F11 -> 0.025 | F15: =Assumptions!G11 -> 0.04 | G15: ='Revenue Build'!H22 -> 0.17
B16: Maggiano's Same-Store Sales | C16: % | D16: =Assumptions!E12 -> -0.03 | E16: =Assumptions!F12 -> 0.01 | F16: =Assumptions!G12 -> 0.03 | G16: ='Revenue Build'!H29 -> 0.008
B17: F&B % of Co Sales (terminal FY30E) | C17: % | D17: =Assumptions!E15 -> 0.27 | E17: =Assumptions!F15 -> 0.26 | F17: =Assumptions!G15 -> 0.245 | G17: =Assumptions!H36 -> 0.25314415
B18: Labor % (terminal FY30E) | C18: % | D18: =Assumptions!E16 -> 0.335 | E18: =Assumptions!F16 -> 0.325 | F18: =Assumptions!G16 -> 0.315 | G18: =Assumptions!H37 -> 0.32187506
B19: Rest. Expenses % (terminal FY30E) | C19: % | D19: =Assumptions!E17 -> 0.26 | E19: =Assumptions!F17 -> 0.25 | F19: =Assumptions!G17 -> 0.235 | G19: =Assumptions!H38 -> 0.25001406
B20: G&A % of revenue (terminal FY30E) | C20: % | D20: =Assumptions!E18 -> 0.045 | E20: =Assumptions!F18 -> 0.04 | F20: =Assumptions!G18 -> 0.038 | G20: =Assumptions!H41 -> 0.041231752
B21: Implied Terminal EBITDA Margin | C21: % | D21: =1-D17-D18-D19-D20 -> 0.09 | E21: =1-E17-E18-E19-E20 -> 0.125 | F21: =1-F17-F18-F19-F20 -> 0.167 | G21: =1-G17-G18-G19-G20 -> 0.13373498
B22: Capex % of revenue (terminal FY30E) | C22: % | D22: =Assumptions!E19 -> 0.045 | E22: =Assumptions!F19 -> 0.04 | F22: =Assumptions!G19 -> 0.035 | G22: =Assumptions!H63 -> 0.049273801
B23: Terminal Growth Rate | C23: % | D23: =Assumptions!E23 -> 0.02 | E23: =Assumptions!F23 -> 0.025 | F23: =Assumptions!G23 -> 0.03 | G23: —
B24: Exit EV/EBITDA Multiple | C24: x | D24: =Assumptions!E24 -> 9 | E24: =Assumptions!F24 -> 11 | F24: =Assumptions!G24 -> 13 | G24: —
J25: Note: Perpetuity and Exit Multiple can diverge in tail scenarios because FCF and EBITDA don't scale in lockstep — in Bull, margin expansion and operating leverage make EBITDA grow faster than FCF; in Bear, the opposite. Since perpetuity anchors on FCF and exit multiple anchors on EBITDA, the two methods are valuing different-sized underlying numbers.
B26: FY30E Model Outputs | C26: Units | D26: Bear | E26: Base | F26: Bull
B27: Revenue FY30E | C27: $M | D27: ='Shadow DCF'!D120 -> 6030.3002 | E27: ='Shadow DCF'!E120 -> 6396.5957 | F27: ='Shadow DCF'!F120 -> 6779.3304
B28: EBITDA FY30E | C28: $M | D28: ='Shadow DCF'!D121 -> 610.39569 | E28: ='Shadow DCF'!E121 -> 868.86404 | F28: ='Shadow DCF'!F121 -> 1202.0658
B29: EBITDA Margin FY30E | C29: % | D29: ='Shadow DCF'!D122 -> 0.10122144 | E29: ='Shadow DCF'!E122 -> 0.13583226 | F29: ='Shadow DCF'!F122 -> 0.17731335
B30: FCF FY30E | C30: $M | D30: ='Shadow DCF'!D123 -> 204.57667 | E30: ='Shadow DCF'!E123 -> 434.73353 | F30: ='Shadow DCF'!F123 -> 730.58063
B31: Enterprise Value — Perpetuity | C31: $M | D31: ='Shadow DCF'!D124 -> 2650.2553 | E31: ='Shadow DCF'!E124 -> 4933.3222 | F31: ='Shadow DCF'!F124 -> 8128.1396
B32: Enterprise Value — Exit Multiple | C32: $M | D32: ='Shadow DCF'!D125 -> 4495.6112 | E32: ='Shadow DCF'!E125 -> 7356.7961 | F32: ='Shadow DCF'!F125 -> 11529.885
B34: Takeaways
B35: i) ~70% of enterprise value sits in terminal value across all three scenarios and both exit multiple and perpetuity methods. Valuation is driven by go-forward steady-state assumptions, not the 5-year forecast. ii) Restaurant operating margin is not the crux. Casual dining margins mean-revert within a narrow band as operators flex pricing and labor against commodity cycles. Even our Bear-to-Bull margin range of 9-17% overstates the realistic spread. iii) The real debate is where Chili's SSS stabilizes. FY25A printed +17% on new-CEO momentum (Hochman), '3 for Me' value messaging, and viral social media moments (Triple Dipper). Essentially, a hype cycle that can't compound forever. Bear/Base/Bull assume 1% / 2.5% / 4% in steady state. A 150bps swing in terminal SSS compounds through 50 years of terminal value and drives the full ~$137/sh Bear-to-Bull dispersion. iv) Maggiano's is 9% of revenue in FY25A, still not totally negliable compared to Chili's company-owned 90% of revenue.
B43: Check: Rec to Three Statement DCF | C43: Units | D43: Bear | E43: Base | F43: Bull
B44: Blended Share Price - Scenario Summary | C44: $/sh | D44: ='Shadow DCF'!D128 -> 69.578753 | E44: ='Shadow DCF'!E128 -> 126.10899 | F44: ='Shadow DCF'!F128 -> 207.075
B45: Blended Share Price - Main Model | C45: $/sh | D45: ='Shadow DCF Rec'!D24 -> 76.59 | E45: ='Shadow DCF Rec'!E24 -> 130.535 | F45: ='Shadow DCF Rec'!F24 -> 203.885
B46: Variance (Shadow − Main) | C46: % | D46: =IFERROR(D44/D45-1,"") -> -0.091542596 | E46: =IFERROR(E44/E45-1,"") -> -0.033906671 | F46: =IFERROR(F44/F45-1,"") -> 0.015646076

Sheet SWOT
B2: SWOT Analysis
B3: Brinker International, Inc. (EAT)
C5: Helpful (to achieving objectives) | H5: Harmful (to achieving objectives)
B6: INTERNAL | C6: STRENGTHS | H6: WEAKNESSES
C7: • Chili's: 6 consecutive quarters of double-digit sales + positive traffic growth through Q1 FY26 | H7: • Maggiano's is a drag: Q2 FY26 SSS -2.4%, ROM down -6.7%; turnaround plan is early-stage
C8: • Chili's AUV jumped from $3.2M (FY22) to $4.5M (FY25), +41% over 3 years | H8: • Single-brand concentration — Chili's is >90% of revenue; limited geographic diversification
C9: • Restaurant operating margin expanded from 11% (FY22) to 17.5% (FY25); Q2 FY26 consolidated ROM 18.8% | H9: • 21% / 8.6% SSS growth in Q1/Q2 FY26; guidance implies mid-single-digit for remainder. Where does run-rate SSS land?
C10: • Value positioning — strong gains among <$60K household income segments despite macro weakness
C11: • $507M buyback authority (Aug 2025 top-up); $679M CFO FY25 covers capex + buybacks + debt paydown
C12: • Paid down $360M of revolver in FY25; debt reduced from $786M to $426M; revolver undrawn at 6/25/25
B15: EXTERNAL | C15: OPPORTUNITIES | H15: THREATS
C16: • International franchise expansion — 26-32 franchise openings planned FY26 (mostly international); 18 active dev agreements | H16: • Economic downturn impact on casual dining; consumer discretionary spending risk
C17: • Maggiano's 'North Star' turnaround plan — apply Chili's playbook to underperforming segment | H17: • Consumer shift toward healthier / fast-casual options (CMG, SG, CAVA) could compress casual dining TAM
C18: • Operating leverage on G&A and fixed costs as Chili's AUV continues to scale (target $6M+ 'North of Six' units) | H18: • Wage inflation — low to mid-single digits expected FY26; labor is 32%+ of company sales
C19: • 100% bonus depreciation restored (OBBBA, July 2025) — improves near-term FCF on capex-heavy new units | H19: • $350M 8.25% notes mature July 2030 — refinancing risk at current rates
H20: • Chili's turnaround centered on hype cycle — potential regression to weak SSS performance

Sheet Valuation >>>
B18: Valuation >>>

Sheet Assumptions
B2: Assumptions
B3: Brinker International, Inc. (NYSE: EAT)
B4: All $ in millions unless noted. Fiscal year ends last Wednesday in June.
B7: SCENARIO SELECTOR
B8: FY26E anchored to mgmt's raised guidance (post-Q2). FY27-FY30 interpolate linearly between FY26 start and scenario terminal values. Each driver toggles independently via column H dropdown.
B9: Metric | C9: Units | D9: FY26E Start | E9: Bear | F9: Base | G9: Bull | H9: Scenario
B10: REVENUE
B11: Chili's Same Store Sales Growth | C11: % | D11: 0.086 | E11: 0.01 | F11: 0.025 | G11: 0.04 | H11: Base
B12: Maggiano's Same Store Sales Growth | C12: % | D12: -0.024 | E12: -0.03 | F12: 0.01 | G12: 0.03 | H12: Base
B13: Franchise Royalty Rate (blended) | C13: % | D13: 0.045 | E13: 0.045 | F13: 0.046 | G13: 0.047 | H13: Base
B14: COST
B15: F&B % of Co sales | C15: % | D15: 0.255 | E15: 0.27 | F15: 0.26 | G15: 0.245 | H15: Base
B16: Labor % of Co sales | C16: % | D16: 0.322 | E16: 0.335 | F16: 0.325 | G16: 0.315 | H16: Base
B17: Restaurant expenses % | C17: % | D17: 0.245 | E17: 0.26 | F17: 0.25 | G17: 0.235 | H17: Base
B18: G&A % of revenue | C18: % | D18: 0.041 | E18: 0.045 | F18: 0.04 | G18: 0.038 | H18: Base
B19: Capex % of revenue | C19: % | D19: 0.045 | E19: 0.045 | F19: 0.04 | G19: 0.035 | H19: Base
B20: CAPITAL ALLOCATION
B21: Buybacks % of FCF | C21: % | D21: 0.6 | E21: 0.3 | F21: 0.5 | G21: 0.7 | H21: Base
B22: VALUATION
B23: Terminal Growth Rate | C23: % | D23: 0.025 | E23: 0.02 | F23: 0.025 | G23: 0.03 | H23: Base
B24: Exit EV / EBITDA Multiple | C24: x | D24: 11 | E24: 9 | F24: 11 | G24: 13 | H24: Base
B27: Revenue Drivers | C27: Units | D27: =IF('Cover Page'!$C$63+0<'Cover Page'!$C$64,"FY"&TEXT(MOD('Cover Page'!$C$63+0,100),"00")&"A","FY"&TEXT(MOD('Cover Page'!$C$63+0,100),"00")&"E") -> FY21A | E27: =IF('Cover Page'!$C$63+1<'Cover Page'!$C$64,"FY"&TEXT(MOD('Cover Page'!$C$63+1,100),"00")&"A","FY"&TEXT(MOD('Cover Page'!$C$63+1,100),"00")&"E") -> FY22A | F27: =IF('Cover Page'!$C$63+2<'Cover Page'!$C$64,"FY"&TEXT(MOD('Cover Page'!$C$63+2,100),"00")&"A","FY"&TEXT(MOD('Cover Page'!$C$63+2,100),"00")&"E") -> FY23A | G27: =IF('Cover Page'!$C$63+3<'Cover Page'!$C$64,"FY"&TEXT(MOD('Cover Page'!$C$63+3,100),"00")&"A","FY"&TEXT(MOD('Cover Page'!$C$63+3,100),"00")&"E") -> FY24A | H27: =IF('Cover Page'!$C$63+4<'Cover Page'!$C$64,"FY"&TEXT(MOD('Cover Page'!$C$63+4,100),"00")&"A","FY"&TEXT(MOD('Cover Page'!$C$63+4,100),"00")&"E") -> FY25A | I27: =IF('Cover Page'!$C$63+5<'Cover Page'!$C$64,"FY"&TEXT(MOD('Cover Page'!$C$63+5,100),"00")&"A","FY"&TEXT(MOD('Cover Page'!$C$63+5,100),"00")&"E") -> FY26E | J27: =IF('Cover Page'!$C$63+6<'Cover Page'!$C$64,"FY"&TEXT(MOD('Cover Page'!$C$63+6,100),"00")&"A","FY"&TEXT(MOD('Cover Page'!$C$63+6,100),"00")&"E") -> FY27E | K27: =IF('Cover Page'!$C$63+7<'Cover Page'!$C$64,"FY"&TEXT(MOD('Cover Page'!$C$63+7,100),"00")&"A","FY"&TEXT(MOD('Cover Page'!$C$63+7,100),"00")&"E") -> FY28E | L27: =IF('Cover Page'!$C$63+8<'Cover Page'!$C$64,"FY"&TEXT(MOD('Cover Page'!$C$63+8,100),"00")&"A","FY"&TEXT(MOD('Cover Page'!$C$63+8,100),"00")&"E") -> FY29E | M27: =IF('Cover Page'!$C$63+9<'Cover Page'!$C$64,"FY"&TEXT(MOD('Cover Page'!$C$63+9,100),"00")&"A","FY"&TEXT(MOD('Cover Page'!$C$63+9,100),"00")&"E") -> FY30E | O27: Notes
B28: Chili's Same-Store Sales | C28: % | D28: ='Revenue Build'!D22 -> 0.215 | E28: ='Revenue Build'!E22 -> 0.03 | F28: ='Revenue Build'!F22 -> 0.074 | G28: ='Revenue Build'!G22 -> 0.038 | H28: ='Revenue Build'!H22 -> 0.17 | I28: ='Revenue Build'!I22 -> 0.086 | J28: ='Revenue Build'!J22 -> 0.0473 | K28: ='Revenue Build'!K22 -> 0.0301 | ... M28: ='Revenue Build'!M22 -> 0.025 | O28: Our revenue proforma uses same-store sales (SSS) growth applied to FY25 reported revenue which is not a bottoms-up unit build. This captures comp growth at existing restaurants but implicitly ignores: Net new stores, Closed stores , and New store ramp This is acceptable for Brinker because net unit change is immaterial (<0.5% of revenue). For a high-growth restaurant concept (e.g., TXRH, WING), a proper unit economic build would be essential. Revenue Build unit economics shown in HP in the Revenue Build Tab reflect how that analytical framework would work but does not flow into the forecast.
B29: Chili's Company Sales | C29: $M | D29: ='Income Statement'!D11-'Revenue Build'!D31 -> 3008.7 | E29: ='Income Statement'!E11-'Revenue Build'!E31 -> 3290.9 | F29: ='Income Statement'!F11-'Revenue Build'!F31 -> 3487.9 | G29: ='Income Statement'!G11-'Revenue Build'!G31 -> 3881.1 | H29: ='Income Statement'!H11-'Revenue Build'!H31 -> 4850.2 | I29: ='Income Statement'!H9*(1+I28) -> 5250.5928 | J29: =I29*(1+J28) -> 5498.9458 | K29: =J29*(1+K28) -> 5664.4641 | L29: =K29*(1+L28) -> 5783.9843 | M29: =L29*(1+M28) -> 5928.5839
B30: Maggiano's Same-Store Sales | C30: % | D30: ='Revenue Build'!D29 -> 0.15 | E30: ='Revenue Build'!E29 -> 0.08 | F30: ='Revenue Build'!F29 -> 0.069 | G30: ='Revenue Build'!G29 -> 0.024 | H30: ='Revenue Build'!H29 -> 0.008 | I30: ='Revenue Build'!I29 -> -0.024 | J30: ='Revenue Build'!J29 -> -0.007 | K30: ='Revenue Build'!K29 -> 0.01 | ... M30: ='Revenue Build'!M29 -> 0.01
B31: Maggiano's Company Sales | C31: $M | D31: ='Revenue Build'!D31 -> 270.3 | E31: ='Revenue Build'!E31 -> 421.2 | F31: ='Revenue Build'!F31 -> 475 | G31: ='Revenue Build'!G31 -> 490 | H31: ='Revenue Build'!H31 -> 485.1 | I31: ='Income Statement'!H10*(1+I30) -> 488.488 | J31: =I31*(1+J30) -> 485.06858 | K31: =J31*(1+K30) -> 489.91927 | L31: =K31*(1+L30) -> 494.81846 | M31: =L31*(1+M30) -> 499.76665
B32: Franchise & Other Revenue | C32: $M | D32: ='Revenue Build'!D39 -> 58.8 | E32: ='Revenue Build'!E39 -> 92 | F32: ='Revenue Build'!F39 -> 91.2 | G32: ='Revenue Build'!G39 -> 44 | H32: ='Revenue Build'!H39 -> 48.9 | I32: ='Revenue Build'!I39 -> 65.43327 | J32: ='Revenue Build'!J39 -> 71.325917 | K32: ='Revenue Build'!K39 -> 76.605997 | ... M32: ='Revenue Build'!M39 -> 84.489546
B33: Total Revenue | C33: $M | D33: =D29+D31+D32 -> 3337.8 | E33: =E29+E31+E32 -> 3804.1 | F33: =F29+F31+F32 -> 4054.1 | G33: =G29+G31+G32 -> 4415.1 | H33: =H29+H31+H32 -> 5384.2 | I33: =I29+I31+I32 -> 5804.5141 | J33: =J29+J31+J32 -> 6055.3403 | K33: =K29+K31+K32 -> 6230.9894 | ... M33: =M29+M31+M32 -> 6512.8401
B35: Margin Drivers
B36: Food & Beverage (F&B) costs % co. sales | C36: % | D36: ='Income Statement'!D18 -> 0.26465386 | E36: ='Income Statement'!E18 -> 0.28245468 | F36: ='Income Statement'!F18 -> 0.2752025 | G36: ='Income Statement'!G18 -> 0.25339159 | H36: ='Income Statement'!H18 -> 0.25314415 | I36: =D15 -> 0.255 | J36: =I36+(INDEX($E$15:$G$15,MATCH($H$15,$E$9:$G$9,0))-I36)*1/4 -> 0.25625 | K36: =I36+(INDEX($E$15:$G$15,MATCH($H$15,$E$9:$G$9,0))-I36)*2/4 -> 0.2575 | L36: =I36+(INDEX($E$15:$G$15,MATCH($H$15,$E$9:$G$9,0))-I36)*3/4 -> 0.25875 | M36: =INDEX($E$15:$G$15,MATCH($H$15,$E$9:$G$9,0)) -> 0.26 | O36: Food (Proteins, Dairy, Bakery), Alcholoic and Non-Alchoholic Beverages (Scales w/ Traffic)
B37: Labor % of co. sales | C37: % | D37: ='Income Statement'!D20 -> 0.33796889 | E37: ='Income Statement'!E20 -> 0.34700035 | F37: ='Income Statement'!F20 -> 0.3434606 | G37: ='Income Statement'!G20 -> 0.33568209 | H37: ='Income Statement'!H20 -> 0.32187506 | I37: =D16 -> 0.322 | J37: =I37+(INDEX($E$16:$G$16,MATCH($H$16,$E$9:$G$9,0))-I37)*1/4 -> 0.32275 | K37: =I37+(INDEX($E$16:$G$16,MATCH($H$16,$E$9:$G$9,0))-I37)*2/4 -> 0.3235 | L37: =I37+(INDEX($E$16:$G$16,MATCH($H$16,$E$9:$G$9,0))-I37)*3/4 -> 0.32425 | M37: =INDEX($E$16:$G$16,MATCH($H$16,$E$9:$G$9,0)) -> 0.325 | O37: Personell wages - Hourly workers and restaurant management (Semi-variable)
B38: Restaurant expenses % of co. sales | C38: % | D38: ='Income Statement'!D22 -> 0.26181763 | E38: ='Income Statement'!E22 -> 0.26084965 | F38: ='Income Statement'!F22 -> 0.26657246 | G38: ='Income Statement'!G22 -> 0.27748164 | H38: ='Income Statement'!H22 -> 0.25001406 | I38: =D17 -> 0.245 | J38: =I38+(INDEX($E$17:$G$17,MATCH($H$17,$E$9:$G$9,0))-I38)*1/4 -> 0.24625 | K38: =I38+(INDEX($E$17:$G$17,MATCH($H$17,$E$9:$G$9,0))-I38)*2/4 -> 0.2475 | L38: =I38+(INDEX($E$17:$G$17,MATCH($H$17,$E$9:$G$9,0))-I38)*3/4 -> 0.24875 | M38: =INDEX($E$17:$G$17,MATCH($H$17,$E$9:$G$9,0)) -> 0.25 | O38: Occupancy costs, utilities, repairs & maintenance, marketing and promos, payment processing fees (Most Fixed Op. Margin Cost)
B39: Restaurant operating margin | C39: % | D39: =1-D36-D37-D38 -> 0.13555962 | E39: =1-E36-E37-E38 -> 0.10969532 | F39: =1-F36-F37-F38 -> 0.11476444 | G39: =1-G36-G37-G38 -> 0.13344467 | H39: =1-H36-H37-H38 -> 0.17496673 | I39: =1-I36-I37-I38 -> 0.178 | J39: =1-J36-J37-J38 -> 0.17475 | K39: =1-K36-K37-K38 -> 0.1715 | ... M39: =1-M36-M37-M38 -> 0.165
B40: D&A % of revenue | C40: % | D40: ='Income Statement'!D26/'Income Statement'!D13 -> 0.0449997 | E40: ='Income Statement'!E26/'Income Statement'!E13 -> 0.04321653 | F40: ='Income Statement'!F26/'Income Statement'!F13 -> 0.041562862 | G40: ='Income Statement'!G26/'Income Statement'!G13 -> 0.03868542 | H40: ='Income Statement'!H26/'Income Statement'!H13 -> 0.038371532 | I40: 0.039 | J40: 0.04 | K40: 0.04 | L40: 0.041 | M40: 0.041 | O40: Driven by Chili's remodel program and Maggiano's reinvestment & OBBBA depreciation accelerating near-term expense recognition on new builds and equipment
B41: G&A % of revenue | C41: % | D41: ='Income Statement'!D27/'Income Statement'!D13 -> 0.040385883 | E41: ='Income Statement'!E27/'Income Statement'!E13 -> 0.037880182 | F41: ='Income Statement'!F27/'Income Statement'!F13 -> 0.042623517 | G41: ='Income Statement'!G27/'Income Statement'!G13 -> 0.041607212 | H41: ='Income Statement'!H27/'Income Statement'!H13 -> 0.041231752 | I41: =D18 -> 0.041 | J41: =I41+(INDEX($E$18:$G$18,MATCH($H$18,$E$9:$G$9,0))-I41)*1/4 -> 0.04075 | K41: =I41+(INDEX($E$18:$G$18,MATCH($H$18,$E$9:$G$9,0))-I41)*2/4 -> 0.0405 | L41: =I41+(INDEX($E$18:$G$18,MATCH($H$18,$E$9:$G$9,0))-I41)*3/4 -> 0.04025 | M41: =INDEX($E$18:$G$18,MATCH($H$18,$E$9:$G$9,0)) -> 0.04 | O41: Corporate overhead as % of total revenue. Excludes anything at restaurant level
B42: Other (gains) & charges % of rev | C42: % | D42: 0.006 | E42: 0.008 | F42: 0.006 | G42: 0.01 | H42: 0.008 | I42: 0.005 | J42: 0.005 | K42: 0.005 | L42: 0.005 | M42: 0.005
B44: Debt Schedule
B45: Tranche / $M | C45: Rate | D45: =IF('Cover Page'!$C$63+0<'Cover Page'!$C$64,"FY"&TEXT(MOD('Cover Page'!$C$63+0,100),"00")&"A","FY"&TEXT(MOD('Cover Page'!$C$63+0,100),"00")&"E") -> FY21A | E45: =IF('Cover Page'!$C$63+1<'Cover Page'!$C$64,"FY"&TEXT(MOD('Cover Page'!$C$63+1,100),"00")&"A","FY"&TEXT(MOD('Cover Page'!$C$63+1,100),"00")&"E") -> FY22A | F45: =IF('Cover Page'!$C$63+2<'Cover Page'!$C$64,"FY"&TEXT(MOD('Cover Page'!$C$63+2,100),"00")&"A","FY"&TEXT(MOD('Cover Page'!$C$63+2,100),"00")&"E") -> FY23A | G45: =IF('Cover Page'!$C$63+3<'Cover Page'!$C$64,"FY"&TEXT(MOD('Cover Page'!$C$63+3,100),"00")&"A","FY"&TEXT(MOD('Cover Page'!$C$63+3,100),"00")&"E") -> FY24A | H45: =IF('Cover Page'!$C$63+4<'Cover Page'!$C$64,"FY"&TEXT(MOD('Cover Page'!$C$63+4,100),"00")&"A","FY"&TEXT(MOD('Cover Page'!$C$63+4,100),"00")&"E") -> FY25A | I45: =IF('Cover Page'!$C$63+5<'Cover Page'!$C$64,"FY"&TEXT(MOD('Cover Page'!$C$63+5,100),"00")&"A","FY"&TEXT(MOD('Cover Page'!$C$63+5,100),"00")&"E") -> FY26E | J45: =IF('Cover Page'!$C$63+6<'Cover Page'!$C$64,"FY"&TEXT(MOD('Cover Page'!$C$63+6,100),"00")&"A","FY"&TEXT(MOD('Cover Page'!$C$63+6,100),"00")&"E") -> FY27E | K45: =IF('Cover Page'!$C$63+7<'Cover Page'!$C$64,"FY"&TEXT(MOD('Cover Page'!$C$63+7,100),"00")&"A","FY"&TEXT(MOD('Cover Page'!$C$63+7,100),"00")&"E") -> FY28E | L45: =IF('Cover Page'!$C$63+8<'Cover Page'!$C$64,"FY"&TEXT(MOD('Cover Page'!$C$63+8,100),"00")&"A","FY"&TEXT(MOD('Cover Page'!$C$63+8,100),"00")&"E") -> FY29E | M45: =IF('Cover Page'!$C$63+9<'Cover Page'!$C$64,"FY"&TEXT(MOD('Cover Page'!$C$63+9,100),"00")&"A","FY"&TEXT(MOD('Cover Page'!$C$63+9,100),"00")&"E") -> FY30E
B46: Senior Notes 8.25% due 2030 | C46: 0.0825 | D46: 0 | E46: 350 | F46: 350 | G46: 350 | H46: 350 | I46: =H46 -> 350 | J46: =I46 -> 350 | K46: =J46 -> 350 | L46: =K46 -> 350 | M46: =L46 -> 350 | O46: Debt schedule = capital structure detail that flows into Interest Expense Three tranches: i) Senior Notes $350M @ 8.25% due 2030 (fixed, bullet) ii) Revolver $42M @ ~6.75% (paying down to zero by FY28) iii) Finance leases $34M @ ~5% (held flat) Rate inputs can be toggled to stress test. Excludes $1.1B op leases (ASC 842). Total debt/EBITDA ~0.5x = under-levered vs casual dining peers (2-3x). Source: FY25 10-K Notes 8 & 9.
B47: Revolving credit facility | C47: 0.0675 | D47: 300 | E47: 255 | F47: 360 | G47: 377 | H47: 42 | I47: =MAX(0,H47-25) -> 17 | J47: =MAX(0,I47-17) -> 0 | K47: =MAX(0,J47-0) -> 0 | L47: =MAX(0,K47-0) -> 0 | M47: =MAX(0,L47-0) -> 0
...

Sheet Revenue Build
B2: Revenue Build
B3: Brinker International (EAT)
B4: All amounts in $ millions unless noted
B6: Ideally, a restaurant DCF would build revenue from unit economic drivers (avg units × AUV + new units × ramp-up AUV − closed units × partial-year AUV) to isolate new stores, existing stores, and closed stores as separate value drivers. We can't do this cleanly because the 10-K doesn't disclose: (1) unit-week counts (when during the year stores closed), (2) new-build AUV vs mature AUV (new restaurants ramp over ~2 yrs), (3) domestic vs international AUV split (international franchisees have different economics), or (4) the restaurant population used in the AUV metric. In the HP, we attempted to take AUV * # of Units to see if this bottoms-up revenue build would align close to reported revenue, but this method overshoots reported sales by 3-9% historically, confirming the current level of disclosure isn't sufficient for a precise bottoms-up build. How we forecast revenue: FY25 Reported × (1 + SSS%), compounded. This method sacrifices segment-level unit economics visibility but anchors forecast to audited revenue. Unit economics breakdown below is kept as analytical color. This is doable for Brinker specifically, because new stores expansion is immaterial (~+2 net Chili's/yr = <0.1% revenue impact). SSS toggles remain the primary value lever.
C16: Units | D16: FY21A | E16: FY22A | F16: FY23A | G16: FY24A | H16: FY25A | I16: FY26E | J16: FY27E | K16: FY28E | L16: FY29E | M16: FY30E | O16: Notes
B18: Chili's Company-Owned
B19: Units BOP | C19: # | D19: 1145 | E19: =D21 -> 1134 | F19: =E21 -> 1123 | G19: =F21 -> 1127 | H19: =G21 -> 1121 | I19: =H21 -> 1113 | J19: =I21 -> 1115 | K19: =J21 -> 1115 | L19: =K21 -> 1115 | M19: =L21 -> 1115 | O19: Proforma company-owned sales are linked here from Assumptions row 29 (FY25 Reported $4,834M × SSS, compounded). Unit counts, SSS, and AUV shown here for reference. FY21 SSS +21.5% = post-COVID rebound; FY25 SSS +17% driven by CEO Hochman's "Chili's Reimagined" turnaround (Q4 traffic +16%, unusually traffic-led growth vs. industry pricing-led norm).
B20: Net new / (closures) | C20: # | D20: =D21-D19 -> -11 | E20: =E21-E19 -> -11 | F20: =F21-F19 -> 4 | G20: =G21-G19 -> -6 | H20: =H21-H19 -> -8 | I20: =7-5 -> 2 | J20: 0 | K20: 0 | L20: 0 | M20: 0
B21: Units EOP | C21: # | D21: 1134 | E21: 1123 | F21: 1127 | G21: 1121 | H21: 1113 | I21: =I19+I20 -> 1115 | J21: =J19+J20 -> 1115 | K21: =K19+K20 -> 1115 | L21: =L19+L20 -> 1115 | M21: =M19+M20 -> 1115
B22: Same store sales YoY growth (SSS) | C22: % | D22: 0.215 | E22: 0.03 | F22: 0.074 | G22: 0.038 | H22: 0.17 | I22: =Assumptions!$D$11 -> 0.086 | J22: =Assumptions!$D$11*0.55 -> 0.0473 | K22: =Assumptions!$D$11*0.35 -> 0.0301 | L22: =(Assumptions!$D$11*0.2+INDEX(Assumptions!$E$11:$G$11,MATCH(Assumptions!$H$11,Assumptions!$E$9:$G$9,0)))/2 -> 0.0211 | M22: =INDEX(Assumptions!$E$11:$G$11,MATCH(Assumptions!$H$11,Assumptions!$E$9:$G$9,0)) -> 0.025
B23: Average unit volume (AUV) | C23: $M | D23: 2.9 | E23: 3.2 | F23: 3.4 | G23: 3.6 | H23: 4.5 | I23: =H23*(1+I22) -> 4.887 | J23: =I23*(1+J22) -> 5.1181551 | K23: =J23*(1+K22) -> 5.2722116 | L23: =K23*(1+L22) -> 5.3834552 | M23: =L23*(1+M22) -> 5.5180416
B24: Chili's company-owned sales | C24: $M | D24: =((D19+D21)/2)*D23 -> 3304.55 | E24: =((E19+E21)/2)*E23 -> 3611.2 | F24: =((F19+F21)/2)*F23 -> 3825 | G24: =((G19+G21)/2)*G23 -> 4046.4 | H24: =((H19+H21)/2)*H23 -> 5026.5 | I24: =Assumptions!I29 -> 5250.5928 | J24: =Assumptions!J29 -> 5498.9458 | K24: =Assumptions!K29 -> 5664.4641 | L24: =Assumptions!L29 -> 5783.9843 | M24: =Assumptions!M29 -> 5928.5839
B25: % of Total Revenue | C25: % | D25: =D24/D41 -> 0.90942991 | E25: =E24/E41 -> 0.87556978 | F25: =F24/F41 -> 0.8710603 | G25: =G24/G41 -> 0.8834163 | H25: =H24/H41 -> 0.90396547 | I25: =I24/I41 -> 0.9045706 | J25: =J24/J41 -> 0.90811507 | K25: =K24/K41 -> 0.9090794 | ... M25: =M24/M41 -> 0.91029164
B27: Maggiano's Company-Owned
B28: Units EOP | C28: # | D28: 51 | E28: 52 | F28: 50 | G28: 50 | H28: 49 | I28: =H28 -> 49 | J28: =I28 -> 49 | K28: =J28 -> 49 | L28: =K28 -> 49 | M28: =L28 -> 49 | O28: Proforma company-owned sales are linked here from Assumptions row 31 (FY25 Reported $500M × SSS). 49 units, 100% Company-operated (zero franchised). Italian-American polished casual; banquet-heavy (15% of sales). Highest AUV in casual dining ($9.9M vs Chili's $4.5M) from higher check size ($39/guest vs $22) and banquet volume. ~9% of total revenue. Brand contracting — FY26 Q1 comp -6.4%, Q2 -2.4%; mgmt applying "Chili's turnaround playbook."
B29: Same store sales YoY growth (SSS) | C29: % | D29: 0.15 | E29: 0.08 | F29: 0.069 | G29: 0.024 | H29: 0.008 | I29: =Assumptions!$D$12 -> -0.024 | J29: =(Assumptions!$D$12+INDEX(Assumptions!$E$12:$G$12,MATCH(Assumptions!$H$12,Assumptions!$E$9:$G$9,0)))/2 -> -0.007 | K29: =INDEX(Assumptions!$E$12:$G$12,MATCH(Assumptions!$H$12,Assumptions!$E$9:$G$9,0)) -> 0.01 | L29: =INDEX(Assumptions!$E$12:$G$12,MATCH(Assumptions!$H$12,Assumptions!$E$9:$G$9,0)) -> 0.01 | M29: =INDEX(Assumptions!$E$12:$G$12,MATCH(Assumptions!$H$12,Assumptions!$E$9:$G$9,0)) -> 0.01
B30: Average unit volume (AUV) | C30: $M | D30: 5.3 | E30: 8.1 | F30: 9.5 | G30: 9.8 | H30: 9.9 | I30: =H30*(1+I29) -> 9.6624 | J30: =I30*(1+J29) -> 9.5947632 | K30: =J30*(1+K29) -> 9.6907108 | L30: =K30*(1+L29) -> 9.7876179 | M30: =L30*(1+M29) -> 9.8854941
B31: Maggiano's company-owned sales | C31: $M | D31: =D28*D30 -> 270.3 | E31: =E28*E30 -> 421.2 | F31: =F28*F30 -> 475 | G31: =G28*G30 -> 490 | H31: =H28*H30 -> 485.1 | I31: =Assumptions!I31 -> 488.488 | J31: =Assumptions!J31 -> 485.06858 | K31: =Assumptions!K31 -> 489.91927 | L31: =Assumptions!L31 -> 494.81846 | M31: =Assumptions!M31 -> 499.76665
B32: % of Total Revenue | C32: % | D32: =D31/D41 -> 0.074388012 | E32: =E31/E41 -> 0.10212395 | F32: =F31/F41 -> 0.10817089 | G32: =G31/G41 -> 0.10697756 | H32: =H31/H41 -> 0.087240356 | I32: =I31/I41 -> 0.084156571 | J32: =J31/J41 -> 0.080105916 | K32: =K31/K41 -> 0.078626241 | ... M32: =M31/M41 -> 0.076735593
B33: Total company-owned sales | C33: $M | D33: =D24+D31 -> 3574.85 | E33: =E24+E31 -> 4032.4 | F33: =F24+F31 -> 4300 | G33: =G24+G31 -> 4536.4 | H33: =H24+H31 -> 5511.6 | I33: =I24+I31 -> 5739.0808 | J33: =J24+J31 -> 5984.0144 | K33: =K24+K31 -> 6154.3834 | ... M33: =M24+M31 -> 6428.3506
B35: Chili's Franchise
B36: Chili's franchise units | C36: # | D36: 316 | E36: 353 | F36: 398 | G36: 430 | H36: 463 | I36: =H36+26 -> 489 | J36: =I36+26 -> 515 | K36: =J36+24 -> 539 | L36: =K36+22 -> 561 | M36: =L36+20 -> 581 | O36: 463 units at FY25 (99 domestic + 364 international): Brinker collects royalties. Per-unit sales much lower than Co-owned ($2.9M vs $4.5M) due to international weighting. FY23→FY24 drop reflects ASC 606 reclassification (ad fund netted vs grossed up), not economic decline. Not a real valuation driver.
B37: Est. franchise system sales | C37: $M | D37: 850 | E37: 950 | F37: 1100 | G37: 1200 | H37: 1320 | I37: =I36*(H37/H36)*(1+I22*0.5) -> 1454.0727 | J37: =J36*(I37/I36)*(1+J22*0.5) -> 1567.6026 | K37: =K36*(J37/J36)*(1+K22*0.5) -> 1665.3478 | L37: =L36*(K37/K36)*(1+L22*0.5) -> 1751.6077 | M37: =M36*(L37/L36)*(1+M22*0.5) -> 1836.7293
B38: Effective royalty + other | C38: % | D38: =D39/D37 -> 0.069176471 | E38: =E39/E37 -> 0.096842105 | F38: =F39/F37 -> 0.082909091 | G38: =G39/G37 -> 0.036666667 | H38: =H39/H37 -> 0.037045455 | I38: =Assumptions!$D$13 -> 0.045 | J38: =(Assumptions!$D$13+INDEX(Assumptions!$E$13:$G$13,MATCH(Assumptions!$H$13,Assumptions!$E$9:$G$9,0)))/2 -> 0.0455 | K38: =INDEX(Assumptions!$E$13:$G$13,MATCH(Assumptions!$H$13,Assumptions!$E$9:$G$9,0)) -> 0.046 | L38: =INDEX(Assumptions!$E$13:$G$13,MATCH(Assumptions!$H$13,Assumptions!$E$9:$G$9,0)) -> 0.046 | M38: =INDEX(Assumptions!$E$13:$G$13,MATCH(Assumptions!$H$13,Assumptions!$E$9:$G$9,0)) -> 0.046
B39: Franchise & other revenue | C39: $M | D39: 58.8 | E39: 92 | F39: 91.2 | G39: 44 | H39: 48.9 | I39: =I37*I38 -> 65.43327 | J39: =J37*J38 -> 71.325917 | K39: =K37*K38 -> 76.605997 | L39: =L37*L38 -> 80.573954 | M39: =M37*M38 -> 84.489546
B40: % of Total Revenue | C40: % | D40: =D39/D41 -> 0.016182076 | E40: =E39/E41 -> 0.022306275 | F40: =F39/F41 -> 0.02076881 | G40: =G39/G41 -> 0.0096061479 | H40: =H39/H41 -> 0.0087941732 | I40: =I39/I41 -> 0.011272825 | J40: =J39/J41 -> 0.01177901 | K40: =K39/K41 -> 0.012294355 | ... M40: =M39/M41 -> 0.012972765
B41: Total Revenue (company-owned + franchise) | C41: $M | D41: =D33+D39 -> 3633.65 | E41: =E33+E39 -> 4124.4 | F41: =F33+F39 -> 4391.2 | G41: =G33+G39 -> 4580.4 | H41: =H33+H39 -> 5560.5 | I41: =I33+I39 -> 5804.5141 | J41: =J33+J39 -> 6055.3403 | K41: =K33+K39 -> 6230.9894 | ... M41: =M33+M39 -> 6512.8401
B42: YoY growth | C42: % | E42: =E41/D41-1 -> 0.13505704 | F42: =F41/E41-1 -> 0.064688197 | G42: =G41/F41-1 -> 0.043086172 | H42: =H41/G41-1 -> 0.21397695 | I42: =I41/H41-1 -> 0.043883476 | J42: =J41/I41-1 -> 0.043212277 | K42: =K41/J41-1 -> 0.029007294 | L42: =L41/K41-1 -> 0.020604648 | M42: =M41/L41-1 -> 0.024131828
B44: Revenue Check : Unit Economics Build vs. Reported
B45: Reported Revenue (IS Statement) | C45: $M | D45: ='Income Statement'!D13 -> 3337.8 | E45: ='Income Statement'!E13 -> 3804.1 | F45: ='Income Statement'!F13 -> 4054.1 | G45: ='Income Statement'!G13 -> 4415.1 | H45: ='Income Statement'!H13 -> 5384.2
B46: Variance (Unit Economics Build vs. IS Reported) | C46: $M | D46: =D41-D45 -> 295.85 | E46: =E41-E45 -> 320.3 | F46: =F41-F45 -> 337.1 | G46: =G41-G45 -> 165.3 | H46: =H41-H45 -> 176.3
B47: Variance % | C47: % | D47: =D46/D45 -> 0.088636227 | E47: =E46/E45 -> 0.084198628 | F47: =F46/F45 -> 0.083150391 | G47: =G46/G45 -> 0.037439696 | H47: =H46/H45 -> 0.032743955

Sheet Income Statement
B2: Income Statement
B3: Brinker International (EAT)
B4: All amounts in $ millions unless noted
C6: Units | D6: =IF('Cover Page'!$C$63+0<'Cover Page'!$C$64,"FY"&TEXT(MOD('Cover Page'!$C$63+0,100),"00")&"A","FY"&TEXT(MOD('Cover Page'!$C$63+0,100),"00")&"E") -> FY21A | E6: =IF('Cover Page'!$C$63+1<'Cover Page'!$C$64,"FY"&TEXT(MOD('Cover Page'!$C$63+1,100),"00")&"A","FY"&TEXT(MOD('Cover Page'!$C$63+1,100),"00")&"E") -> FY22A | F6: =IF('Cover Page'!$C$63+2<'Cover Page'!$C$64,"FY"&TEXT(MOD('Cover Page'!$C$63+2,100),"00")&"A","FY"&TEXT(MOD('Cover Page'!$C$63+2,100),"00")&"E") -> FY23A | G6: =IF('Cover Page'!$C$63+3<'Cover Page'!$C$64,"FY"&TEXT(MOD('Cover Page'!$C$63+3,100),"00")&"A","FY"&TEXT(MOD('Cover Page'!$C$63+3,100),"00")&"E") -> FY24A | H6: =IF('Cover Page'!$C$63+4<'Cover Page'!$C$64,"FY"&TEXT(MOD('Cover Page'!$C$63+4,100),"00")&"A","FY"&TEXT(MOD('Cover Page'!$C$63+4,100),"00")&"E") -> FY25A | I6: =IF('Cover Page'!$C$63+5<'Cover Page'!$C$64,"FY"&TEXT(MOD('Cover Page'!$C$63+5,100),"00")&"A","FY"&TEXT(MOD('Cover Page'!$C$63+5,100),"00")&"E") -> FY26E | J6: =IF('Cover Page'!$C$63+6<'Cover Page'!$C$64,"FY"&TEXT(MOD('Cover Page'!$C$63+6,100),"00")&"A","FY"&TEXT(MOD('Cover Page'!$C$63+6,100),"00")&"E") -> FY27E | K6: =IF('Cover Page'!$C$63+7<'Cover Page'!$C$64,"FY"&TEXT(MOD('Cover Page'!$C$63+7,100),"00")&"A","FY"&TEXT(MOD('Cover Page'!$C$63+7,100),"00")&"E") -> FY28E | L6: =IF('Cover Page'!$C$63+8<'Cover Page'!$C$64,"FY"&TEXT(MOD('Cover Page'!$C$63+8,100),"00")&"A","FY"&TEXT(MOD('Cover Page'!$C$63+8,100),"00")&"E") -> FY29E | M6: =IF('Cover Page'!$C$63+9<'Cover Page'!$C$64,"FY"&TEXT(MOD('Cover Page'!$C$63+9,100),"00")&"A","FY"&TEXT(MOD('Cover Page'!$C$63+9,100),"00")&"E") -> FY30E | O6: Notes
B8: Revenue
B9: Chili's company sales | C9: $M | D9: 3008.7 | E9: 3290.9 | F9: 3487.9 | G9: 3876 | H9: 4834.8 | I9: =Assumptions!I29 -> 5250.5928 | J9: =Assumptions!J29 -> 5498.9458 | K9: =Assumptions!K29 -> 5664.4641 | L9: =Assumptions!L29 -> 5783.9843 | M9: =Assumptions!M29 -> 5928.5839 | O9: Brinker revenue = Company sales (98%) + Franchise revenues (1%). Company sales = revenue from restaurants Brinker owns & operates (1,113 Chili's + 49 Maggiano's). Franchise = royalties from 463 franchised Chili's (mostly international). Forecast: FY25 reported × (1 + SSS%), compounded. SSS toggles live on Assumptions
B10: Maggiano's company sales | C10: $M | D10: 270.3 | E10: 421.2 | F10: 475 | G10: 495.1 | H10: 500.5 | I10: =Assumptions!I31 -> 488.488 | J10: =Assumptions!J31 -> 485.06858 | K10: =Assumptions!K31 -> 489.91927 | L10: =Assumptions!L31 -> 494.81846 | M10: =Assumptions!M31 -> 499.76665
B11: Total Company-Owned Sales | C11: $M | D11: =D9+D10 -> 3279 | E11: =E9+E10 -> 3712.1 | F11: =F9+F10 -> 3962.9 | G11: =G9+G10 -> 4371.1 | H11: =H9+H10 -> 5335.3 | I11: =I9+I10 -> 5739.0808 | J11: =J9+J10 -> 5984.0144 | K11: =K9+K10 -> 6154.3834 | ... M11: =M9+M10 -> 6428.3506
B12: Franchise revenues | C12: $M | D12: 58.8 | E12: 92 | F12: 91.2 | G12: 44 | H12: 48.9 | I12: =Assumptions!I32 -> 65.43327 | J12: =Assumptions!J32 -> 71.325917 | K12: =Assumptions!K32 -> 76.605997 | L12: =Assumptions!L32 -> 80.573954 | M12: =Assumptions!M32 -> 84.489546
B13: Total revenues | C13: $M | D13: =D11+D12 -> 3337.8 | E13: =E11+E12 -> 3804.1 | F13: =F11+F12 -> 4054.1 | G13: =G11+G12 -> 4415.1 | H13: =H11+H12 -> 5384.2 | I13: =I11+I12 -> 5804.5141 | J13: =J11+J12 -> 6055.3403 | K13: =K11+K12 -> 6230.9894 | ... M13: =M11+M12 -> 6512.8401
B14: YoY growth % | C14: % | E14: =E13/D13-1 -> 0.1397028 | F14: =F13/E13-1 -> 0.065718567 | G14: =G13/F13-1 -> 0.089045657 | H14: =H13/G13-1 -> 0.21949673 | I14: =I13/H13-1 -> 0.078064349 | J14: =J13/I13-1 -> 0.043212277 | K14: =K13/J13-1 -> 0.029007294 | L14: =L13/K13-1 -> 0.020604648 | M14: =M13/L13-1 -> 0.024131828
B16: Restaurant-level operating costs
B17: Food and beverage costs | C17: $M | D17: 867.8 | E17: 1048.5 | F17: 1090.6 | G17: 1107.6 | H17: 1350.6 | I17: =I11*Assumptions!I36 -> 1463.4656 | J17: =J11*Assumptions!J36 -> 1533.4037 | K17: =K11*Assumptions!K36 -> 1584.7537 | L17: =L11*Assumptions!L36 -> 1624.6402 | M17: =M11*Assumptions!M36 -> 1671.3711 | O17: Costs that happen inside the four walls of a restaurant. Three line items: i) F&B costs — ingredients; moves with commodity cycles, ii) Restaurant labor — hourly staff, managers, benefits, payroll taxes iii) Restaurant expenses — rent, utilities, R&M, credit card fees, local marketing Forecast % driven by scenario toggles on Assumptions (F&B/Labor/Rest Exp). These three sum to ~82-83% of company sales.
B18: % of Company sales | C18: % | D18: =D17/D11 -> 0.26465386 | E18: =E17/E11 -> 0.28245468 | F18: =F17/F11 -> 0.2752025 | G18: =G17/G11 -> 0.25339159 | H18: =H17/H11 -> 0.25314415 | I18: =I17/I11 -> 0.255 | J18: =J17/J11 -> 0.25625 | K18: =K17/K11 -> 0.2575 | ... M18: =M17/M11 -> 0.26
B19: Restaurant labor | C19: $M | D19: 1108.2 | E19: 1288.1 | F19: 1361.1 | G19: 1467.3 | H19: 1717.3 | I19: =I11*Assumptions!I37 -> 1847.984 | J19: =J11*Assumptions!J37 -> 1931.3407 | K19: =K11*Assumptions!K37 -> 1990.943 | L19: =L11*Assumptions!L37 -> 2035.9018 | M19: =M11*Assumptions!M37 -> 2089.2139
B20: % of Company sales | C20: % | D20: =D19/D11 -> 0.33796889 | E20: =E19/E11 -> 0.34700035 | F20: =F19/F11 -> 0.3434606 | G20: =G19/G11 -> 0.33568209 | H20: =H19/H11 -> 0.32187506 | I20: =I19/I11 -> 0.322 | J20: =J19/J11 -> 0.32275 | K20: =K19/K11 -> 0.3235 | ... M20: =M19/M11 -> 0.325
B21: Restaurant expenses | C21: $M | D21: 858.5 | E21: 968.3 | F21: 1056.4 | G21: 1212.9 | H21: 1333.9 | I21: =I11*Assumptions!I38 -> 1406.0748 | J21: =J11*Assumptions!J38 -> 1473.5636 | K21: =K11*Assumptions!K38 -> 1523.2099 | L21: =L11*Assumptions!L38 -> 1561.8522 | M21: =M11*Assumptions!M38 -> 1607.0876
B22: % of Company sales | C22: % | D22: =D21/D11 -> 0.26181763 | E22: =E21/E11 -> 0.26084965 | F22: =F21/F11 -> 0.26657246 | G22: =G21/G11 -> 0.27748164 | H22: =H21/H11 -> 0.25001406 | I22: =I21/I11 -> 0.245 | J22: =J21/J11 -> 0.24625 | K22: =K21/K11 -> 0.2475 | ... M22: =M21/M11 -> 0.25
B23: Restaurant-Level Profit | C23: $M | D23: =D11-D17-D19-D21 -> 444.5 | E23: =E11-E17-E19-E21 -> 407.2 | F23: =F11-F17-F19-F21 -> 454.8 | G23: =G11-G17-G19-G21 -> 583.3 | H23: =H11-H17-H19-H21 -> 933.5 | I23: =I11-I17-I19-I21 -> 1021.5564 | J23: =J11-J17-J19-J21 -> 1045.7065 | K23: =K11-K17-K19-K21 -> 1055.4767 | ... M23: =M11-M17-M19-M21 -> 1060.6778
B24: Restaurant-Level Margin % | C24: % | D24: =D23/D11 -> 0.13555962 | E24: =E23/E11 -> 0.10969532 | F24: =F23/F11 -> 0.11476444 | G24: =G23/G11 -> 0.13344467 | H24: =H23/H11 -> 0.17496673 | I24: =I23/I11 -> 0.178 | J24: =J23/J11 -> 0.17475 | K24: =K23/K11 -> 0.1715 | ... M24: =M23/M11 -> 0.165
B25: Corporate costs
B26: Depreciation & amortization | C26: $M | D26: 150.2 | E26: 164.4 | F26: 168.5 | G26: 170.8 | H26: 206.6 | I26: =I13*Assumptions!I40 -> 226.37605 | J26: =J13*Assumptions!J40 -> 242.21361 | K26: =K13*Assumptions!K40 -> 249.23958 | L26: =L13*Assumptions!L40 -> 260.73445 | M26: =M13*Assumptions!M40 -> 267.02644 | O26: Costs that happen above the restaurant level at HQ: i) D&A — depreciation on restaurant buildings/equipment + intangibles amortization ii) G&A — corporate HQ staff, field leadership above GM, legal/audit, IT iii) Other (gains) & charges — impairments, litigation settlements, restructuring, one-timers. Forecast driven by Assumptions scenario toggles.
B27: General & administrative | C27: $M | D27: 134.8 | E27: 144.1 | F27: 172.8 | G27: 183.7 | H27: 222 | I27: =I13*Assumptions!I41 -> 237.98508 | J27: =J13*Assumptions!J41 -> 246.75512 | K27: =K13*Assumptions!K41 -> 252.35507 | L27: =L13*Assumptions!L41 -> 255.96491 | M27: =M13*Assumptions!M41 -> 260.5136
B28: Other (gains) and charges | C28: $M | D28: 19 | E28: 31.2 | F28: 24 | G28: 43.2 | H28: 41.8 | I28: =I13*Assumptions!I42 -> 29.02257 | J28: =J13*Assumptions!J42 -> 30.276702 | K28: =K13*Assumptions!K42 -> 31.154947 | L28: =L13*Assumptions!L42 -> 31.796884 | M28: =M13*Assumptions!M42 -> 32.564201
B29: Total operating costs and expenses | C29: $M | D29: =D17+D19+D21+D26+D27+D28 -> 3138.5 | E29: =E17+E19+E21+E26+E27+E28 -> 3644.6 | F29: =F17+F19+F21+F26+F27+F28 -> 3873.4 | G29: =G17+G19+G21+G26+G27+G28 -> 4185.5 | H29: =H17+H19+H21+H26+H27+H28 -> 4872.2 | I29: =I17+I19+I21+I26+I27+I28 -> 5210.9081 | J29: =J17+J19+J21+J26+J27+J28 -> 5457.5533 | K29: =K17+K19+K21+K26+K27+K28 -> 5631.6562 | ... M29: =M17+M19+M21+M26+M27+M28 -> 5927.777
B31: Operating Income (EBIT) | C31: $M | D31: =D13-D29 -> 199.3 | E31: =E13-E29 -> 159.5 | F31: =F13-F29 -> 180.7 | G31: =G13-G29 -> 229.6 | H31: =H13-H29 -> 512 | I31: =I13-I29 -> 593.60596 | J31: =J13-J29 -> 597.787 | K31: =K13-K29 -> 599.33316 | ... M31: =M13-M29 -> 585.06314
B32: Operating margin % | C32: % | D32: =D31/D13 -> 0.059709989 | E32: =E31/E13 -> 0.041928446 | F32: =F31/F13 -> 0.044572162 | G32: =G31/G13 -> 0.052003352 | H32: =H31/H13 -> 0.09509305 | I32: =I31/I13 -> 0.10226626 | J32: =J31/J13 -> 0.098720628 | K32: =K31/K13 -> 0.096185873 | ... M32: =M31/M13 -> 0.089832259
B34: Below-the-line
B35: Interest expense | C35: $M | D35: 56.2 | E35: 46.1 | F35: 54.4 | G35: 65 | H35: 53.1 | I35: =Assumptions!I60 -> 32.56625 | J35: =Assumptions!J60 -> 31.14875 | K35: =Assumptions!K60 -> 30.575 | L35: =Assumptions!L60 -> 30.575 | M35: =Assumptions!M60 -> 30.575 | O35: Items between EBIT and Net Income: i) Interest expense — flows from debt schedule (Assumptions row 60) ii) Other income, net — FX gains/losses and misc; typically immaterial (~$1M) iii) Taxes — provision = pretax income × effective tax rate (Assumptions I43) FY25 effective rate 16.7% depressed by SBC tax benefits; normalizing to ~23% by FY30E as benefits fade.
B36: Other income, net | C36: $M | D36: -2.1 | E36: -1.8 | F36: -1.6 | G36: -0.3 | H36: -1.1 | I36: -1 | J36: -1 | K36: -1 | L36: -1 | M36: -1
B37: Pre-tax income | C37: $M | D37: =D31-D35-D36 -> 145.2 | E37: =E31-E35-E36 -> 115.2 | F37: =F31-F35-F36 -> 127.9 | G37: =G31-G35-G36 -> 164.9 | H37: =H31-H35-H36 -> 460 | I37: =I31-I35-I36 -> 562.03971 | J37: =J31-J35-J36 -> 567.63825 | K37: =K31-K35-K36 -> 569.75816 | ... M37: =M31-M35-M36 -> 555.48814
B38: Provision for income taxes | C38: $M | D38: 13.6 | E38: -2.4 | F38: 10.9 | G38: 9.6 | H38: 76.9 | I38: =I37*Assumptions!I59 -> 95.54675 | J38: =J37*Assumptions!J59 -> 113.52765 | K38: =K37*Assumptions!K59 -> 125.34679 | L38: =L37*Assumptions!L59 -> 128.54959 | M38: =M37*Assumptions!M59 -> 127.76227
B39: Effective tax rate | C39: % | D39: =D38/D37 -> 0.093663912 | E39: =E38/E37 -> -0.020833333 | F39: =F38/F37 -> 0.08522283 | G39: =G38/G37 -> 0.058217101 | H39: =H38/H37 -> 0.16717391 | I39: =I38/I37 -> 0.17 | J39: =J38/J37 -> 0.2 | K39: =K38/K37 -> 0.22 | ... M39: =M38/M37 -> 0.23
B40: NET INCOME | C40: $M | D40: =D37-D38 -> 131.6 | E40: =E37-E38 -> 117.6 | F40: =F37-F38 -> 117 | G40: =G37-G38 -> 155.3 | H40: =H37-H38 -> 383.1 | I40: =I37-I38 -> 466.49296 | J40: =J37-J38 -> 454.1106 | K40: =K37-K38 -> 444.41136 | ... M40: =M37-M38 -> 427.72587
B41: Net margin % | C41: % | D41: =D40/D13 -> 0.039427168 | E41: =E40/E13 -> 0.030914014 | F41: =F40/F13 -> 0.028859673 | G41: =G40/G13 -> 0.035174741 | H41: =H40/H13 -> 0.071152632 | I41: =I40/I13 -> 0.080367271 | J41: =J40/J13 -> 0.074993407 | K41: =K40/K13 -> 0.07132276 | ... M41: =M40/M13 -> 0.065674247
B43: EPS & Share Count
B44: Diluted shares outstanding | C44: M | D44: 46.7 | E44: 45.4 | F44: 45.3 | G44: 45 | H44: 45.5 | I44: =Assumptions!I73 -> 44.076453 | J44: =Assumptions!J73 -> 42.762636 | K44: =Assumptions!K73 -> 41.543981 | L44: =Assumptions!L73 -> 40.403867 | M44: =Assumptions!M73 -> 39.313496 | O44: Diluted EPS = Net Income / Diluted Shares. Diluted share count derived on Assumptions from buyback math (prior shares − buybacks/price + SBC/price). Current ~45.5M diluted declining to ~38.5M by FY30E reflecting aggressive buyback program
B45: Diluted EPS (GAAP) | C45: $ | D45: =D40/D44 -> 2.8179872 | E45: =E40/E44 -> 2.5903084 | F45: =F40/F44 -> 2.5827815 | G45: =G40/G44 -> 3.4511111 | H45: =H40/H44 -> 8.4197802 | I45: =I40/I44 -> 10.583723 | J45: =J40/J44 -> 10.619331 | K45: =K40/K44 -> 10.697371 | ... M45: =M40/M44 -> 10.879874
B46: Diluted EPS growth | C46: % | E46: =E45/D45-1 -> -0.080794826 | F46: =F45/E45-1 -> -0.0029057981 | G46: =G45/F45-1 -> 0.33619943 | H46: =H45/G45-1 -> 1.4397303 | I46: =I45/H45-1 -> 0.257007 | J46: =J45/I45-1 -> 0.0033644856 | K46: =K45/J45-1 -> 0.0073487842 | L46: =L45/K45-1 -> -0.0042882716 | M46: =M45/L45-1 -> 0.021440762
B48: EBITDA & SBC
...

Sheet Balance Sheet
B2: Balance Sheet
B3: Brinker International (EAT)
B4: All amounts in $ millions unless noted
C6: Units | D6: =IF('Cover Page'!$C$63+0<'Cover Page'!$C$64,"FY"&TEXT(MOD('Cover Page'!$C$63+0,100),"00")&"A","FY"&TEXT(MOD('Cover Page'!$C$63+0,100),"00")&"E") -> FY21A | E6: =IF('Cover Page'!$C$63+1<'Cover Page'!$C$64,"FY"&TEXT(MOD('Cover Page'!$C$63+1,100),"00")&"A","FY"&TEXT(MOD('Cover Page'!$C$63+1,100),"00")&"E") -> FY22A | F6: =IF('Cover Page'!$C$63+2<'Cover Page'!$C$64,"FY"&TEXT(MOD('Cover Page'!$C$63+2,100),"00")&"A","FY"&TEXT(MOD('Cover Page'!$C$63+2,100),"00")&"E") -> FY23A | G6: =IF('Cover Page'!$C$63+3<'Cover Page'!$C$64,"FY"&TEXT(MOD('Cover Page'!$C$63+3,100),"00")&"A","FY"&TEXT(MOD('Cover Page'!$C$63+3,100),"00")&"E") -> FY24A | H6: =IF('Cover Page'!$C$63+4<'Cover Page'!$C$64,"FY"&TEXT(MOD('Cover Page'!$C$63+4,100),"00")&"A","FY"&TEXT(MOD('Cover Page'!$C$63+4,100),"00")&"E") -> FY25A | I6: =IF('Cover Page'!$C$63+5<'Cover Page'!$C$64,"FY"&TEXT(MOD('Cover Page'!$C$63+5,100),"00")&"A","FY"&TEXT(MOD('Cover Page'!$C$63+5,100),"00")&"E") -> FY26E | J6: =IF('Cover Page'!$C$63+6<'Cover Page'!$C$64,"FY"&TEXT(MOD('Cover Page'!$C$63+6,100),"00")&"A","FY"&TEXT(MOD('Cover Page'!$C$63+6,100),"00")&"E") -> FY27E | K6: =IF('Cover Page'!$C$63+7<'Cover Page'!$C$64,"FY"&TEXT(MOD('Cover Page'!$C$63+7,100),"00")&"A","FY"&TEXT(MOD('Cover Page'!$C$63+7,100),"00")&"E") -> FY28E | L6: =IF('Cover Page'!$C$63+8<'Cover Page'!$C$64,"FY"&TEXT(MOD('Cover Page'!$C$63+8,100),"00")&"A","FY"&TEXT(MOD('Cover Page'!$C$63+8,100),"00")&"E") -> FY29E | M6: =IF('Cover Page'!$C$63+9<'Cover Page'!$C$64,"FY"&TEXT(MOD('Cover Page'!$C$63+9,100),"00")&"A","FY"&TEXT(MOD('Cover Page'!$C$63+9,100),"00")&"E") -> FY30E
B8: Assets: | O8: Notes
B9: Current assets:
B10: Cash and cash equivalents | C10: $M | D10: 23.9 | E10: 13.5 | F10: 15.1 | G10: 64.6 | H10: 18.9 | I10: ='Cash Flow'!I32 -> 243.38238 | J10: ='Cash Flow'!J32 -> 476.71039 | K10: ='Cash Flow'!K32 -> 719.19446 | L10: ='Cash Flow'!L32 -> 972.17038 | M10: ='Cash Flow'!M32 -> 1240.5068 | O10: Brinker runs very lean on cash — uses $1B revolver for liquidity and deploys excess cash into buybacks. jumps FY26E-FY30E as model doesn't fully recycle excess FCF into buybacks/dividends.
B11: Accounts receivable, net | C11: $M | D11: 65.2 | E11: 66.4 | F11: 60.9 | G11: 60.6 | H11: 73.4 | I11: =H11*'Income Statement'!I13/'Income Statement'!H13 -> 79.129923 | J11: =I11*'Income Statement'!J13/'Income Statement'!I13 -> 82.549307 | K11: =J11*'Income Statement'!K13/'Income Statement'!J13 -> 84.943839 | L11: =K11*'Income Statement'!L13/'Income Statement'!K13 -> 86.694077 | M11: =L11*'Income Statement'!M13/'Income Statement'!L13 -> 88.786164 | O11: Mostly credit card recievables, but also franchise recievables and gift card recievables
B12: Inventories | C12: $M | D12: 28.9 | E12: 35.6 | F12: 34.5 | G12: 34.5 | H12: 35.2 | I12: =H12*'Income Statement'!I11/'Income Statement'!H11 -> 37.863971 | J12: =I12*'Income Statement'!J11/'Income Statement'!I11 -> 39.479937 | K12: =J12*'Income Statement'!K11/'Income Statement'!J11 -> 40.603958 | L12: =K12*'Income Statement'!L11/'Income Statement'!K11 -> 41.424823 | M12: =L12*'Income Statement'!M11/'Income Statement'!L11 -> 42.411474 | O12: Raw food and beverages. Not a whole lot of volume because inventory turns 1-2 weeks.
B13: Restaurant supplies | C13: $M | D13: 52.6 | E13: 55.5 | F13: 55.6 | G13: 53.8 | H13: 54.9 | I13: =H13*'Income Statement'!I11/'Income Statement'!H11 -> 59.054886 | J13: =I13*'Income Statement'!J11/'Income Statement'!I11 -> 61.575243 | K13: =J13*'Income Statement'!K11/'Income Statement'!J11 -> 63.328332 | L13: =K13*'Income Statement'!L11/'Income Statement'!K11 -> 64.608602 | M13: =L13*'Income Statement'!M11/'Income Statement'!L11 -> 66.147442 | O13: Smallwares, packaging, cleaning supps, uniforms, menus. Turnover is months not weeks
B14: Prepaid expenses | C14: $M | D14: 36.6 | E14: 30.2 | F14: 17.2 | G14: 20.6 | H14: 24.6 | I14: =H14*'Income Statement'!I13/'Income Statement'!H13 -> 26.520383 | J14: =I14*'Income Statement'!J13/'Income Statement'!I13 -> 27.666389 | K14: =J14*'Income Statement'!K13/'Income Statement'!J13 -> 28.468916 | L14: =K14*'Income Statement'!L13/'Income Statement'!K13 -> 29.055508 | M14: =L14*'Income Statement'!M13/'Income Statement'!L13 -> 29.756671 | O14: Insurance premiums, rent, enterprise software SaaS, licenses & permits
B15: Current assets | C15: $M | D15: =SUM(D10:D14) -> 207.2 | E15: =SUM(E10:E14) -> 201.2 | F15: =SUM(F10:F14) -> 183.3 | G15: =SUM(G10:G14) -> 234.1 | H15: =SUM(H10:H14) -> 207 | I15: =SUM(I10:I14) -> 445.95155 | J15: =SUM(J10:J14) -> 687.98126 | K15: =SUM(K10:K14) -> 936.53951 | ... M15: =SUM(M10:M14) -> 1467.6085
B17: Non-current assets:
B18: Net property & equipment | C18: $M | D18: 774.8 | E18: 816.7 | F18: 808.3 | G18: 879.7 | H18: 952.7 | I18: =H18+Assumptions!I66-'Income Statement'!I26 -> 987.52708 | J18: =I18+Assumptions!J66-'Income Statement'!J26 -> 1010.2346 | K18: =J18+Assumptions!K66-'Income Statement'!K26 -> 1025.8121 | L18: =K18+Assumptions!L66-'Income Statement'!L26 -> 1027.4019 | M18: =L18+Assumptions!M66-'Income Statement'!M26 -> 1020.8891 | O18: Owned buildings and improvements on leased buildings mostly but also furniture and equipment
B19: Operating lease assets | C19: $M | D19: 1007.4 | E19: 1160.5 | F19: 1134.9 | G19: 1095.2 | H19: 1149.1 | I19: =H19 -> 1149.1 | J19: =I19 -> 1149.1 | K19: =J19 -> 1149.1 | L19: =K19 -> 1149.1 | M19: =L19 -> 1149.1 | O19: Right to operate leased restaurants. Brinker leases most of its 1,113 Chili's + 49 Maggiano's locations.
B20: Goodwill | C20: $M | D20: 188.2 | E20: 195.1 | F20: 195 | G20: 194.8 | H20: 194.7 | I20: =H20 -> 194.7 | J20: =I20 -> 194.7 | K20: =J20 -> 194.7 | L20: =K20 -> 194.7 | M20: =L20 -> 194.7 | O20: FY22 frachise reaquisition + maggiano's acquisition in 1995
B21: Deferred income taxes, net | C21: $M | D21: 50.9 | E21: 62.5 | F21: 93.4 | G21: 113.9 | H21: 101.4 | I21: =H21 -> 101.4 | J21: =I21 -> 101.4 | K21: =J21 -> 101.4 | L21: =K21 -> 101.4 | M21: =L21 -> 101.4 | O21: Future tax savings from timing differences between GAAP book income and IRS taxable income.
B22: Intangibles, net | C22: $M | D22: 21.1 | E22: 27.4 | F22: 23.9 | G22: 19.9 | H22: 17.4 | I22: =H22 -> 17.4 | J22: =I22 -> 17.4 | K22: =J22 -> 17.4 | L22: =K22 -> 17.4 | M22: =L22 -> 17.4 | O22: Identifiable intangible assets from past acquisitions
B23: Other non-current assets | C23: $M | D23: 25.3 | E23: 21 | F23: 48.2 | G23: 55.5 | H23: 56.3 | I23: =H23-'Cash Flow'!I20 -> 54.3 | J23: =I23-'Cash Flow'!J20 -> 52.3 | K23: =J23-'Cash Flow'!K20 -> 50.3 | L23: =K23-'Cash Flow'!L20 -> 48.3 | M23: =L23-'Cash Flow'!M20 -> 46.3 | O23: Long-term marketable securities, long-term renteres deposits, life insurance deposits
B24: Total assets | C24: $M | D24: =D15+SUM(D18:D23) -> 2274.9 | E24: =E15+SUM(E18:E23) -> 2484.4 | F24: =F15+SUM(F18:F23) -> 2487 | G24: =G15+SUM(G18:G23) -> 2593.1 | H24: =H15+SUM(H18:H23) -> 2678.6 | I24: =I15+SUM(I18:I23) -> 2950.3786 | J24: =J15+SUM(J18:J23) -> 3213.1159 | K24: =K15+SUM(K18:K23) -> 3475.2516 | ... M24: =M15+SUM(M18:M23) -> 3997.3976
B26: Liabilities + Equity:
B27: Current liabilities:
B28: Accounts payable | C28: $M | D28: 127.7 | E28: 134.3 | F28: 125.7 | G28: 160.6 | H28: 168.5 | I28: =H28*'Income Statement'!I17/'Income Statement'!H17 -> 182.58104 | J28: =I28*'Income Statement'!J17/'Income Statement'!I17 -> 191.30647 | K28: =J28*'Income Statement'!K17/'Income Statement'!J17 -> 197.71287 | L28: =K28*'Income Statement'!L17/'Income Statement'!K17 -> 202.68908 | M28: =L28*'Income Statement'!M17/'Income Statement'!L17 -> 208.5192 | O28: Mostly food & beverage distributors, smallware suppliers, utilities, maintenance/R&M vendors, marketing agencies, and third-party tech providers
B29: Gift card liability | C29: $M | D29: 106.4 | E29: 83.9 | F29: 73 | G29: 64.8 | H29: 57.2 | I29: =H29 -> 57.2 | J29: =I29 -> 57.2 | K29: =J29 -> 57.2 | L29: =K29 -> 57.2 | M29: =L29 -> 57.2 | O29: Money received from customers (via gift card sales) but for which food/drink hasn't yet been delivered. Deferred revenue.
B30: Accrued payroll | C30: $M | D30: 122.4 | E30: 111 | F30: 106.1 | G30: 130.8 | H30: 156.2 | I30: =H30*'Income Statement'!I19/'Income Statement'!H19 -> 168.08659 | J30: =I30*'Income Statement'!J19/'Income Statement'!I19 -> 175.66844 | K30: =J30*'Income Statement'!K19/'Income Statement'!J19 -> 181.08968 | L30: =K30*'Income Statement'!L19/'Income Statement'!K19 -> 185.17898 | M30: =L30*'Income Statement'!M19/'Income Statement'!L19 -> 190.02808 | O30: Labor-related obligations earned by employees but not yet paid. Big number relative to AP — reflects that labor is Brinker's single largest cost line
B31: Current operating lease liabilities | C31: $M | D31: 97.7 | E31: 112.7 | F31: 112.4 | G31: 114.1 | H31: 114.6 | I31: =H31 -> 114.6 | J31: =I31 -> 114.6 | K31: =J31 -> 114.6 | L31: =K31 -> 114.6 | M31: =L31 -> 114.6 | O31: Next year's rent payments on leased restaurants, reported at the present value of scheduled cash payments.
B32: Other accrued liabilities | C32: $M | D32: 117.4 | E32: 116.1 | F32: 116.3 | G32: 144.7 | H32: 172.6 | I32: =H32*'Income Statement'!I13/'Income Statement'!H13 -> 186.07391 | J32: =I32*'Income Statement'!J13/'Income Statement'!I13 -> 194.11458 | K32: =J32*'Income Statement'!K13/'Income Statement'!J13 -> 199.74532 | L32: =K32*'Income Statement'!L13/'Income Statement'!K13 -> 203.861 | M32: =L32*'Income Statement'!M13/'Income Statement'!L13 -> 208.78054 | O32: Utilities, property taxes, advertising & markteing, professional fees, insurance, sales payable, interest on debt
B33: Income taxes payable, net | C33: $M | D33: 0 | E33: 0 | F33: 2.4 | G33: 7.3 | H33: 6.5 | I33: =H33 -> 6.5 | J33: =I33 -> 6.5 | K33: =J33 -> 6.5 | L33: =K33 -> 6.5 | M33: =L33 -> 6.5 | O33: Taaxes owed to the IRS and state authorities but not yet remitted
B34: Current liabilities | C34: $M | D34: =SUM(D28:D33) -> 571.6 | E34: =SUM(E28:E33) -> 558 | F34: =SUM(F28:F33) -> 535.9 | G34: =SUM(G28:G33) -> 622.3 | H34: =SUM(H28:H33) -> 675.6 | I34: =SUM(I28:I33) -> 715.04154 | J34: =SUM(J28:J33) -> 739.3895 | K34: =SUM(K28:K33) -> 756.84787 | ... M34: =SUM(M28:M33) -> 785.62782
B36: Non-current liabilities:
B37: Long-term debt & finance leases | C37: $M | D37: 917.9 | E37: 989.1 | F37: 912.2 | G37: 786.3 | H37: 426 | I37: =H37 -> 426 | J37: =I37 -> 426 | K37: =J37 -> 426 | L37: =K37 -> 426 | M37: =L37 -> 426 | O37: $350M Senior Notes (8.25% due 2030) + revolver + finance leases; tied to debt schedule on Assumptions.
B38: LT operating lease liabilities | C38: $M | D38: 1006.7 | E38: 1151.1 | F38: 1125.8 | G38: 1084.5 | H38: 1135.3 | I38: =H38 -> 1135.3 | J38: =I38 -> 1135.3 | K38: =J38 -> 1135.3 | L38: =K38 -> 1135.3 | M38: =L38 -> 1135.3 | O38: PV of future rent. Not 'debt' traditionally but rating agencies treat as debt-like.
B39: Other non-current liabilities | C39: $M | D39: 82 | E39: 54.3 | F39: 57.4 | G39: 60.6 | H39: 70.8 | I39: =H39+'Cash Flow'!I27 -> 75.8 | J39: =I39+'Cash Flow'!J27 -> 80.8 | K39: =J39+'Cash Flow'!K27 -> 85.8 | L39: =K39+'Cash Flow'!L27 -> 90.8 | M39: =L39+'Cash Flow'!M27 -> 95.8 | O39: Catch-all for long-term obligations. Uncertain tax positions, deferred comp for execs, asset retirement obligations, long-term workers' comp reserves.
B40: Total liabilities | C40: $M | D40: =D34+SUM(D37:D39) -> 2578.2 | E40: =E34+SUM(E37:E39) -> 2752.5 | F40: =F34+SUM(F37:F39) -> 2631.3 | G40: =G34+SUM(G37:G39) -> 2553.7 | H40: =H34+SUM(H37:H39) -> 2307.7 | I40: =I34+SUM(I37:I39) -> 2352.1415 | J40: =J34+SUM(J37:J39) -> 2381.4895 | K40: =K34+SUM(K37:K39) -> 2403.9479 | ... M40: =M34+SUM(M37:M39) -> 2442.7278
B42: Shareholders' equity:
B43: Common stock ($0.10 par) | C43: $M | D43: 7 | E43: 7 | F43: 6 | G43: 6 | H43: 6 | I43: =H43 -> 6 | J43: =I43 -> 6 | K43: =J43 -> 6 | L43: =K43 -> 6 | M43: =L43 -> 6 | O43: Par value of issued shares ($0.10 par × 60.3M shares issued).
B44: Additional paid-in capital | C44: $M | D44: 685.4 | E44: 690.9 | F44: 690 | G44: 707.8 | H44: 714.5 | I44: =H44+'Income Statement'!I55 -> 749.32708 | J44: =I44+'Income Statement'!J55 -> 785.65913 | K44: =J44+'Income Statement'!K55 -> 823.04506 | L44: =K44+'Income Statement'!L55 -> 861.20132 | M44: =L44+'Income Statement'!M55 -> 900.27836 | O44: Amount paid above par value when shares were originally issued, plus cumulative SBC expense recognized
B45: Accumulated OCI | C45: $M | D45: -4.7 | E45: -5.3 | F45: -6 | G45: -6.3 | H45: -6.4 | I45: =H45 -> -6.4 | J45: =I45 -> -6.4 | K45: =J45 -> -6.4 | L45: =K45 -> -6.4 | M45: =L45 -> -6.4 | O45: non-P&L equity items, mostly FX translation adjustments on foreign subsidiaries
B46: Retained earnings (Accumulated deficit) | C46: $M | D46: -266.1 | E46: -148.4 | F46: -351.9 | G46: -196.6 | H46: 186.5 | I46: =H46+'Income Statement'!I40+'Cash Flow'!I25 -> 652.99296 | J46: =I46+'Income Statement'!J40+'Cash Flow'!J25 -> 1107.1036 | K46: =J46+'Income Statement'!K40+'Cash Flow'!K25 -> 1551.5149 | L46: =K46+'Income Statement'!L40+'Cash Flow'!L25 -> 1981.8766 | M46: =L46+'Income Statement'!M40+'Cash Flow'!M25 -> 2409.6025 | O46: Was negative (Accumulated Deficit) through FY24 due to historical losses + large buybacks — flipped positive in FY25 as recent profitability caught up
B47: Treasury stock | C47: $M | D47: -724.9 | E47: -812.3 | F47: -482.4 | G47: -471.5 | H47: -529.7 | I47: =H47-Assumptions!I71 -> -803.68295 | J47: =I47-Assumptions!J71 -> -1060.7363 | K47: =J47-Assumptions!K71 -> -1302.8563 | L47: =K47-Assumptions!L71 -> -1532.5517 | M47: =L47-Assumptions!M71 -> -1754.811 | O47: Cumulative cost of all shares Brinker has repurchased and retired since inception. Reflects Brinker's aggressive capital return program
...

Sheet Cash Flow
B2: Cash Flow
B3: Brinker International (EAT)
B4: All amounts in $ millions unless noted
