Workbook
Name BaseYear: 'Cover Page'!$C$63
Name CompanyName: 'Cover Page'!$B$2
Name CurrentPrice: 'DCF & Sensitivity'!$D$51
Name ExitMultiple: Assumptions!$D$106
Name FirstForecastYear: 'Cover Page'!$C$64
Name NetDebt: 'DCF & Sensitivity'!$D$44
Name ScenarioRange: Assumptions!$E$9:$G$9
Name SharesOut: 'DCF & Sensitivity'!$D$47
Name TaxRate: 'DCF & Sensitivity'!$D$12
Name TerminalGrowth: Assumptions!$D$105
Name Ticker: 'Cover Page'!$B$3
Name WACC: Assumptions!$D$104

Sheet Cover Page
B2: GRACO INC.
B3: NYSE: GGG
B4: Industrial — Specialty Fluid Handling Equipment & Coatings
B6: Company Overview
B7: Sector | C7: Industrials: Specialty Industrial Machinery
B8: Brands | C8: Three segments: Contractor (paint sprayers ~48% of rev), Industrial (manufacturing/finishing ~45%), Expansion Markets (semis, oil & gas, environmental ~7%)
B9: Footprint | C9: Global manufacturing: HQ Minneapolis MN; major facilities in OH, MI, plus international (Italy, Switzerland, India, China). Sells in 60+ countries via distributor network. ~4,400 employees.
B10: Revenue Model | C10: Equipment & systems sales (point-of-shipment recognition); some service & contract revenue. Americas ~60%, EMEA ~24%, APAC ~16%.
B11: Capital Structure | C11: Essentially debt-free: $25M total debt (FY25), $624M cash = $600M+ net cash position. $750M revolver undrawn. $507M buyback authority outstanding.
B13: Valuation Snapshot
B14: Current Share Price | C14: ='DCF & Sensitivity'!D51 -> 80.76
B15: Base Case (Perpetuity Growth) | C15: ='DCF & Sensitivity'!D49 -> 61.712738
B16: Base Case (Exit Multiple, 15x) | C16: ='DCF & Sensitivity'!D50 -> 70.737056
B17: Upside/(Downside) vs Market (Blended) | C17: =AVERAGE(C15:C16)/C14-1 -> -0.17997899
B19: Key Assumptions
B20: WACC | C20: =Assumptions!D104 -> 0.08
B21: Terminal Growth Rate | C21: =Assumptions!D105 -> 0.025
B22: Exit EV/EBITDA Multiple | C22: =Assumptions!D106 -> 15
B23: Terminal EBITDA Margin | C23: =Assumptions!M57 -> 0.274
B24: Net Debt ($M) | C24: ='DCF & Sensitivity'!D44 -> -624.083
B25: Diluted Shares Outstanding (M) | C25: ='DCF & Sensitivity'!D47 -> 169.219
B27: Table of Contents
B28: › Summary
B29: Scenario Summary
B30: SWOT
B31: › Valuation
B32: Assumptions
B33: Revenue Build
B34: Income Statement
B35: Balance Sheet
B36: Cash Flow
B37: DCF & Sensitivity
B38: Comps
... B45: › Color Coding
B46: Blue text | C46: Hardcoded inputs and assumptions. Scenario drivers, historical data, WACC components.
B47: Black text | C47: Formulas and calculations that reference cells within the same sheet.
B48: Green text | C48: Cross-sheet links. Formulas pulling values from other tabs.
B49: › Number Conventions
B50: Amounts | C50: All $ values in millions ($M) unless labeled per-share ($/sh). Units column on each sheet confirms.
B51: Percentages | C51: Stored as decimals (0.125 = 12.5%) and displayed with 0.0% format
...

Sheet Scenario Summary
B2: Scenario Summary
B3: Graco Inc. (NYSE: GGG)
B4: Bear / Base / Bull scenarios side-by-side. Valuation from Shadow DCF tab (simplified model, scenario-specific drivers). Current market: $168/sh.
B5: The valuation outputs (share price & FY30E) values are simplified views of bear, base, and bull that reconcile within a material percentage of main model
B7: Valuation Summary | C7: Units | D7: Bear | E7: Base | F7: Bull | G7: Range (Bull − Bear)
B8: Implied Price — Perpetuity | C8: $/sh | D8: ='Shadow DCF'!D126 -> 23.995326 | E8: ='Shadow DCF'!E126 -> 45.166975 | F8: ='Shadow DCF'!F126 -> 102.87723 | G8: =F8-D8 -> 78.881899
B9: Implied Price — Exit Multiple | C9: $/sh | D9: ='Shadow DCF'!D127 -> 35.617127 | E9: ='Shadow DCF'!E127 -> 63.167838 | F9: ='Shadow DCF'!F127 -> 112.74784 | G9: =F9-D9 -> 77.130717
B10: Blended (avg of two methods) | C10: $/sh | D10: ='Shadow DCF'!D128 -> 29.806226 | E10: ='Shadow DCF'!E128 -> 54.167406 | F10: ='Shadow DCF'!F128 -> 107.81253 | G10: =F10-D10 -> 78.006308
B11: Current Share Price | C11: $/sh | D11: ='DCF & Sensitivity'!$D$51 -> 80.76 | E11: ='DCF & Sensitivity'!$D$51 -> 80.76 | F11: ='DCF & Sensitivity'!$D$51 -> 80.76 | G11: —
B12: Upside / (Downside) vs. market | C12: % | D12: =D10/D11-1 -> -0.63092835 | E12: =E10/E11-1 -> -0.32927927 | F12: =F10/F11-1 -> 0.33497442 | G12: =F12-D12 -> 0.96590277
B14: Scenario Drivers | C14: Units | D14: Bear | E14: Base | F14: Bull | G14: ="FY"&TEXT(MOD('Cover Page'!$C$64-1,100),"00")&"A" -> FY25A
B15: REVENUE
B16: Contractor
B17: Contractor Organic Growth | C17: % | D17: =Assumptions!E12 -> -0.02 | E17: =Assumptions!F12 -> 0.01 | F17: =Assumptions!G12 -> 0.04 | G17: 0.084
B18: Contractor Acquisitions | C18: % | D18: =Assumptions!E13 -> 0.01 | E18: =Assumptions!F13 -> 0.03 | F18: =Assumptions!G13 -> 0.06 | G18: 0
B19: Industrial
B20: Industrial Organic Growth | C20: % | D20: =Assumptions!E15 -> -0.02 | E20: =Assumptions!F15 -> 0.03 | F20: =Assumptions!G15 -> 0.05 | G20: 0.039
B21: Industrial Acquisitions | C21: % | D21: =Assumptions!E16 -> 0.01 | E21: =Assumptions!F16 -> 0.02 | F21: =Assumptions!G16 -> 0.04 | G21: 0
B22: Expansion
B23: Expansion Organic Growth | C23: % | D23: =Assumptions!E18 -> -0.05 | E23: =Assumptions!F18 -> 0.03 | F23: =Assumptions!G18 -> 0.08 | G23: 0.009
B24: Expansion Acquisitions | C24: % | D24: =Assumptions!E19 -> 0.01 | E24: =Assumptions!F19 -> 0.03 | F24: =Assumptions!G19 -> 0.08 | G24: 0
B25: FX Impact | C25: % | D25: =Assumptions!E20 -> -0.01 | E25: =Assumptions!F20 -> 0.01 | F25: =Assumptions!G20 -> 0.02 | G25: 0.005
B26: COST (As a % of Revenue)
B27: Cost of Products Sold | C27: % | D27: =Assumptions!E22 -> 0.5 | E27: =Assumptions!F22 -> 0.475 | F27: =Assumptions!G22 -> 0.45 | G27: =Assumptions!H52 -> 0.47545381
B28: Product Development | C28: % | D28: =Assumptions!E23 -> 0.042 | E28: =Assumptions!F23 -> 0.038 | F28: =Assumptions!G23 -> 0.035 | G28: =Assumptions!H54 -> 0.036796924
B29: Selling, Marketing, & Dist | C29: % | D29: =Assumptions!E24 -> 0.135 | E29: =Assumptions!F24 -> 0.125 | F29: =Assumptions!G24 -> 0.115 | G29: =Assumptions!H55 -> 0.12246267
B30: G&A | C30: % | D30: =Assumptions!E25 -> 0.095 | E30: =Assumptions!F25 -> 0.088 | F30: =Assumptions!G25 -> 0.08 | G30: =Assumptions!H56 -> 0.092193508
B31: CASH CONVERSION CYCLE
B32: Days Inventory Outstanding (DIO) | C32: days | D32: =Assumptions!E27 -> 145 | E32: =Assumptions!F27 -> 138 | F32: =Assumptions!G27 -> 130 | G32: =Assumptions!H77 -> 137.68607
B33: Days Sales Outstanding (DSO) | C33: days | D33: =Assumptions!E28 -> 60 | E33: =Assumptions!F28 -> 62 | F33: =Assumptions!G28 -> 58 | G33: =Assumptions!H76 -> 64.25818
B34: Days Payables Outstanding (DPO) | C34: days | D34: =Assumptions!E29 -> 30 | E34: =Assumptions!F29 -> 27 | F34: =Assumptions!G29 -> 32 | G34: =Assumptions!H78 -> 26.969292
B35: CAPITAL ALLOCATION
B36: CapEx % (as a % of revenue) | C36: % | D36: =Assumptions!E31 -> 0.038 | E36: =Assumptions!F31 -> 0.042 | F36: =Assumptions!G31 -> 0.05 | G36: =Assumptions!H80 -> 0.020418939
B37: Buybacks % (as a % of FCF) | C37: % | D37: =Assumptions!E32 -> 0.3 | E37: =Assumptions!F32 -> 0.5 | F37: =Assumptions!G32 -> 0.7 | G37: =Assumptions!D32 -> 0.6
B38: Acquisition Spend ($M/year) | C38: $M | D38: =Assumptions!E33 -> 50 | E38: =Assumptions!F33 -> 100 | F38: =Assumptions!G33 -> 200 | G38: =Assumptions!D33 -> 135
B39: VALUATION
B40: Terminal Growth Rate | C40: % | D40: =Assumptions!E35 -> 0.02 | E40: =Assumptions!F35 -> 0.025 | F40: =Assumptions!G35 -> 0.03 | G40: n/a
B41: Exit EV / EBITDA Multiple | C41: x | D41: =Assumptions!E36 -> 13 | E41: =Assumptions!F36 -> 15 | F41: =Assumptions!G36 -> 18 | G41: =Assumptions!D36 -> 17.6
B42: WACC | C42: % | D42: =Assumptions!E37 -> 0.1 | E42: =Assumptions!F37 -> 0.08 | F42: =Assumptions!G37 -> 0.06 | G42: =Assumptions!D37 -> 0.107
B44: FY30E Model Outputs | C44: Units | D44: Bear | E44: Base | F44: Bull
...

Sheet SWOT
B2: SWOT Analysis
B3: Graco Inc. (NYSE: GGG)
C5: Helpful (to achieving objectives) | H5: Harmful (to achieving objectives)
B6: INTERNAL | C6: STRENGTHS | H6: WEAKNESSES
C7: • Strong margins: 33% EBITDA margin, 28.5% FCF margin (peer-leading ex-Roper); ROIC ~24% sustained over 5 years | H7: • Cyclical end-market exposure: Contractor segment tied to U.S. residential/commercial construction; Industrial tied to manufacturing capex
C8: • Niche pricing power: 52-53% gross margin reflects specialty fluid-handling moat in difficult-to-handle materials. Peer median ~38% but Nordson - most direct compeitior - is around the same GM. | H8: • US construction soft in recent periods; FY25 Contractor organic growth muted, masked by acquisitions and FX tailwind
C9: • Strong balance sheet: $624M cash, ~$25M debt = $600M+ net cash; 100-year operating history with consistent dividend increases for 25+ years | H9: • Heavy reliance on a few large channel partners in Contractor segment (Sherwin-Williams, Home Depot/Sam's Club)
C10: • Diversified end markets: Contractor (paint sprayers ~48%), Industrial (manufacturing/automotive/finishing ~45%), Expansion (semis, oil & gas ~7%) | H10: • Mature business in mature end markets, there is a ceiling to growth and most likely the company will stay within low-single digits
C11: • Capital return engine: $423M buybacks + $183M dividends in FY25 = $606M returned (~89% of FCF) | H11: • R&D intensity below specialty peers: Graco spends ~3.7% of revenue on Product Development vs. Nordson at ~5%+
C12: • Geographic balance: Americas ~60%, EMEA ~24%, APAC ~16% — reduces single-region exposure
B15: EXTERNAL | C15: OPPORTUNITIES | H15: THREATS
C16: • M&A pipeline: 100+ name pipeline per mgmt; FY24-25 closed Corob (€230M), Color Service (€63M), Radia ($69M); $190M run-rate revenue from acquisitions | H16: • Tariff exposure: $4M Q4 FY25 hit to gross margin (70bps) from increased product costs; ongoing tariff and supply chain risk
C17: • ETM electric pump licensing: high-torque motor IP being licensed to OEMs/motor manufacturers; royalties not in current guidance — incremental upside | H17: • Industrial production weakness: end markets remain soft; macroeconomic uncertainty cited by mgmt as biggest near-term headwind
C18: • One Graco operating model launch (2025) — organizational leverage from consolidation | H18: • Valuation premium: trades at 17x EV/EBITDA, ~5% premium to closest comps (NDSN, IEX); limited multiple expansion room
C19: • Capex normalization: FY25 capex spiked low ($46M) post heavy FY21-23 buildout cycle; sustained low maintenance capex would lift FCF | H19: • Currency translation risk: 40% of revenue outside USA; EUR/CNY/GBP fluctuations swing reported results materially
H20: • Acquisition integration risk: 3 acquisitions in 18 months (Corob/Color Service/Radia); execution risk if integration falters or earnouts trigger

Sheet Valuation >>>
B18: Valuation >>>

Sheet Assumptions
B2: Assumptions
B3: Graco Inc. (NYSE: GGG)
B4: All $ in millions unless noted. Fiscal year ends last Wednesday in June.
B7: SCENARIO SELECTOR
B8: FY26E anchored to mgmt's guidance where given. FY27-FY30 interpolate linearly between FY26 start and scenario terminal values. Each driver toggles independently via column H dropdown.
B9: Metric | C9: Units | D9: FY26E Start | E9: Bear | F9: Base | G9: Bull | H9: Scenario
B10: REVENUE
B11: Contractor
B12: Contractor Organic Growth | C12: % | D12: 0.01 | E12: -0.02 | F12: 0.01 | G12: 0.04 | H12: Base
B13: Contractor Acquisitions | C13: % | D13: 0.03 | E13: 0.01 | F13: 0.03 | G13: 0.06 | H13: Base
B14: Industrial
B15: Industrial Organic Growth | C15: % | D15: 0.03 | E15: -0.02 | F15: 0.03 | G15: 0.05 | H15: Base
B16: Industrial Acquisitions | C16: % | D16: 0.02 | E16: 0.01 | F16: 0.02 | G16: 0.04 | H16: Base
B17: Expansion
B18: Expansion Organic Growth | C18: % | D18: 0.03 | E18: -0.05 | F18: 0.03 | G18: 0.08 | H18: Base
B19: Expansion Acquisitions | C19: % | D19: 0.03 | E19: 0.01 | F19: 0.03 | G19: 0.08 | H19: Base
B20: FX Impact | C20: % | D20: 0.01 | E20: -0.01 | F20: 0.01 | G20: 0.02 | H20: Base
B21: COST (As a % of Revenue)
B22: Cost of Products Sold | C22: % | D22: 0.475 | E22: 0.5 | F22: 0.475 | G22: 0.45 | H22: Base
B23: Product Development | C23: % | D23: 0.038 | E23: 0.042 | F23: 0.038 | G23: 0.035 | H23: Base
B24: Selling, Marketing, & Dist | C24: % | D24: 0.125 | E24: 0.135 | F24: 0.125 | G24: 0.115 | H24: Base
B25: G&A | C25: % | D25: 0.088 | E25: 0.095 | F25: 0.088 | G25: 0.08 | H25: Base
B26: CASH CONVERSION CYCLE
B27: Days Inventory Outstanding (DIO) | C27: days | D27: 137.5 | E27: 145 | F27: 138 | G27: 130 | H27: Base
B28: Days Sales Outstanding (DSO) | C28: days | D28: 65 | E28: 60 | F28: 62 | G28: 58 | H28: Base
B29: Days Payables Outstanding (DPO) | C29: days | D29: 25 | E29: 30 | F29: 27 | G29: 32 | H29: Base
B30: CAPITAL ALLOCATION
B31: CapEx % (as a % of revenue) | C31: % | D31: 0.062 | E31: 0.038 | F31: 0.042 | G31: 0.05 | H31: Base
B32: Buybacks % (as a % of FCF) | C32: % | D32: 0.6 | E32: 0.3 | F32: 0.5 | G32: 0.7 | H32: Base
B33: Acquisition Spend ($M/year) | C33: $M | D33: 135 | E33: 50 | F33: 100 | G33: 200 | H33: Base
B34: VALUATION
B35: Terminal Growth Rate | C35: % | D35: 0.025 | E35: 0.02 | F35: 0.025 | G35: 0.03 | H35: Base
B36: Exit EV / EBITDA Multiple | C36: x | D36: 17.6 | E36: 13 | F36: 15 | G36: 18 | H36: Base
B37: WACC | C37: % | D37: 0.107 | E37: 0.1 | F37: 0.08 | G37: 0.06 | H37: Base
B39: Revenue Drivers | C39: Units | D39: =IF('Cover Page'!$C$63+0<'Cover Page'!$C$64,"FY"&TEXT(MOD('Cover Page'!$C$63+0,100),"00")&"A","FY"&TEXT(MOD('Cover Page'!$C$63+0,100),"00")&"E") -> FY21A | E39: =IF('Cover Page'!$C$63+1<'Cover Page'!$C$64,"FY"&TEXT(MOD('Cover Page'!$C$63+1,100),"00")&"A","FY"&TEXT(MOD('Cover Page'!$C$63+1,100),"00")&"E") -> FY22A | F39: =IF('Cover Page'!$C$63+2<'Cover Page'!$C$64,"FY"&TEXT(MOD('Cover Page'!$C$63+2,100),"00")&"A","FY"&TEXT(MOD('Cover Page'!$C$63+2,100),"00")&"E") -> FY23A | G39: =IF('Cover Page'!$C$63+3<'Cover Page'!$C$64,"FY"&TEXT(MOD('Cover Page'!$C$63+3,100),"00")&"A","FY"&TEXT(MOD('Cover Page'!$C$63+3,100),"00")&"E") -> FY24A | H39: =IF('Cover Page'!$C$63+4<'Cover Page'!$C$64,"FY"&TEXT(MOD('Cover Page'!$C$63+4,100),"00")&"A","FY"&TEXT(MOD('Cover Page'!$C$63+4,100),"00")&"E") -> FY25A | I39: =IF('Cover Page'!$C$63+5<'Cover Page'!$C$64,"FY"&TEXT(MOD('Cover Page'!$C$63+5,100),"00")&"A","FY"&TEXT(MOD('Cover Page'!$C$63+5,100),"00")&"E") -> FY26E | J39: =IF('Cover Page'!$C$63+6<'Cover Page'!$C$64,"FY"&TEXT(MOD('Cover Page'!$C$63+6,100),"00")&"A","FY"&TEXT(MOD('Cover Page'!$C$63+6,100),"00")&"E") -> FY27E | K39: =IF('Cover Page'!$C$63+7<'Cover Page'!$C$64,"FY"&TEXT(MOD('Cover Page'!$C$63+7,100),"00")&"A","FY"&TEXT(MOD('Cover Page'!$C$63+7,100),"00")&"E") -> FY28E | L39: =IF('Cover Page'!$C$63+8<'Cover Page'!$C$64,"FY"&TEXT(MOD('Cover Page'!$C$63+8,100),"00")&"A","FY"&TEXT(MOD('Cover Page'!$C$63+8,100),"00")&"E") -> FY29E | M39: =IF('Cover Page'!$C$63+9<'Cover Page'!$C$64,"FY"&TEXT(MOD('Cover Page'!$C$63+9,100),"00")&"A","FY"&TEXT(MOD('Cover Page'!$C$63+9,100),"00")&"E") -> FY30E | O39: Notes
B40: Contractor | C40: $M | D40: ='Revenue Build'!D43 -> 987.6 | E40: ='Revenue Build'!E43 -> 999.1 | F40: ='Revenue Build'!F43 -> 985.7 | G40: ='Revenue Build'!G43 -> 988.9 | H40: ='Revenue Build'!H43 -> 1071.9 | I40: ='Revenue Build'!I43 -> 1125.495 | J40: ='Revenue Build'!J43 -> 1181.7698 | K40: ='Revenue Build'!K43 -> 1240.8582 | ... M40: ='Revenue Build'!M43 -> 1368.0462 | O40: Revenue build by segment (Contractor, Industrial, Expansion). Drives top-line forecast off scenario-selected growth rates. Contractor (~48% of revenue) is the largest segment and most cyclical; Industrial is the highest-margin business; Expansion Markets is the smallest but fastest-growing.
B41: Industrial | C41: $M | D41: ='Revenue Build'!D51 -> 864.6 | E41: ='Revenue Build'!E51 -> 972.7 | F41: ='Revenue Build'!F51 -> 1018.2 | G41: ='Revenue Build'!G51 -> 958 | H41: ='Revenue Build'!H51 -> 996.8 | I41: ='Revenue Build'!I51 -> 1056.608 | J41: ='Revenue Build'!J51 -> 1120.0045 | K41: ='Revenue Build'!K51 -> 1187.2047 | ... M41: ='Revenue Build'!M51 -> 1333.9433
B42: Expansion | C42: $M | D42: ='Revenue Build'!D59 -> 135.4 | E42: ='Revenue Build'!E59 -> 171.7 | F42: ='Revenue Build'!F59 -> 191.7 | G42: ='Revenue Build'!G59 -> 166.4 | H42: ='Revenue Build'!H59 -> 167.9 | I42: ='Revenue Build'!I59 -> 179.653 | J42: ='Revenue Build'!J59 -> 192.22871 | K42: ='Revenue Build'!K59 -> 205.68472 | ... M42: ='Revenue Build'!M59 -> 235.48844
B43: Total Revenue | C43: $M | D43: ='Revenue Build'!D61 -> 1987.6 | E43: ='Revenue Build'!E61 -> 2143.5 | F43: ='Revenue Build'!F61 -> 2195.6 | G43: ='Revenue Build'!G61 -> 2113.3 | H43: ='Revenue Build'!H61 -> 2236.6 | I43: ='Revenue Build'!I61 -> 2361.756 | J43: ='Revenue Build'!J61 -> 2494.0029 | K43: ='Revenue Build'!K61 -> 2633.7477 | ... M43: ='Revenue Build'!M61 -> 2937.4779
B44: YoY Growth % | E44: =(E43-D43)/D43 -> 0.078436305 | F44: =(F43-E43)/E43 -> 0.024306042 | G44: =(G43-F43)/F43 -> -0.037484059 | H44: =(H43-G43)/G43 -> 0.058344769 | I44: =(I43-H43)/H43 -> 0.055958151 | J44: =(J43-I43)/I43 -> 0.055995175 | K44: =(K43-J43)/J43 -> 0.056032318 | L44: =(L43-K43)/K43 -> 0.05606958 | M44: =(M43-L43)/L43 -> 0.056106959
...

Sheet Revenue Build
B2: Revenue Build
B3: Graco Inc. (NYSE: GGG)
B4: All amounts in $ millions unless noted
B6: Revenue Build Overview
B7: This tab is a high-level segment-level revenue bridge: BoP Revenue × (1 + Organic % + Acquisitions % + FX %) = EoP Revenue, applied separately to each segment (Contractor, Industrial, Expansion) and rolled to consolidated. Historicals tie to filed numbers; forecasts pull growth assumptions from the Assumptions tab via a scenario switch. This enables an easier understanding of the model and quick scenario analysis - flex one growth rate and watch the total roll forward. Graco's investor matierials only break out metrics at the business unit level. What this build cannot do is explain the drivers behind growth — price vs. volume, which tier, which sales channel, which geography, aftermarket vs. new equipment, or how M&A integrates into the revenue base. The growth rate is the assumption; there is no underlying logic within this model supporting the growth rates at a more granular level. An ideal revenue decomposition is illustrated on the orange-colored tabs (Rev Build - PF1 - Airless Spray, Rev Build - PF2 - Powder Coat, Rev Build - BU 1 - Contractor). Those derive segment growth from Units × ASP by tier, Installed Base × Attach Rate for aftermarket, Service & Integration contracts, deal-by-deal M&A, and FX on a weighted currency-exposure base. Inputs are real business mechanics, not top-line growth rates. Those tabs demonstrate that we would have a build for each product family feeding into business segment tabs, which would roll up to a consolidated company-level view like the one presented below. In that architecture, the growth rates on this tab stop being standalone inputs and become outputs of the bottoms-up work — this tab becomes the presentation layer, the bottoms-up tabs become the justification layer.
C13: Units | D13: FY21A | E13: FY22A | F13: FY23A | G13: FY24A | H13: FY25A | I13: FY26E | J13: FY27E | K13: FY28E | L13: FY29E | M13: FY30E
B15: Consolidated Revenue Bridge
B16: BOP Revenue | C16: $M | D16: 1842 | E16: =D21 -> 1989.36 | F16: =E21 -> 2148.5088 | G16: =F21 -> 2191.479 | H16: =G21 -> 2103.8198
B17: Organic Growth % | C17: % | D17: 0.11 | E17: 0.11 | F17: 0.02 | G17: -0.04 | H17: 0
B18: Acquisitions Growth % | C18: % | D18: 0.01 | E18: 0.01 | F18: 0 | G18: 0.01 | H18: 0.05
B19: Currency % | C19: % | D19: -0.04 | E19: -0.04 | F19: 0 | G19: -0.01 | H19: 0.01
B20: Total Growth % | C20: % | D20: =SUM(D17:D19) -> 0.08 | E20: =SUM(E17:E19) -> 0.08 | F20: =SUM(F17:F19) -> 0.02 | G20: =SUM(G17:G19) -> -0.04 | H20: =SUM(H17:H19) -> 0.06
B21: Total Revenue (Growth %) | C21: $M | D21: =D16*(D20+1) -> 1989.36 | E21: =E16*(E20+1) -> 2148.5088 | F21: =F16*(F20+1) -> 2191.479 | G21: =G16*(G20+1) -> 2103.8198 | H21: =H16*(H20+1) -> 2230.049
B23: Revenue by Geography
B24: USA | C24: $M | E24: 1116 | F24: 1162 | G24: 1329.3 | H24: 1353
B25: EMEA | C25: $M | E25: 451.8 | F25: 463.9 | G25: 454.2 | H25: 527.5
B26: Asia Pacific | C26: $M | E26: 409.8 | F26: 393.7 | G26: 329.8 | H26: 356.1
B27: Other Americas | C27: $M | E27: 165.9 | F27: 176 | G27: 0 | H27: 0
B28: Total Revenue (Geo) | C28: $M | E28: =SUM(E24:E27) -> 2143.5 | F28: =SUM(F24:F27) -> 2195.6 | G28: =SUM(G24:G27) -> 2113.3
B30: Segment Revenue (Old Naming)
B31: Contractor | C31: $M | E31: 999.1 | F31: 985.7 | G31: 988.9
B32: Industrial | C32: $M | E32: 649.3 | F32: 662.8 | G32: 619.6
B33: Process | C33: $M | E33: 495.1 | F33: 547.1 | G33: 504.8
B34: Total Revenue (Old Segments) | C34: $M | E34: =SUM(E31:E33) -> 2143.5 | F34: =SUM(F31:F33) -> 2195.6 | G34: =SUM(G31:G33) -> 2113.3
B36: Segment Revenue
B37: › Contractor
B38: BoP Revenue | E38: =D43 -> 987.6 | F38: =E43 -> 999.1 | G38: =F43 -> 985.7 | H38: =G43 -> 988.9 | I38: =H43 -> 1071.9 | J38: =I43 -> 1125.495 | K38: =J43 -> 1181.7698 | L38: =K43 -> 1240.8582 | M38: =L43 -> 1302.9011
B39: Organic Growth % | E39: 0.04 | F39: -0.01 | G39: -0.01 | H39: -0.02 | I39: =Assumptions!$D$12 -> 0.01 | J39: =$I39+(INDEX(Assumptions!$E$12:$G$12,MATCH(Assumptions!$H$12,Assumptions!$E$9:$G$9,0))-$I39)*(COLUMN()-COLUMN($I39))/4 -> 0.01 | K39: =$I39+(INDEX(Assumptions!$E$12:$G$12,MATCH(Assumptions!$H$12,Assumptions!$E$9:$G$9,0))-$I39)*(COLUMN()-COLUMN($I39))/4 -> 0.01 | L39: =$I39+(INDEX(Assumptions!$E$12:$G$12,MATCH(Assumptions!$H$12,Assumptions!$E$9:$G$9,0))-$I39)*(COLUMN()-COLUMN($I39))/4 -> 0.01 | M39: =$I39+(INDEX(Assumptions!$E$12:$G$12,MATCH(Assumptions!$H$12,Assumptions!$E$9:$G$9,0))-$I39)*(COLUMN()-COLUMN($I39))/4 -> 0.01
B40: Acquisitions % | E40: 0 | F40: 0 | G40: 0.02 | H40: 0.1 | I40: =Assumptions!$D$13 -> 0.03 | J40: =$I40+(INDEX(Assumptions!$E$13:$G$13,MATCH(Assumptions!$H$13,Assumptions!$E$9:$G$9,0))-$I40)*(COLUMN()-COLUMN($I40))/4 -> 0.03 | K40: =$I40+(INDEX(Assumptions!$E$13:$G$13,MATCH(Assumptions!$H$13,Assumptions!$E$9:$G$9,0))-$I40)*(COLUMN()-COLUMN($I40))/4 -> 0.03 | L40: =$I40+(INDEX(Assumptions!$E$13:$G$13,MATCH(Assumptions!$H$13,Assumptions!$E$9:$G$9,0))-$I40)*(COLUMN()-COLUMN($I40))/4 -> 0.03 | M40: =$I40+(INDEX(Assumptions!$E$13:$G$13,MATCH(Assumptions!$H$13,Assumptions!$E$9:$G$9,0))-$I40)*(COLUMN()-COLUMN($I40))/4 -> 0.03
B41: Currency % | E41: -0.03 | F41: 0 | G41: -0.01 | H41: 0 | I41: =Assumptions!$D$20 -> 0.01 | J41: =$I41+(INDEX(Assumptions!$E$20:$G$20,MATCH(Assumptions!$H$20,Assumptions!$E$9:$G$9,0))-$I41)*(COLUMN()-COLUMN($I41))/4 -> 0.01 | K41: =$I41+(INDEX(Assumptions!$E$20:$G$20,MATCH(Assumptions!$H$20,Assumptions!$E$9:$G$9,0))-$I41)*(COLUMN()-COLUMN($I41))/4 -> 0.01 | L41: =$I41+(INDEX(Assumptions!$E$20:$G$20,MATCH(Assumptions!$H$20,Assumptions!$E$9:$G$9,0))-$I41)*(COLUMN()-COLUMN($I41))/4 -> 0.01 | M41: =$I41+(INDEX(Assumptions!$E$20:$G$20,MATCH(Assumptions!$H$20,Assumptions!$E$9:$G$9,0))-$I41)*(COLUMN()-COLUMN($I41))/4 -> 0.01
B42: Total Growth % | E42: =SUM(E39:E41) -> 0.01 | F42: =SUM(F39:F41) -> -0.01 | G42: =SUM(G39:G41) -> 0 | H42: =SUM(H39:H41) -> 0.08 | I42: =SUM(I39:I41) -> 0.05 | J42: =SUM(J39:J41) -> 0.05 | K42: =SUM(K39:K41) -> 0.05 | L42: =SUM(L39:L41) -> 0.05 | M42: =SUM(M39:M41) -> 0.05
B43: EOP Revenue | D43: 987.6 | E43: 999.1 | F43: 985.7 | G43: 988.9 | H43: 1071.9 | I43: =I38*(1+I42) -> 1125.495 | J43: =J38*(1+J42) -> 1181.7698 | K43: =K38*(1+K42) -> 1240.8582 | L43: =L38*(1+L42) -> 1302.9011 | M43: =M38*(1+M42) -> 1368.0462
B44: Check | E44: =(E38*(E42+1))-E43 -> -1.624 | F44: =(F38*(F42+1))-F43 -> 3.409 | G44: =(G38*(G42+1))-G43 -> -3.2 | H44: =(H38*(H42+1))-H43 -> -3.888
B45: › Industrial
B46: BoP Revenue | E46: =D51 -> 864.6 | F46: =E51 -> 972.7 | G46: =F51 -> 1018.2 | H46: =G51 -> 958 | I46: =H51 -> 996.8 | J46: =I51 -> 1056.608 | K46: =J51 -> 1120.0045 | L46: =K51 -> 1187.2047 | M46: =L51 -> 1258.437
B47: Organic Growth % | E47: 0.18 | F47: 0.05 | G47: -0.05 | H47: 0.02 | I47: =Assumptions!$D$15 -> 0.03 | J47: =$I47+(INDEX(Assumptions!$E$15:$G$15,MATCH(Assumptions!$H$15,Assumptions!$E$9:$G$9,0))-$I47)*(COLUMN()-COLUMN($I47))/4 -> 0.03 | K47: =$I47+(INDEX(Assumptions!$E$15:$G$15,MATCH(Assumptions!$H$15,Assumptions!$E$9:$G$9,0))-$I47)*(COLUMN()-COLUMN($I47))/4 -> 0.03 | L47: =$I47+(INDEX(Assumptions!$E$15:$G$15,MATCH(Assumptions!$H$15,Assumptions!$E$9:$G$9,0))-$I47)*(COLUMN()-COLUMN($I47))/4 -> 0.03 | M47: =$I47+(INDEX(Assumptions!$E$15:$G$15,MATCH(Assumptions!$H$15,Assumptions!$E$9:$G$9,0))-$I47)*(COLUMN()-COLUMN($I47))/4 -> 0.03
B48: Acquisitions % | E48: 0 | F48: 0 | G48: 0 | H48: 0.01 | I48: =Assumptions!$D$16 -> 0.02 | J48: =$I48+(INDEX(Assumptions!$E$16:$G$16,MATCH(Assumptions!$H$16,Assumptions!$E$9:$G$9,0))-$I48)*(COLUMN()-COLUMN($I48))/4 -> 0.02 | K48: =$I48+(INDEX(Assumptions!$E$16:$G$16,MATCH(Assumptions!$H$16,Assumptions!$E$9:$G$9,0))-$I48)*(COLUMN()-COLUMN($I48))/4 -> 0.02 | L48: =$I48+(INDEX(Assumptions!$E$16:$G$16,MATCH(Assumptions!$H$16,Assumptions!$E$9:$G$9,0))-$I48)*(COLUMN()-COLUMN($I48))/4 -> 0.02 | M48: =$I48+(INDEX(Assumptions!$E$16:$G$16,MATCH(Assumptions!$H$16,Assumptions!$E$9:$G$9,0))-$I48)*(COLUMN()-COLUMN($I48))/4 -> 0.02
B49: Currency % | E49: -0.05 | F49: 0 | G49: 0 | H49: 0.01 | I49: =Assumptions!$D$20 -> 0.01 | J49: =$I49+(INDEX(Assumptions!$E$20:$G$20,MATCH(Assumptions!$H$20,Assumptions!$E$9:$G$9,0))-$I49)*(COLUMN()-COLUMN($I49))/4 -> 0.01 | K49: =$I49+(INDEX(Assumptions!$E$20:$G$20,MATCH(Assumptions!$H$20,Assumptions!$E$9:$G$9,0))-$I49)*(COLUMN()-COLUMN($I49))/4 -> 0.01 | L49: =$I49+(INDEX(Assumptions!$E$20:$G$20,MATCH(Assumptions!$H$20,Assumptions!$E$9:$G$9,0))-$I49)*(COLUMN()-COLUMN($I49))/4 -> 0.01 | M49: =$I49+(INDEX(Assumptions!$E$20:$G$20,MATCH(Assumptions!$H$20,Assumptions!$E$9:$G$9,0))-$I49)*(COLUMN()-COLUMN($I49))/4 -> 0.01
B50: Total Growth % | E50: =SUM(E47:E49) -> 0.13 | F50: =SUM(F47:F49) -> 0.05 | G50: =SUM(G47:G49) -> -0.05 | H50: =SUM(H47:H49) -> 0.04 | I50: =SUM(I47:I49) -> 0.06 | J50: =SUM(J47:J49) -> 0.06 | K50: =SUM(K47:K49) -> 0.06 | L50: =SUM(L47:L49) -> 0.06 | M50: =SUM(M47:M49) -> 0.06
B51: EOP Revenue | D51: 864.6 | E51: 972.7 | F51: 1018.2 | G51: 958 | H51: 996.8 | I51: =I46*(1+I50) -> 1056.608 | J51: =J46*(1+J50) -> 1120.0045 | K51: =K46*(1+K50) -> 1187.2047 | L51: =L46*(1+L50) -> 1258.437 | M51: =M46*(1+M50) -> 1333.9433
...

Sheet Income Statement
B2: Income Statement
B3: Graco Inc. (NYSE: GGG)
B4: All amounts in $ millions unless noted
C6: Units | D6: =IF('Cover Page'!$C$63+0<'Cover Page'!$C$64,"FY"&TEXT(MOD('Cover Page'!$C$63+0,100),"00")&"A","FY"&TEXT(MOD('Cover Page'!$C$63+0,100),"00")&"E") -> FY21A | E6: =IF('Cover Page'!$C$63+1<'Cover Page'!$C$64,"FY"&TEXT(MOD('Cover Page'!$C$63+1,100),"00")&"A","FY"&TEXT(MOD('Cover Page'!$C$63+1,100),"00")&"E") -> FY22A | F6: =IF('Cover Page'!$C$63+2<'Cover Page'!$C$64,"FY"&TEXT(MOD('Cover Page'!$C$63+2,100),"00")&"A","FY"&TEXT(MOD('Cover Page'!$C$63+2,100),"00")&"E") -> FY23A | G6: =IF('Cover Page'!$C$63+3<'Cover Page'!$C$64,"FY"&TEXT(MOD('Cover Page'!$C$63+3,100),"00")&"A","FY"&TEXT(MOD('Cover Page'!$C$63+3,100),"00")&"E") -> FY24A | H6: =IF('Cover Page'!$C$63+4<'Cover Page'!$C$64,"FY"&TEXT(MOD('Cover Page'!$C$63+4,100),"00")&"A","FY"&TEXT(MOD('Cover Page'!$C$63+4,100),"00")&"E") -> FY25A | I6: =IF('Cover Page'!$C$63+5<'Cover Page'!$C$64,"FY"&TEXT(MOD('Cover Page'!$C$63+5,100),"00")&"A","FY"&TEXT(MOD('Cover Page'!$C$63+5,100),"00")&"E") -> FY26E | J6: =IF('Cover Page'!$C$63+6<'Cover Page'!$C$64,"FY"&TEXT(MOD('Cover Page'!$C$63+6,100),"00")&"A","FY"&TEXT(MOD('Cover Page'!$C$63+6,100),"00")&"E") -> FY27E | K6: =IF('Cover Page'!$C$63+7<'Cover Page'!$C$64,"FY"&TEXT(MOD('Cover Page'!$C$63+7,100),"00")&"A","FY"&TEXT(MOD('Cover Page'!$C$63+7,100),"00")&"E") -> FY28E | L6: =IF('Cover Page'!$C$63+8<'Cover Page'!$C$64,"FY"&TEXT(MOD('Cover Page'!$C$63+8,100),"00")&"A","FY"&TEXT(MOD('Cover Page'!$C$63+8,100),"00")&"E") -> FY29E | M6: =IF('Cover Page'!$C$63+9<'Cover Page'!$C$64,"FY"&TEXT(MOD('Cover Page'!$C$63+9,100),"00")&"A","FY"&TEXT(MOD('Cover Page'!$C$63+9,100),"00")&"E") -> FY30E | O6: Notes
B8: Revenue
B9: Contractor | C9: $M | D9: ='Revenue Build'!D43 -> 987.6 | E9: ='Revenue Build'!E43 -> 999.1 | F9: ='Revenue Build'!F43 -> 985.7 | G9: ='Revenue Build'!G43 -> 988.9 | H9: ='Revenue Build'!H43 -> 1071.9 | I9: ='Revenue Build'!I43 -> 1125.495 | J9: ='Revenue Build'!J43 -> 1181.7698 | K9: ='Revenue Build'!K43 -> 1240.8582 | ... M9: ='Revenue Build'!M43 -> 1368.0462 | O9: Graco's three reporting segments. Contractor (~48% of sales) sells paint sprayers and dispensing equipment to professional contractors. Industrial (~45%) supplies fluid handling and finishing systems for manufacturing and process applications. Expansion Markets (~7%) covers semiconductor pumps, oil & gas valves, and environmental remediation. Forecast pulls segment-level revenue from the Revenue Build tab, which scenarios growth rates by segment.
B10: Industrial | C10: $M | D10: ='Revenue Build'!D51 -> 864.6 | E10: ='Revenue Build'!E51 -> 972.7 | F10: ='Revenue Build'!F51 -> 1018.2 | G10: ='Revenue Build'!G51 -> 958 | H10: ='Revenue Build'!H51 -> 996.8 | I10: ='Revenue Build'!I51 -> 1056.608 | J10: ='Revenue Build'!J51 -> 1120.0045 | K10: ='Revenue Build'!K51 -> 1187.2047 | ... M10: ='Revenue Build'!M51 -> 1333.9433
B11: Expansion | C11: $M | D11: ='Revenue Build'!D59 -> 135.4 | E11: ='Revenue Build'!E59 -> 171.7 | F11: ='Revenue Build'!F59 -> 191.7 | G11: ='Revenue Build'!G59 -> 166.4 | H11: ='Revenue Build'!H59 -> 167.9 | I11: ='Revenue Build'!I59 -> 179.653 | J11: ='Revenue Build'!J59 -> 192.22871 | K11: ='Revenue Build'!K59 -> 205.68472 | ... M11: ='Revenue Build'!M59 -> 235.48844
B12: Total revenues | C12: $M | D12: =SUM(D9:D11) -> 1987.6 | E12: =SUM(E9:E11) -> 2143.5 | F12: =SUM(F9:F11) -> 2195.6 | G12: =SUM(G9:G11) -> 2113.3 | H12: =SUM(H9:H11) -> 2236.6 | I12: =SUM(I9:I11) -> 2361.756 | J12: =SUM(J9:J11) -> 2494.0029 | K12: =SUM(K9:K11) -> 2633.7477 | ... M12: =SUM(M9:M11) -> 2937.4779
B13: YoY growth % | C13: % | D13: ="-" -> - | E13: =E12/D12-1 -> 0.078436305 | F13: =F12/E12-1 -> 0.024306042 | G13: =G12/F12-1 -> -0.037484059 | H13: =H12/G12-1 -> 0.058344769 | I13: =I12/H12-1 -> 0.055958151 | J13: =J12/I12-1 -> 0.055995175 | K13: =K12/J12-1 -> 0.056032318 | L13: =L12/K12-1 -> 0.05606958 | M13: =M12/L12-1 -> 0.056106959
B15: Gross Profit
B16: Cost of products sold | C16: $M | D16: 953.7 | E16: 1086.1 | F16: 1034.6 | G16: 990.9 | H16: 1063.4 | I16: =Assumptions!I52*I12 -> 1122.9059 | J16: =Assumptions!J52*J12 -> 1185.5003 | K16: =Assumptions!K52*K12 -> 1251.6278 | L16: =Assumptions!L52*L12 -> 1321.4905 | M16: =Assumptions!M52*M12 -> 1395.302 | O16: Cost of Products Sold includes raw materials, direct labor, manufacturing overhead, freight. Graco's gross margin runs historically at ~52-53%, well above peers like IDEX (~44-45%), Watts Water (~37-38%), and Lincoln Electric (~35%) and roughly in line with Nordson (~55%)
B17: Gross Margin % | C17: % | D17: =D18/D12 -> 0.52017509 | E17: =E18/E12 -> 0.49330534 | F17: =F18/F12 -> 0.52878484 | G17: =G18/G12 -> 0.53111248 | H17: =H18/H12 -> 0.52454619 | I17: =I18/I12 -> 0.52454619 | J17: =J18/J12 -> 0.52465964 | K17: =K18/K12 -> 0.52477309 | ... M17: =M18/M12 -> 0.525
B18: Gross Profit | C18: $M | D18: =D12-D16 -> 1033.9 | E18: =E12-E16 -> 1057.4 | F18: =F12-F16 -> 1161 | G18: =G12-G16 -> 1122.4 | H18: =H12-H16 -> 1173.2 | I18: =I12-I16 -> 1238.8501 | J18: =J12-J16 -> 1308.5027 | K18: =K12-K16 -> 1382.1199 | ... M18: =M12-M16 -> 1542.1759
B20: Operating Expenses
B21: Product development | C21: $M | D21: 79.7 | E21: 80 | F21: 82.8 | G21: 87.2 | H21: 82.3 | I21: =Assumptions!I54*I12 -> 89.746728 | J21: =Assumptions!J54*J12 -> 92.521755 | K21: =Assumptions!K54*K12 -> 98.498113 | L21: =Assumptions!L54*L12 -> 104.85743 | M21: =Assumptions!M54*M12 -> 111.62416 | O21: Three main buckets: Product Development (~3.7-4.1% of revenue) is R&D for new equipment platforms. Selling, Marketing & Distribution (~12-13% of revenue) covers the global sales force, channel partners, and distribution. G&A (~7-9% of revenue) is corporate overhead. 'Other Operating Items' captures contingent consideration adjustments, impairments, and one-time charges. FY25 operating margin was 27.9%, expanding from 26.7% in FY21 as the business scaled.
B22: % of revenue | C22: % | D22: =D21/D$12 -> 0.040098611 | E22: =E21/E$12 -> 0.037322137 | F22: =F21/F$12 -> 0.037711787 | G22: =G21/G$12 -> 0.04126248 | H22: =H21/H$12 -> 0.036796924 | I22: =I21/I12 -> 0.038 | J22: =J21/J12 -> 0.037097693 | K22: =K21/K12 -> 0.037398462 | L22: =L21/L12 -> 0.037699231 | M22: =M21/M12 -> 0.038
B23: Selling, marketing, & distribution | C23: $M | D23: 271.5 | E23: 250.9 | F23: 260.7 | G23: 273.7 | H23: 273.9 | I23: =Assumptions!I55*I12 -> 295.2195 | J23: =Assumptions!J55*J12 -> 307.00428 | K23: =Assumptions!K55*K12 -> 325.87712 | L23: =Assumptions!L55*L12 -> 345.91326 | M23: =Assumptions!M55*M12 -> 367.18474
B24: % of revenue | C24: % | D24: =D23/D$12 -> 0.1365969 | E24: =E23/E$12 -> 0.11705155 | F24: =F23/F$12 -> 0.11873747 | G24: =G23/G$12 -> 0.12951308 | H24: =H23/H$12 -> 0.12246267 | I24: =I23/I12 -> 0.125 | J24: =J23/J12 -> 0.123097 | K24: =K23/K12 -> 0.12373133 | L24: =L23/L12 -> 0.12436567 | M24: =M23/M12 -> 0.125
B25: General & admin | C25: $M | D25: 151.4 | E25: 153.8 | F25: 171.4 | G25: 191.4 | H25: 206.2 | I25: =Assumptions!I56*I12 -> 207.83453 | J25: =Assumptions!J56*J12 -> 227.31622 | K25: =Assumptions!K56*K12 -> 237.29212 | L25: =Assumptions!L56*L12 -> 247.68101 | M25: =Assumptions!M56*M12 -> 258.49806
B26: % of revenue | C26: % | D26: =D25/D$12 -> 0.076172268 | E26: =E25/E$12 -> 0.071751808 | F26: =F25/F$12 -> 0.078065221 | G26: =G25/G$12 -> 0.090569252 | H26: =H25/H$12 -> 0.092193508 | I26: =I25/I12 -> 0.088 | J26: =J25/J12 -> 0.091145131 | K26: =K25/K12 -> 0.090096754 | L26: =L25/L12 -> 0.089048377 | M26: =M25/M12 -> 0.088
B27: Other Op. items / contingent considerations | C27: $M | D27: 0 | E27: 0 | F27: -0.8 | G27: 0 | H27: -14.1 | I27: 0 | J27: 0 | K27: 0 | L27: 0 | M27: 0
B28: Total Operating Expenses | C28: $M | D28: =SUM(D21,D23,D25,D27) -> 502.6 | E28: =SUM(E21,E23,E25,E27) -> 484.7 | F28: =SUM(F21,F23,F25,F27) -> 514.1 | G28: =SUM(G21,G23,G25,G27) -> 552.3 | H28: =SUM(H21,H23,H25,H27) -> 548.3 | I28: =SUM(I21,I23,I25,I27) -> 592.80076 | J28: =SUM(J21,J23,J25,J27) -> 626.84226 | K28: =SUM(K21,K23,K25,K27) -> 661.66735 | ... M28: =SUM(M21,M23,M25,M27) -> 737.30695
B29: Operating Income (EBIT) | C29: $M | D29: =D18-D28 -> 531.3 | E29: =E18-E28 -> 572.7 | F29: =F18-F28 -> 646.9 | G29: =G18-G28 -> 570.1 | H29: =H18-H28 -> 624.9 | I29: =I18-I28 -> 646.04935 | J29: =J18-J28 -> 681.66042 | K29: =K18-K28 -> 720.45258 | ... M29: =M18-M28 -> 804.86894
B30: Operating margin % | C30: % | D30: =D29/D12 -> 0.26730731 | E30: =E29/E12 -> 0.26717985 | F30: =F29/F12 -> 0.29463472 | G30: =G29/G12 -> 0.26976766 | H30: =H29/H12 -> 0.2793973 | I30: =I29/I12 -> 0.27354619 | J30: =J29/J12 -> 0.27331982 | K30: =K29/K12 -> 0.27354654 | ... M30: =M29/M12 -> 0.274
B32: Below-the-line
B33: Interest expense | C33: $M | D33: 10.2 | E33: 9.9 | F33: 5.2 | G33: 2.8 | H33: 2.9 | I33: =Assumptions!I69 -> 0.66814 | J33: =Assumptions!J69 -> 0.66814 | K33: =Assumptions!K69 -> 0.66814 | L33: =Assumptions!L69 -> 0.66814 | M33: =Assumptions!M69 -> 0.66814 | O33: Two separate items between EBIT and pretax income. (1) Interest expense: cost of carrying Graco's small debt load (2) Other (income) / expense, non operating costs including pension/retirement plan returns, FX gains/losses, equity method investment income, gains on sale of buildings. This line is volatile: FY23 had a $42M pension settlement charge; FY24-FY25 had $19-22M of net gains. Therefore, we took 5 yr avg. for forecast. Effective tax rate has run 13-19%, held BELOW the ~21-23% statutory rate by OBBBA bonus depreciation and SBC excess tax benefits.
B34: Other (income) / expense, net | C34: $M | D34: 12.6 | E34: -2.9 | F34: 32.9 | G34: -22 | H34: -19.3 | I34: =AVERAGE($D$34:$H$34) -> 0.26 | J34: =AVERAGE($D$34:$H$34) -> 0.26 | K34: =AVERAGE($D$34:$H$34) -> 0.26 | L34: =AVERAGE($D$34:$H$34) -> 0.26 | M34: =AVERAGE($D$34:$H$34) -> 0.26
B35: Pre-tax income | C35: $M | D35: =D29-D33-D34 -> 508.5 | E35: =E29-E33-E34 -> 565.7 | F35: =F29-F33-F34 -> 608.8 | G35: =G29-G33-G34 -> 589.3 | H35: =H29-H33-H34 -> 641.3 | I35: =I29-I33-I34 -> 645.12121 | J35: =J29-J33-J34 -> 680.73228 | K35: =K29-K33-K34 -> 719.52444 | ... M35: =M29-M33-M34 -> 803.9408
B36: Income Tax Expense | C36: $M | D36: 68.6 | E36: 105.1 | F36: 102.3 | G36: 103.2 | H36: 119.4 | I36: =I35*$I$37 -> 122.57303 | J36: =J35*$I$37 -> 129.33913 | K36: =K35*$I$37 -> 136.70964 | L36: =L35*$I$37 -> 144.5046 | M36: =M35*$I$37 -> 152.74875
B37: Effective tax rate | C37: % | D37: =D36/D35 -> 0.13490659 | E37: =E36/E35 -> 0.18578752 | F37: =F36/F35 -> 0.16803548 | G37: =G36/G35 -> 0.17512303 | H37: =H36/H35 -> 0.18618431 | I37: 0.19 | J37: 0.19 | K37: 0.19 | L37: 0.19 | M37: 0.19
B38: Net Income | C38: $M | D38: =D35-D36 -> 439.9 | E38: =E35-E36 -> 460.6 | F38: =F35-F36 -> 506.5 | G38: =G35-G36 -> 486.1 | H38: =H35-H36 -> 521.9 | I38: =I35-I36 -> 522.54818 | J38: =J35-J36 -> 551.39315 | K38: =K35-K36 -> 582.8148 | ... M38: =M35-M36 -> 651.19205
B39: Net margin % | C39: % | D39: =D38/D12 -> 0.2213222 | E39: =E38/E12 -> 0.2148822 | F39: =F38/F12 -> 0.23068865 | G39: =G38/G12 -> 0.2300194 | H39: =H38/H12 -> 0.23334526 | I39: =I38/I12 -> 0.22125409 | J39: =J38/J12 -> 0.22108761 | K39: =K38/K12 -> 0.22128725 | ... M39: =M38/M12 -> 0.22168407
B41: EPS & Share Count
B42: Diluted shares outstanding | C42: M | D42: 174.526 | E42: 172.893 | F42: 172.199 | G42: 172.405 | H42: 169.219 | I42: =Assumptions!I89 -> 166.12899 | J42: =Assumptions!J89 -> 163.02959 | K42: =Assumptions!K89 -> 159.895 | L42: =Assumptions!L89 -> 156.72721 | M42: =Assumptions!M89 -> 153.52974 | O42: Diluted shares = basic shares + dilutive impact of stock options and RSUs. Graco's share count drifts down ~2% per year (buybacks > RSUs). Forecast assumes 2% annual share count reduction and EPS reaches ~$3.93 by FY30. Adjusted EPS strips out one-time items in historicals; in the forecast we don't model discrete charges so Adjusted = GAAP.
B43: Diluted EPS (GAAP) | C43: $ | D43: =D38/D42 -> 2.5205414 | E43: =E38/E42 -> 2.6640755 | F43: =F38/F42 -> 2.9413644 | G43: =G38/G42 -> 2.8195238 | H43: =H38/H42 -> 3.084169 | I43: =I38/I42 -> 3.1454364 | J43: =J38/J42 -> 3.3821661 | K43: =K38/K42 -> 3.6449846 | ... M43: =M38/M42 -> 4.2414716
B44: Diluted EPS growth | C44: % | D44: 0 | E44: =E43/D43-1 -> 0.05694575 | F44: =F43/E43-1 -> 0.10408447 | G44: =G43/F43-1 -> -0.041423143 | H44: =H43/G43-1 -> 0.09386168 | I44: =I43/H43-1 -> 0.019865103 | J44: =J43/I43-1 -> 0.075261334 | K44: =K43/J43-1 -> 0.077707147 | L44: =L43/K43-1 -> 0.07838292 | M44: =M43/L43-1 -> 0.07906566
B45: Adjusted Diluted EPS | C45: $ | D45: 2.44 | E45: 2.63 | F45: 3.04 | G45: 2.77 | H45: 3 | I45: =I43 -> 3.1454364 | J45: =J43 -> 3.3821661 | K45: =K43 -> 3.6449846 | L45: =L43 -> 3.9306891 | M45: =M43 -> 4.2414716
B47: EBITDA & SBC
B48: Operating income (EBIT) | C48: $M | D48: =D29 -> 531.3 | E48: =E29 -> 572.7 | F48: =F29 -> 646.9 | G48: =G29 -> 570.1 | H48: =H29 -> 624.9 | I48: =I29 -> 646.04935 | J48: =J29 -> 681.66042 | K48: =K29 -> 720.45258 | ... M48: =M29 -> 804.86894 | O48: EBITDA margin has expanded from 29.7% (FY21) to 33.4% (FY25) as fixed-cost leverage and acquisition-driven amortization both grew. Forecast EBITDA margin compresses slightly to ~31% by FY30 as amortization runs off (intangibles burn down without new M&A modeled). Stock-based compensation runs ~1.2-1.5% of revenue.
...

Sheet Balance Sheet
B2: Balance Sheet
B3: Graco Inc. (NYSE: GGG)
B4: All amounts in $ millions unless noted
C6: Units | D6: =IF('Cover Page'!$C$63+0<'Cover Page'!$C$64,"FY"&TEXT(MOD('Cover Page'!$C$63+0,100),"00")&"A","FY"&TEXT(MOD('Cover Page'!$C$63+0,100),"00")&"E") -> FY21A | E6: =IF('Cover Page'!$C$63+1<'Cover Page'!$C$64,"FY"&TEXT(MOD('Cover Page'!$C$63+1,100),"00")&"A","FY"&TEXT(MOD('Cover Page'!$C$63+1,100),"00")&"E") -> FY22A | F6: =IF('Cover Page'!$C$63+2<'Cover Page'!$C$64,"FY"&TEXT(MOD('Cover Page'!$C$63+2,100),"00")&"A","FY"&TEXT(MOD('Cover Page'!$C$63+2,100),"00")&"E") -> FY23A | G6: =IF('Cover Page'!$C$63+3<'Cover Page'!$C$64,"FY"&TEXT(MOD('Cover Page'!$C$63+3,100),"00")&"A","FY"&TEXT(MOD('Cover Page'!$C$63+3,100),"00")&"E") -> FY24A | H6: =IF('Cover Page'!$C$63+4<'Cover Page'!$C$64,"FY"&TEXT(MOD('Cover Page'!$C$63+4,100),"00")&"A","FY"&TEXT(MOD('Cover Page'!$C$63+4,100),"00")&"E") -> FY25A | I6: =IF('Cover Page'!$C$63+5<'Cover Page'!$C$64,"FY"&TEXT(MOD('Cover Page'!$C$63+5,100),"00")&"A","FY"&TEXT(MOD('Cover Page'!$C$63+5,100),"00")&"E") -> FY26E | J6: =IF('Cover Page'!$C$63+6<'Cover Page'!$C$64,"FY"&TEXT(MOD('Cover Page'!$C$63+6,100),"00")&"A","FY"&TEXT(MOD('Cover Page'!$C$63+6,100),"00")&"E") -> FY27E | K6: =IF('Cover Page'!$C$63+7<'Cover Page'!$C$64,"FY"&TEXT(MOD('Cover Page'!$C$63+7,100),"00")&"A","FY"&TEXT(MOD('Cover Page'!$C$63+7,100),"00")&"E") -> FY28E | L6: =IF('Cover Page'!$C$63+8<'Cover Page'!$C$64,"FY"&TEXT(MOD('Cover Page'!$C$63+8,100),"00")&"A","FY"&TEXT(MOD('Cover Page'!$C$63+8,100),"00")&"E") -> FY29E | M6: =IF('Cover Page'!$C$63+9<'Cover Page'!$C$64,"FY"&TEXT(MOD('Cover Page'!$C$63+9,100),"00")&"A","FY"&TEXT(MOD('Cover Page'!$C$63+9,100),"00")&"E") -> FY30E
B8: Assets: | O8: Notes
B9: Current assets:
B10: Cash and cash equivalents | C10: $M | D10: 624.302 | E10: 339.196 | F10: 537.951 | G10: 675.336 | H10: 624.083 | I10: ='Cash Flow'!I46 -> 712.38418 | J10: ='Cash Flow'!J46 -> 813.85532 | K10: ='Cash Flow'!K46 -> 934.25151 | L10: ='Cash Flow'!L46 -> 1076.189 | M10: ='Cash Flow'!M46 -> 1242.5938 | O10: Cash on hand. Graco runs a large cash balance (~$600-700M). No marketable securities.
B11: Accounts receivable, net | C11: $M | D11: 325.132 | E11: 346.01 | F11: 354.439 | G11: 362.533 | H11: 393.753 | I11: =(Assumptions!I76*'Income Statement'!I12)/365 -> 412.86435 | J11: =(I11*'Income Statement'!J12)/'Income Statement'!I12 -> 435.98276 | K11: =(J11*'Income Statement'!K12)/'Income Statement'!J12 -> 460.41189 | L11: =(K11*'Income Statement'!L12)/'Income Statement'!K12 -> 486.22699 | M11: =(L11*'Income Statement'!M12)/'Income Statement'!L12 -> 513.50771 | O11: Mostly comprised from channel resellers - distributors, OEMs
B12: Inventories, net | C12: $M | D12: 382.301 | E12: 476.79 | F12: 438.349 | G12: 404.676 | H12: 401.138 | I12: =(Assumptions!I77*'Income Statement'!I16)/365 -> 423.7781 | J12: =(Assumptions!J77*'Income Statement'!J16)/365 -> 447.60476 | K12: =(Assumptions!K77*'Income Statement'!K16)/365 -> 472.78758 | L12: =(Assumptions!L77*'Income Statement'!L16)/365 -> 499.40469 | M12: =(Assumptions!M77*'Income Statement'!M16)/365 -> 527.53884 | O12: Raw materials, WIP, and finished goods. Inventory has been declining since FY22 peak as supply chain normalizes.
B13: Other current assets | C13: $M | D13: 31.886 | E13: 43.624 | F13: 35.07 | G13: 54.896 | H13: 52.907 | I13: =(H13/'Income Statement'!H12)*'Income Statement'!I12 -> 55.867578 | J13: =(H13/'Income Statement'!H12)*'Income Statement'!J12 -> 58.995893 | K13: =(H13/'Income Statement'!H12)*'Income Statement'!K12 -> 62.301569 | L13: =(H13/'Income Statement'!H12)*'Income Statement'!L12 -> 65.794792 | M13: =(H13/'Income Statement'!H12)*'Income Statement'!M12 -> 69.486338 | O13: Prepaid expenses, refundable income taxes, and miscellaneous short-term receivables. Forecast as % of revenue (scales with operating activity).
B14: Current assets | C14: $M | D14: =SUM(D10:D13) -> 1363.621 | E14: =SUM(E10:E13) -> 1205.62 | F14: =SUM(F10:F13) -> 1365.809 | G14: =SUM(G10:G13) -> 1497.441 | H14: =SUM(H10:H13) -> 1471.881 | I14: =SUM(I10:I13) -> 1604.8942 | J14: =SUM(J10:J13) -> 1756.4387 | K14: =SUM(K10:K13) -> 1929.7525 | ... M14: =SUM(M10:M13) -> 2353.1267
B16: Non-current assets:
B17: PP&E, net | C17: $M | D17: 451.061 | E17: 607.609 | F17: 741.713 | G17: 771.656 | H17: 755.064 | I17: =H17+Assumptions!I81-'Income Statement'!I58 -> 837.72546 | J17: =I17+Assumptions!J81-'Income Statement'!J58 -> 912.54555 | K17: =J17+Assumptions!K81-'Income Statement'!K58 -> 978.38924 | L17: =K17+Assumptions!L81-'Income Statement'!L58 -> 1034.0177 | M17: =L17+Assumptions!M81-'Income Statement'!M58 -> 1078.0798 | O17: Forecast roll-forward: prior + Capex - Depreciation. Reflects manufacturing facilities in MN, OH, MI, plus international sites. PPE is cumulative total CapEx spend - Acc. Dep
B18: Goodwill | C18: $M | D18: 356.255 | E18: 368.171 | F18: 370.228 | G18: 487.468 | H18: 585.304 | I18: =H18+(Assumptions!I33*0.55) -> 585.304 | J18: =I18+(Assumptions!J33*0.55) -> 585.304 | K18: =J18+(Assumptions!K33*0.55) -> 585.304 | L18: =K18+(Assumptions!L33*0.55) -> 585.304 | M18: =L18+(Assumptions!M33*0.55) -> 585.304 | O18: Excess of acquisition cost over fair value of net assets acquired. Held flat in forecast (no future M&A modeled). Step-ups from FY24 Corob ($230M) and FY25 Color Service / Radia acquisitions.
B19: Intangibles, net | C19: $M | D19: 149.74 | E19: 137.507 | F19: 126.258 | G19: 233.306 | H19: 303.851 | I19: =H19-'Income Statement'!I59+(Assumptions!I33*0.45) -> 256.851 | J19: =I19-'Income Statement'!J59+(Assumptions!J33*0.45) -> 216.851 | K19: =J19-'Income Statement'!K59+(Assumptions!K33*0.45) -> 183.851 | L19: =K19-'Income Statement'!L59+(Assumptions!L33*0.45) -> 157.851 | M19: =L19-'Income Statement'!M59+(Assumptions!M33*0.45) -> 138.851 | O19: Acquired customer relationships, technology, trademarks. Forecast roll-forward: prior - Amortization (assumes no new M&A). Runs off ~$7M/yr as ~7-yr useful life intangibles age.
B20: Operating lease assets | C20: $M | D20: 30.046 | E20: 29.785 | F20: 18.768 | G20: 19.678 | H20: 26.073 | I20: =H20 -> 26.073 | J20: =I20 -> 26.073 | K20: =J20 -> 26.073 | L20: =K20 -> 26.073 | M20: =L20 -> 26.073 | O20: Right-of-use asset for operating leases (ASC 842). Held flat in forecast — small (~$26M) and minimal impact.
B21: Deferred income taxes, net | C21: $M | D21: 55.786 | E21: 57.09 | F21: 61.381 | G21: 46.91 | H21: 35.975 | I21: =H21 -> 35.975 | J21: =I21 -> 35.975 | K21: =J21 -> 35.975 | L21: =K21 -> 35.975 | M21: =L21 -> 35.975 | O21: Net deferred tax asset position from temporary differences (mostly U.S. pension, SBC, inventory reserves). Held flat in forecast because its based on discrete events.
B22: Other non-current assets | C22: $M | D22: 36.689 | E22: 33.118 | F22: 37.85 | G22: 82.753 | H22: 96.122 | I22: =H22+((AVERAGE($D$22:$F$22)-H22)*1/5) -> 84.074733 | J22: =H22+((AVERAGE($D$22:$F$22)-H22)*2/5) -> 72.027467 | K22: =H22+((AVERAGE($D$22:$F$22)-H22)*3/5) -> 59.9802 | L22: =H22+((AVERAGE($D$22:$F$22)-H22)*4/5) -> 47.932933 | M22: =AVERAGE($D$22:$F$22) -> 35.885667 | O22: Catch-all: long-term notes receivable, minority equity investments in companies, indemnification escrow assets from acquisitions, and deferred long-term costs. Inflated FY24-25 likely high M&A activity tied escrow holdbacks and minority stakes from those deals. Forecast linear runoff to ~$36M baseline over 5 years as escrows release and items roll off.
B23: Total assets | C23: $M | D23: =D14+SUM(D17:D22) -> 2443.198 | E23: =E14+SUM(E17:E22) -> 2438.9 | F23: =F14+SUM(F17:F22) -> 2722.007 | G23: =G14+SUM(G17:G22) -> 3139.212 | H23: =H14+SUM(H17:H22) -> 3274.27 | I23: =I14+SUM(I17:I22) -> 3430.8974 | J23: =J14+SUM(J17:J22) -> 3605.2148 | K23: =K14+SUM(K17:K22) -> 3799.325 | ... M23: =M14+SUM(M17:M22) -> 4253.2952
B25: Liabilities + Equity:
B26: Current liabilities:
B27: Notes payable | C27: $M | D27: 43.489 | E27: 20.974 | F27: 30.036 | G27: 28.537 | H27: 23.072 | I27: =H27 -> 23.072 | J27: =I27 -> 23.072 | K27: =J27 -> 23.072 | L27: =K27 -> 23.072 | M27: =L27 -> 23.072 | O27: Short-term borrowings on bank lines of credit, primarily used to fund foreign subsidiary operations in local currency. A treasury / financing decision, not an operating one. Historically stable at $21-44M range with no clear trend; held flat at FY25 level (~$23M) since there is no clean economic driver.
B28: Current portion of LTD | C28: $M | D28: 75 | E28: 0 | F28: 0 | G28: 0 | H28: 1.624 | I28: =H28 -> 1.624 | J28: =I28 -> 1.624 | K28: =J28 -> 1.624 | L28: =K28 -> 1.624 | M28: =L28 -> 1.624 | O28: All LTD is maturing in NTM
B29: Trade accounts payable | C29: $M | D29: 78.432 | E29: 84.218 | F29: 72.214 | G29: 60.816 | H29: 78.573 | I29: =(Assumptions!I78*'Income Statement'!I16)/365 -> 82.988694 | J29: =(Assumptions!J78*'Income Statement'!J16)/365 -> 87.634697 | K29: =(Assumptions!K78*'Income Statement'!K16)/365 -> 92.544044 | L29: =(Assumptions!L78*'Income Statement'!L16)/365 -> 97.731853 | M29: =(Assumptions!M78*'Income Statement'!M16)/365 -> 103.21412 | O29: DPO well below industry norms (~50-60 days), suggesting it doesn't use suppliers as a cheap financing source, but gains discounts and strengthens relationship by paying fast. They can do this because consistent they got stockpile of cash.
B30: Salaries and incentives | C30: $M | D30: 82.941 | E30: 63.969 | F30: 64.802 | G30: 58.169 | H30: 73.42 | I30: =(H30/'Income Statement'!H12)*'Income Statement'!I12 -> 77.528447 | J30: =(H30/'Income Statement'!H12)*'Income Statement'!J12 -> 81.869666 | K30: =(H30/'Income Statement'!H12)*'Income Statement'!K12 -> 86.457014 | L30: =(H30/'Income Statement'!H12)*'Income Statement'!L12 -> 91.304622 | M30: =(H30/'Income Statement'!H12)*'Income Statement'!M12 -> 96.427447 | O30: Accrued bonus, commissions, and incentive comp. Forecast as % of revenue (scales with headcount and revenue base).
B31: Dividends payable | C31: $M | D31: 35.771 | E31: 39.963 | F31: 42.789 | G31: 46.558 | H31: 48.705 | I31: =H31 -> 48.705 | J31: =I31 -> 48.705 | K31: =J31 -> 48.705 | L31: =K31 -> 48.705 | M31: =L31 -> 48.705 | O31: Quarterly cash dividend declared but not yet paid. Held flat at FY25 level (≈ quarterly dividend run-rate × shares outstanding).
B32: Operating lease liability | C32: $M | D32: 23.527 | E32: 21.057 | F32: 11.785 | G32: 12.278 | H32: 18.131 | I32: =H32 -> 18.131 | J32: =I32 -> 18.131 | K32: =J32 -> 18.131 | L32: =K32 -> 18.131 | M32: =L32 -> 18.131 | O32: Held flat in forecast - small total (~$18M)
B33: Other current liabilities | C33: $M | D33: 191.159 | E33: 190.793 | F33: 185.359 | G33: 211.728 | H33: 241.867 | I33: =(H33/'Income Statement'!H12)*'Income Statement'!I12 -> 255.40143 | J33: =(H33/'Income Statement'!H12)*'Income Statement'!J12 -> 269.70268 | K33: =(H33/'Income Statement'!H12)*'Income Statement'!K12 -> 284.81474 | L33: =(H33/'Income Statement'!H12)*'Income Statement'!L12 -> 300.78419 | M33: =(H33/'Income Statement'!H12)*'Income Statement'!M12 -> 317.66027 | O33: Accrued warranties, customer rebates, deferred revenue, accrued professional fees, and miscellaneous accruals. Forecast as % of revenue.
B34: Current liabilities | C34: $M | D34: =SUM(D27:D33) -> 530.319 | E34: =SUM(E27:E33) -> 420.974 | F34: =SUM(F27:F33) -> 406.985 | G34: =SUM(G27:G33) -> 418.086 | H34: =SUM(H27:H33) -> 485.392 | I34: =SUM(I27:I33) -> 507.45057 | J34: =SUM(J27:J33) -> 530.73904 | K34: =SUM(K27:K33) -> 555.3478 | ... M34: =SUM(M27:M33) -> 608.83384
B36: Non-current liabilities:
B37: Long-term debt & finance leases | C37: $M | D37: 75 | E37: 75 | F37: 0 | G37: 0 | H37: 0 | I37: =H37 -> 0 | J37: =I37 -> 0 | K37: =J37 -> 0 | L37: =K37 -> 0 | M37: =L37 -> 0 | O37: Graco operates with minimal LT debt (mostly paid off after FY22); held at $0 in forecast (no new debt assumed).
B38: Retirement benefits and deferred comp | C38: $M | D38: 106.897 | E38: 61.672 | F38: 80.347 | G38: 80.381 | H38: 87.179 | I38: =H38 -> 87.179 | J38: =I38 -> 87.179 | K38: =J38 -> 87.179 | L38: =K38 -> 87.179 | M38: =L38 -> 87.179 | O38: Pension obligation + deferred compensation liability for executives. Held flat in forecast (assumes minimal pension contribution changes).
B39: Deferred income taxes | C39: $M | D39: 10.661 | E39: 9.443 | F39: 8.215 | G39: 37.822 | H39: 36.708 | I39: =H39 -> 36.708 | J39: =I39 -> 36.708 | K39: =J39 -> 36.708 | L39: =K39 -> 36.708 | M39: =L39 -> 36.708 | O39: Net deferred tax liability from temporary differences (intangible amortization, accelerated tax depreciation). Volatile, hard to forecast so held flat .
B40: Other non-current liabilities | C40: $M | D40: 10.978 | E40: 12.159 | F40: 2.235 | G40: 18.788 | H40: 11.06 | I40: =H40 -> 11.06 | J40: =I40 -> 11.06 | K40: =J40 -> 11.06 | L40: =K40 -> 11.06 | M40: =L40 -> 11.06 | O40: Uncertain tax positions, contingent consideration earnouts from acquisitions, miscellaneous LT obligations. Held flat in forecast.
B41: Total liabilities | C41: $M | D41: =D34+SUM(D37:D40) -> 733.855 | E41: =E34+SUM(E37:E40) -> 579.248 | F41: =F34+SUM(F37:F40) -> 497.782 | G41: =G34+SUM(G37:G40) -> 555.077 | H41: =H34+SUM(H37:H40) -> 620.339 | I41: =I34+SUM(I37:I40) -> 642.39757 | J41: =J34+SUM(J37:J40) -> 665.68604 | K41: =K34+SUM(K37:K40) -> 690.2948 | ... M41: =M34+SUM(M37:M40) -> 743.78084
B43: Shareholders' equity:
B44: Common stock ($1.00 stated value) | C44: $M | D44: 170.308 | E44: 167.702 | F44: 167.946 | G44: 169.394 | H44: 165.15 | I44: =H44 -> 165.15 | J44: =I44 -> 165.15 | K44: =J44 -> 165.15 | L44: =K44 -> 165.15 | M44: =L44 -> 165.15 | O44: Shares Outs. x 1.00 (bookeeping number, no insights here)
B45: Additional paid-in capital | C45: $M | D45: 742.288 | E45: 784.477 | F45: 863.336 | G45: 955.051 | H45: 994.566 | I45: =MAX(0, H45+'Income Statement'!I54+'Cash Flow'!I36+'Cash Flow'!I37+'Cash Flow'!I38) -> 797.10625 | J45: =MAX(0, I45+'Income Statement'!J54+'Cash Flow'!J36+'Cash Flow'!J37+'Cash Flow'!J38) -> 598.88756 | K45: =MAX(0, J45+'Income Statement'!K54+'Cash Flow'!K36+'Cash Flow'!K37+'Cash Flow'!K38) -> 397.8271 | L45: =MAX(0, K45+'Income Statement'!L54+'Cash Flow'!L36+'Cash Flow'!L37+'Cash Flow'!L38) -> 194.08584 | M45: =MAX(0, L45+'Income Statement'!M54+'Cash Flow'!M36+'Cash Flow'!M37+'Cash Flow'!M38) -> 0 | O45: Capital paid in above par. Drivers: SBC (+~$15M/yr), stock issued (small), buybacks (-~$300M+/yr). Floored at zero cuz GAAP doesn't allow negative APIC. Exhausts by FY29; overflow flows to RE.
B46: Retained earnings (Accumulated deficit) | C46: $M | D46: 876.916 | E46: 976.851 | F46: 1227.938 | G46: 1509.264 | H46: 1456.71 | I46: =H46+'Income Statement'!I38+'Cash Flow'!I39+MIN(0, H45+'Income Statement'!I54+'Cash Flow'!I36+'Cash Flow'!I37+'Cash Flow'!I38) -> 1786.7386 | J46: =I46+'Income Statement'!J38+'Cash Flow'!J39+MIN(0, I45+'Income Statement'!J54+'Cash Flow'!J36+'Cash Flow'!J37+'Cash Flow'!J38) -> 2135.9861 | K46: =J46+'Income Statement'!K38+'Cash Flow'!K39+MIN(0, J45+'Income Statement'!K54+'Cash Flow'!K36+'Cash Flow'!K37+'Cash Flow'!K38) -> 2506.5481 | L46: =K46+'Income Statement'!L38+'Cash Flow'!L39+MIN(0, K45+'Income Statement'!L54+'Cash Flow'!L36+'Cash Flow'!L37+'Cash Flow'!L38) -> 2899.7285 | M46: =L46+'Income Statement'!M38+'Cash Flow'!M39+MIN(0, L45+'Income Statement'!M54+'Cash Flow'!M36+'Cash Flow'!M37+'Cash Flow'!M38) -> 3304.8594 | O46: Cumulative NI less cumulative dividends, plus buyback overflow once APIC hits zero. Grows ~$340M/yr from retained earnings; dampens FY29+ as overflow charges here.
B47: Accumulated other comprehensive loss | C47: $M | D47: -80.169 | E47: -69.378 | F47: -34.995 | G47: -49.574 | H47: 37.505 | I47: =H47 -> 37.505 | J47: =I47 -> 37.505 | K47: =J47 -> 37.505 | L47: =K47 -> 37.505 | M47: =L47 -> 37.505 | O47: Cumulative FX translation + pension OCI. Held flat at FY25 ($37.5M). Historically volatile (-$80M to +$38M) driven by USD strength and pension discount rates.
...

Sheet Cash Flow
B2: Cash Flow
B3: Graco Inc. (NYSE: GGG)
B4: All amounts in $ millions unless noted
C7: Units | D7: =IF('Cover Page'!$C$63+0<'Cover Page'!$C$64,"FY"&TEXT(MOD('Cover Page'!$C$63+0,100),"00")&"A","FY"&TEXT(MOD('Cover Page'!$C$63+0,100),"00")&"E") -> FY21A | E7: =IF('Cover Page'!$C$63+1<'Cover Page'!$C$64,"FY"&TEXT(MOD('Cover Page'!$C$63+1,100),"00")&"A","FY"&TEXT(MOD('Cover Page'!$C$63+1,100),"00")&"E") -> FY22A | F7: =IF('Cover Page'!$C$63+2<'Cover Page'!$C$64,"FY"&TEXT(MOD('Cover Page'!$C$63+2,100),"00")&"A","FY"&TEXT(MOD('Cover Page'!$C$63+2,100),"00")&"E") -> FY23A | G7: =IF('Cover Page'!$C$63+3<'Cover Page'!$C$64,"FY"&TEXT(MOD('Cover Page'!$C$63+3,100),"00")&"A","FY"&TEXT(MOD('Cover Page'!$C$63+3,100),"00")&"E") -> FY24A | H7: =IF('Cover Page'!$C$63+4<'Cover Page'!$C$64,"FY"&TEXT(MOD('Cover Page'!$C$63+4,100),"00")&"A","FY"&TEXT(MOD('Cover Page'!$C$63+4,100),"00")&"E") -> FY25A | I7: =IF('Cover Page'!$C$63+5<'Cover Page'!$C$64,"FY"&TEXT(MOD('Cover Page'!$C$63+5,100),"00")&"A","FY"&TEXT(MOD('Cover Page'!$C$63+5,100),"00")&"E") -> FY26E | J7: =IF('Cover Page'!$C$63+6<'Cover Page'!$C$64,"FY"&TEXT(MOD('Cover Page'!$C$63+6,100),"00")&"A","FY"&TEXT(MOD('Cover Page'!$C$63+6,100),"00")&"E") -> FY27E | K7: =IF('Cover Page'!$C$63+7<'Cover Page'!$C$64,"FY"&TEXT(MOD('Cover Page'!$C$63+7,100),"00")&"A","FY"&TEXT(MOD('Cover Page'!$C$63+7,100),"00")&"E") -> FY28E | L7: =IF('Cover Page'!$C$63+8<'Cover Page'!$C$64,"FY"&TEXT(MOD('Cover Page'!$C$63+8,100),"00")&"A","FY"&TEXT(MOD('Cover Page'!$C$63+8,100),"00")&"E") -> FY29E | M7: =IF('Cover Page'!$C$63+9<'Cover Page'!$C$64,"FY"&TEXT(MOD('Cover Page'!$C$63+9,100),"00")&"A","FY"&TEXT(MOD('Cover Page'!$C$63+9,100),"00")&"E") -> FY30E | O7: Notes
B9: Operating Activities
B10: Net income | C10: $M | D10: ='Income Statement'!D38 -> 439.9 | E10: ='Income Statement'!E38 -> 460.6 | F10: ='Income Statement'!F38 -> 506.5 | G10: ='Income Statement'!G38 -> 486.1 | H10: ='Income Statement'!H38 -> 521.9 | I10: ='Income Statement'!I38 -> 522.54818 | J10: ='Income Statement'!J38 -> 551.39315 | K10: ='Income Statement'!K38 -> 582.8148 | ... M10: ='Income Statement'!M38 -> 651.19205 | O10: Net Income from IS row 38. Starting point for indirect-method CFO.
B11: Depreciation | C11: $M | D11: ='Income Statement'!D58 -> 50.3 | E11: ='Income Statement'!E58 -> 54.5 | F11: ='Income Statement'!F58 -> 56 | G11: ='Income Statement'!G58 -> 56 | H11: ='Income Statement'!H58 -> 60 | I11: ='Income Statement'!I58 -> 63.767412 | J11: ='Income Statement'!J58 -> 67.338079 | K11: ='Income Statement'!K58 -> 71.111188 | ... M11: ='Income Statement'!M58 -> 79.311903 | O11: Depreciation addback (non-cash). Drives from IS row 58.
B12: Amortization of intangibles | D12: ='Income Statement'!D59 -> 9 | E12: ='Income Statement'!E59 -> 11.5 | F12: ='Income Statement'!F59 -> 18.3 | G12: ='Income Statement'!G59 -> 30.7 | H12: ='Income Statement'!H59 -> 47.4 | I12: ='Income Statement'!I59 -> 47 | J12: ='Income Statement'!J59 -> 40 | K12: ='Income Statement'!K59 -> 33 | ... M12: ='Income Statement'!M59 -> 19 | O12: Amortization of intangibles addback (non-cash). Drives from IS row 59. Declines as acquired intangibles roll off.
B13: Stock-based compensation | C13: $M | D13: ='Income Statement'!D54 -> 24.9 | E13: ='Income Statement'!E54 -> 24.7 | F13: ='Income Statement'!F54 -> 30.2 | G13: ='Income Statement'!G54 -> 31.9 | H13: ='Income Statement'!H54 -> 34.3 | I13: ='Income Statement'!I54 -> 36.219365 | J13: ='Income Statement'!J54 -> 38.247474 | K13: ='Income Statement'!K54 -> 40.390569 | ... M13: ='Income Statement'!M54 -> 45.048508 | O13: Stock-based comp addback (non-cash) as it sits hidden in OpEx. Drives from IS row 54.
B14: Non-cash other (gains)/charges | C14: $M | D14: 0 | E14: 0 | F14: 41.329 | G14: 1.216 | H14: -18.798 | I14: 0 | J14: 0 | K14: 0 | L14: 0 | M14: 0 | O14: Catch-all for non-cash items: pension settlement losses, impairments, contingent consideration adjustments, gains on building sale. Forecast = 0 (assumes no discrete events; override if M&A or impairments expected).
B15: Deferred income taxes | C15: $M | D15: -46.572 | E15: -9.997 | F15: -8.502 | G15: 6.06 | H15: -8.673 | I15: 0 | J15: 0 | K15: 0 | L15: 0 | M15: 0 | O15: Deferred tax movements. Forecast = 0 (timing-driven; averages to ~zero over multi-year periods).
B16: Working capital changes
