Workbook

Sheet Cover Page
B2: QUALYS, INC.
B3: NASDAQ: QLYS
B4: Cybersecurity — SaaS Vulnerability Management
B6: 5-Year DCF + Scenario Analysis
B9: Company Overview
B10: Sector | C10: Technology: Cybersecurity
B11: Product | C11: Enterprise TruRisk Platform: 20+ integrated cloud-based IT security and compliance solutions
B12: Customers | C12: 10,000+ globally, majority of Forbes Global 100
B13: Revenue Model | C13: 100% subscription/SaaS. ~94% from existing customer expansion, ~6% from new logos
B14: Capital Structure | C14: Zero debt. Consistent buybacks (~2% annual share reduction)
B16: Valuation Snapshot
B17: Current Share Price | C17: ='DCF & Sensitivity'!D55 -> 80.52
B18: Base Case (Perpetuity Growth) | C18: ='DCF & Sensitivity'!D53 -> 124.46762
B19: Base Case (Exit Multiple) | C19: ='DCF & Sensitivity'!D54 -> 168.81434
B21: Key Assumptions
B22: WACC | C22: =Assumptions!D67/100 -> 0.0981
B23: Terminal Growth Rate | C23: =Assumptions!D68/100 -> 0.03
B24: Terminal EV/EBITDA Multiple | C24: =Assumptions!D69 -> 20
B25: Net Dollar Expansion Rate (terminal) | C25: =Assumptions!F10/100 -> 1.01
B26: Terminal Operating Margin | C26: ='Income Statement'!M29/100 -> 0.355
B27: Net Debt ($M) | C27: ='DCF & Sensitivity'!D48 -> -698
B28: Diluted Shares Outstanding (M) | C28: ='DCF & Sensitivity'!D51 -> 36.5
B29: WACC note: Uses adjusted beta of 1.00 (cyber SaaS peer median), not raw regression beta 0.61. Raw beta gave 7.67% WACC which understated risk. See Assumptions tab rows 62-64 and DCF Sensitivity table for ranges.
B30: Table of Contents
B31: › Summary
B32: Scenario Summary
B33: SWOT
B34: › Valuation
B35: Assumptions
B36: Revenue Build
B37: Income Statement
B38: Balance Sheet
B39: Cash Flow
B40: DCF & Sensitivity
... B44: Sources

Sheet Scenario Summary
B2: Scenario Summary
B3: Qualys, Inc. (QLYS)
B4: What is the market pricing? Side-by-side DCF outputs across Bear / Base / Bull.
B6: Purpose | C6: Single-page comparison of Bear / Base / Bull DCF outputs against the current market price. Answers the question, "What scenario is the market pricing today?"
B7: Data source | C7: Share prices pull from the "Appendix --> Shadow DCF tab", which runs bear, base, and bull DCFs simultaneously (one per scenario column).
B8: Reconciliation note | C8: Shadow DCF ties to the main DCF within ~3% on perpetuity and <1% on multiple for Base case. The small gap is because Shadow uses a simplified FCF build (NOPAT + D&A − Capex + ΔDeferred Revenue) rather than routing through the full Cash Flow statement. This is a deliberate tradeoff, It is simpler and more auditable.
B9: Book of record | C9: For a full, scenario-toggled valuation with complete IS/BS/CF linkages, use the main DCF & Sensitivity tab. Shadow DCF exists for comparison only.
B12: Current Share Price | C12: ='DCF & Sensitivity'!D55 -> 80.52 | D12: (as of model date)
B14: Scenario Analysis Summary | C14: Bear | D14: Base | E14: Bull | G14: Notes
B16: VALUATION OUTPUT
B17: Implied Share Price (Perpetuity) | C17: ='Shadow DCF'!D39 -> 76.970576 | D17: ='Shadow DCF'!D75 -> 128.28403 | E17: ='Shadow DCF'!D111 -> 179.13503 | G17: DCF perpetuity (live from Shadow DCF)
B18: Implied Share Price (Exit Multiple) | C18: ='Shadow DCF'!D40 -> 97.758499 | D18: ='Shadow DCF'!D76 -> 170.0188 | E18: ='Shadow DCF'!D112 -> 261.01641 | G18: DCF exit multiple (live from Shadow DCF)
B19: Blended (avg of both methods) | C19: =AVERAGE(C17:C18) -> 87.364538 | D19: =AVERAGE(D17:D18) -> 149.15142 | E19: =AVERAGE(E17:E18) -> 220.07572 | G19: Average of TGR + Multiple
B20: Upside / (Downside) vs Market | C20: =C19/$C$12-1 -> 0.085004193 | D20: =D19/$C$12-1 -> 0.85235242 | E20: =E19/$C$12-1 -> 1.7331808 | G20: vs. current market price
B22: KEY OPERATING ASSUMPTIONS (2030E TERMINAL)
B23: Net Dollar Expansion Rate | C23: =Assumptions!E10 -> 95 | D23: =Assumptions!F10 -> 101 | E23: =Assumptions!G10 -> 105 | G23: Historical has been 103% for 3yrs
B24: New Customer Logos Added | C24: =Assumptions!E11 -> 800 | D24: =Assumptions!F11 -> 1300 | E24: =Assumptions!G11 -> 1600 | G24: Back-solved from New Rev / ARPU
B25: New Customer ARPU ($K) | C25: =Assumptions!E12 -> 30 | D25: =Assumptions!F12 -> 35 | E25: =Assumptions!G12 -> 40 | G25: Roughly half of blended ARPU
B26: Gross Margin % | C26: =Assumptions!E13 -> 81 | D26: =Assumptions!F13 -> 84.5 | E26: =Assumptions!G13 -> 86 | G26: FY25A: 82.8%
B27: R&D % of Revenue | C27: =Assumptions!E14 -> 19.5 | D27: =Assumptions!F14 -> 17.5 | E27: =Assumptions!G14 -> 15.5 | G27: FY25A: 17.5%
B28: S&M % of Revenue | C28: =Assumptions!E15 -> 25 | D28: =Assumptions!F15 -> 21.5 | E28: =Assumptions!G15 -> 18 | G28: FY25A: 21.4% — trending UP
B29: Terminal Growth Rate | C29: =Assumptions!E16 -> 2 | D29: =Assumptions!F16 -> 3 | E29: =Assumptions!G16 -> 3.5 | G29: Long-run perpetuity rate
B30: Exit EV/EBITDA | C30: =Assumptions!E17 -> 15 | D30: =Assumptions!F17 -> 20 | E30: =Assumptions!G17 -> 25 | G30: Peer Direct median ~24x
B32: 2030E TERMINAL FINANCIALS
B33: Revenue ($M) | C33: ='Shadow DCF'!J9 -> 796.0184 | D33: ='Shadow DCF'!J45 -> 973.09489 | E33: ='Shadow DCF'!J81 -> 1110.2976 | G33: 2025A: $669M (live from Shadow DCF)
B34: 5-yr Revenue CAGR | C34: =(C33/669.1)^(1/5)-1 -> 0.035348157 | D34: =(D33/669.1)^(1/5)-1 -> 0.07778673 | E34: =(E33/669.1)^(1/5)-1 -> 0.10659748 | G34: FY25A-FY30E compound rate
B35: Operating Margin % | C35: =C26/100-C27/100-C28/100-0.105 -> 0.26 | D35: =D26/100-D27/100-D28/100-0.1 -> 0.355 | E35: =E26/100-E27/100-E28/100-0.1 -> 0.425 | G35: = GM - R&D - S&M - G&A
B36: EBITDA ($M) | C36: ='Shadow DCF'!J18 -> 219.70108 | D36: ='Shadow DCF'!J54 -> 356.15273 | E36: ='Shadow DCF'!J90 -> 484.08976 | G36: Terminal year (live from Shadow DCF)
B37: FCF ex-SBC ($M) | C37: ='Shadow DCF'!J23 -> 159.57239 | D37: ='Shadow DCF'!J59 -> 310.14251 | E37: ='Shadow DCF'!J95 -> 446.9057 | G37: Live from Shadow DCF
B39: Summary
B40: ="Market price of $"&TEXT(C12,"0.00")&" is roughly in line with our Bear blended output of $"&TEXT(C19,"0.00")&" ("&TEXT(1-C12/C19,"0%")&" gap)." -> Market price of $80.52 is roughly in line with our Bear blended output of $87.36 (8% gap).
B41: At peer-median WACC, the market is pricing the Bear case. The subsequent question is, "What does it take to get to Base?" Answer: NDER holding ~101% (vs Bear's 95%) and S&M discipline. Both are tractable, observable in quarterly results.

Sheet SWOT
B2: SWOT Analysis
B3: Qualys, Inc. (QLYS)
B18: Strengths
B19: 1 | C19: 94% of revenue from existing customer base. Highly recurring, low churn risk on revenue
B20: 2 | C20: Deep enterprise stickiness - 20+ modules on single platform, high switching costs once deployed
B21: 3 | C21: Zero debt, consistent FCF generation, disciplined buyback program (~$185M/yr)
B22: 4 | C22: Blue-chip customer base - majority of Forbes Global 100, validates enterprise credibility
B23: 5 | C23: Margins expanding as legacy on-prem hardware fully depreciates and cloud hosting scales
B24: 6 | C24: Asset-light model - no inventory, no hardware (moved to cloud), minimal capex (<1% of revenue). Nearly all revenue converts to cash.
B25: 7 | C25: Buybacks compounding per-share value. ~2% annual share count reduction on top of organic growth
B27: Weaknesses
B28: 1 | C28: NDER flat at 103% for 3 consecutive years. No visible catalyst for expansion to re-accelerate
B29: 2 | C29: S&M % of revenue increasing (18.6% to 21.4%) despite growing partner channel
B30: 3 | C30: Platform is deep but narrow. Only provide vulnerability management and compliance. Bigger players offer end-to-end incl. endpoint, network and cloud
B31: 4 | C31: Management provides minimal disclosure - no exact customer count, no cohort data, no segment breakdowns. Makes independent verification of growth drivers difficult.
B33: Opportunities
B34: 1 | C34: Module upsell. New customers start with 1-2 of 20+ products, significant whitespace within existing base
B35: 2 | C35: International revenue mix trending up (44% to 50%). Geographic diversification without new product investment
B36: 3 | C36: Cloud migration complete - legacy on-prem security competitors still transitioning, creates share opportunity
B37: 4 | C37: Regulatory and government tailwinds - SEC cyber disclosure rules and expanding FedRAMP/defense compliance mandates both drive demand for vulnerability assessment and compliance reporting.
B39: Threats
B40: 1 | C40: CrowdStrike, Palo Alto, Zscaler competing for same enterprise wallet. Platform consolidation may favor larger vendors
B41: 2 | C41: Even non-discretionary cybersecurity budgets get reviewed in downturns. The bigger players may be cheaper.
B42: 3 | C42: Terminal value is 80%+ of enterprise value - small changes in WACC or exit multiple swing the implied price by 30%+. Valuation is highly assumption-dependent.
B43: 4 | C43: AI could shift competitive dynamics in security tooling - TBD whether this benefits incumbents like QLYS (who have the data and platform to integrate AI) or enables new entrants to commoditize vulnerability scanning.

Sheet Valuation >>>
B18: Valuation >>>

Sheet Assumptions
B2: Assumptions
B3: Qualys, Inc. (QLYS)
B4: All amounts in $ millions unless noted
B7: SCENARIO SELECTOR
B8: 2026E Start is fixed. 2030E = Bear/Base/Bull terminal values. 2027-2029 interpolate linearly between start and terminal. Each metric toggles independently via column H dropdown.
B9: Metric | C9: Units | D9: 2026E Start | E9: Bear | F9: Base | G9: Bull | H9: Scenario
B10: Net Dollar Expansion Rate | C10: % | D10: 103 | E10: 95 | F10: 101 | G10: 105 | H10: Base
B11: New Customer Logos Added | C11: # | D11: 1300 | E11: 800 | F11: 1300 | G11: 1600 | H11: Base
B12: New Customer ARPU | C12: $K | D12: 35 | E12: 30 | F12: 35 | G12: 40 | H12: Base
B13: Gross Margin % | C13: % | D13: 83 | E13: 81 | F13: 84.5 | G13: 86 | H13: Base
B14: R&D % of Revenue | C14: % | D14: 17.5 | E14: 19.5 | F14: 17.5 | G14: 15.5 | H14: Base
B15: S&M % of Revenue | C15: % | D15: 21 | E15: 25 | F15: 21.5 | G15: 18 | H15: Base
B16: Terminal Growth Rate | C16: % | D16: n.a | E16: 2 | F16: 3 | G16: 3.5 | H16: Base
B17: Exit EV/EBITDA | C17: x | D17: n.a | E17: 15 | F17: 20 | G17: 25 | H17: Base
C19: Units | D19: 2021A | E19: 2022A | F19: 2023A | G19: 2024A | H19: 2025A | I19: 2026E | J19: 2027E | K19: 2028E | L19: 2029E | M19: 2030E | O19: Notes
B21: REVENUE DRIVERS
B22: Total Revenue | C22: $M | D22: ='Revenue Build'!D21 -> 411.2 | E22: ='Revenue Build'!E21 -> 489.7 | F22: ='Revenue Build'!F21 -> 554.5 | G22: ='Revenue Build'!G21 -> 607.6 | H22: ='Revenue Build'!H21 -> 669.1 | I22: ='Revenue Build'!I21 -> 734.673 | J22: ='Revenue Build'!J21 -> 798.53982 | K22: ='Revenue Build'!K21 -> 860.01062 | ... M22: ='Revenue Build'!M21 -> 973.09489
B23: Revenue Growth % | C23: % | E23: =(E22/D22-1)*100 -> 19.090467 | F23: =(F22/E22-1)*100 -> 13.232591 | G23: =(G22/F22-1)*100 -> 9.5761948 | H23: =(H22/G22-1)*100 -> 10.121791 | I23: =(I22/H22-1)*100 -> 9.8001793 | J23: =(J22/I22-1)*100 -> 8.6932315 | K23: =(K22/J22-1)*100 -> 7.6978999 | L23: =(L22/K22-1)*100 -> 6.7906323 | M23: =(M22/L22-1)*100 -> 5.9542101
B24: Net Dollar Expansion Rate | C24: % | E24: ='Revenue Build'!E10 -> 109 | F24: ='Revenue Build'!F10 -> 105 | G24: ='Revenue Build'!G10 -> 103 | H24: ='Revenue Build'!H10 -> 103 | I24: ='Revenue Build'!I10 -> 103 | J24: ='Revenue Build'!J10 -> 102.5 | K24: ='Revenue Build'!K10 -> 102 | L24: ='Revenue Build'!L10 -> 101.5 | M24: ='Revenue Build'!M10 -> 101
B25: Ending Customer Count | C25: # | D25: ='Revenue Build'!D31 -> 10000 | E25: ='Revenue Build'!E31 -> 10000 | F25: ='Revenue Build'!F31 -> 10000 | G25: ='Revenue Build'!G31 -> 10000 | H25: ='Revenue Build'!H31 -> 10000 | I25: ='Revenue Build'!I31 -> 10000 | J25: ='Revenue Build'!J31 -> 10000 | K25: ='Revenue Build'!K31 -> 10000 | ... M25: ='Revenue Build'!M31 -> 10000
B26: Blended ARPU | C26: $K | D26: ='Revenue Build'!D32 -> 41.12 | E26: ='Revenue Build'!E32 -> 48.97 | F26: ='Revenue Build'!F32 -> 55.45 | G26: ='Revenue Build'!G32 -> 60.76 | H26: ='Revenue Build'!H32 -> 66.91 | I26: ='Revenue Build'!I32 -> 73.4673 | J26: ='Revenue Build'!J32 -> 79.853982 | K26: ='Revenue Build'!K32 -> 86.001062 | ... M26: ='Revenue Build'!M32 -> 97.309489
B28: GEOGRAPHIC MIX
B29: US Revenue % | C29: % | D29: 61 | E29: 60 | F29: 60 | G29: 58 | H29: 56 | I29: 54.5 | J29: 53 | K29: 51.5 | L29: 50 | M29: 50 | O29: Actuals from 10-K Item 1. Trending down ~2pts/yr. Floored at 50%.
B30: International Revenue % | C30: % | D30: =100-D29 -> 39 | E30: =100-E29 -> 40 | F30: =100-F29 -> 40 | G30: =100-G29 -> 42 | H30: =100-H29 -> 44 | I30: =100-I29 -> 45.5 | J30: =100-J29 -> 47 | K30: =100-K29 -> 48.5 | ... M30: =100-M29 -> 50
B31: US Revenue | C31: $M | D31: =D22*D29/100 -> 250.832 | E31: =E22*E29/100 -> 293.82 | F31: =F22*F29/100 -> 332.7 | G31: =G22*G29/100 -> 352.408 | H31: =H22*H29/100 -> 374.696 | I31: =I22*I29/100 -> 400.39679 | J31: =J22*J29/100 -> 423.22611 | K31: =K22*K29/100 -> 442.90547 | ... M31: =M22*M29/100 -> 486.54744
B32: International Revenue | C32: $M | D32: =D22*D30/100 -> 160.368 | E32: =E22*E30/100 -> 195.88 | F32: =F22*F30/100 -> 221.8 | G32: =G22*G30/100 -> 255.192 | H32: =H22*H30/100 -> 294.404 | I32: =I22*I30/100 -> 334.27622 | J32: =J22*J30/100 -> 375.31372 | K32: =K22*K30/100 -> 417.10515 | ... M32: =M22*M30/100 -> 486.54744
B34: CHANNEL MIX
B35: Direct Revenue % | C35: % | D35: 59 | E35: 58 | F35: 57 | G35: 54 | H35: 51 | I35: 50 | J35: 49 | K35: 48 | L35: 47 | M35: 46 | O35: Actuals from 10-K. Partner share rising ~2-3 pts/yr. Direct = 100 - Partner.
B36: Channel Partner Revenue % | C36: % | D36: =100-D35 -> 41 | E36: =100-E35 -> 42 | F36: =100-F35 -> 43 | G36: =100-G35 -> 46 | H36: =100-H35 -> 49 | I36: =100-I35 -> 50 | J36: =100-J35 -> 51 | K36: =100-K35 -> 52 | ... M36: =100-M35 -> 54 | O36: FY25: 49% partner (10-K Item 1). FY21: 41%.
B38: MARGIN ASSUMPTIONS
B39: Gross Margin % | C39: % | D39: ='Income Statement'!D15 -> 78.258755 | E39: ='Income Statement'!E15 -> 79.007556 | F39: ='Income Statement'!F15 -> 80.613165 | G39: ='Income Statement'!G15 -> 81.649111 | H39: ='Income Statement'!H15 -> 82.842624 | I39: =$D$13 -> 83 | J39: =$D$13+(INDEX($E$13:$G$13,MATCH($H$13,$E$9:$G$9,0))-$D$13)*1/4 -> 83.375 | K39: =$D$13+(INDEX($E$13:$G$13,MATCH($H$13,$E$9:$G$9,0))-$D$13)*2/4 -> 83.75 | L39: =$D$13+(INDEX($E$13:$G$13,MATCH($H$13,$E$9:$G$9,0))-$D$13)*3/4 -> 84.125 | M39: =$D$13+(INDEX($E$13:$G$13,MATCH($H$13,$E$9:$G$9,0))-$D$13)*4/4 -> 84.5 | O39: Has been expanding as D&A declines and cloud costs scale.
B40: R&D % of Revenue | C40: % | D40: ='Income Statement'!D19 -> 19.771401 | E40: ='Income Statement'!E19 -> 20.665714 | F40: ='Income Statement'!F19 -> 19.927863 | G40: ='Income Statement'!G19 -> 18.416722 | H40: ='Income Statement'!H19 -> 17.531012 | I40: =$D$14 -> 17.5 | J40: =$D$14+(INDEX($E$14:$G$14,MATCH($H$14,$E$9:$G$9,0))-$D$14)*1/4 -> 17.5 | K40: =$D$14+(INDEX($E$14:$G$14,MATCH($H$14,$E$9:$G$9,0))-$D$14)*2/4 -> 17.5 | L40: =$D$14+(INDEX($E$14:$G$14,MATCH($H$14,$E$9:$G$9,0))-$D$14)*3/4 -> 17.5 | M40: =$D$14+(INDEX($E$14:$G$14,MATCH($H$14,$E$9:$G$9,0))-$D$14)*4/4 -> 17.5 | O40: R&D dollars growing but slower than revenue — R&D as % of revenue declining over time. 10-K says they will "continue to devote resources".
B41: Sales & Marketing % of Revenue | C41: % | D41: ='Income Statement'!D21 -> 18.604086 | E41: ='Income Statement'!E21 -> 19.848887 | F41: ='Income Statement'!F21 -> 20.144274 | G41: ='Income Statement'!G21 -> 21.115866 | H41: ='Income Statement'!H21 -> 21.446719 | I41: =$D$15 -> 21 | J41: =$D$15+(INDEX($E$15:$G$15,MATCH($H$15,$E$9:$G$9,0))-$D$15)*1/4 -> 21.125 | K41: =$D$15+(INDEX($E$15:$G$15,MATCH($H$15,$E$9:$G$9,0))-$D$15)*2/4 -> 21.25 | L41: =$D$15+(INDEX($E$15:$G$15,MATCH($H$15,$E$9:$G$9,0))-$D$15)*3/4 -> 21.375 | M41: =$D$15+(INDEX($E$15:$G$15,MATCH($H$15,$E$9:$G$9,0))-$D$15)*4/4 -> 21.5 | O41: S&M as % of revenue has been increasing historically (18.6% to 21.4%), not declining. Forward projections assume leverage, but history does not support this yet. Partner channel growth has not reduced S&M spend.
B42: G&A % of Revenue | C42: % | D42: ='Income Statement'!D23 -> 18.555447 | E42: ='Income Statement'!E23 -> 11.843986 | F42: ='Income Statement'!F23 -> 11.127142 | G42: ='Income Statement'!G23 -> 11.306781 | H42: ='Income Statement'!H23 -> 10.700942 | I42: 10.5 | J42: 10.5 | K42: 10 | L42: 10 | M42: 10 | O42: 2021 was 18.6% due to $27.3M CEO accelerated SBC vesting (one-time). Normalized ~11%. Do not trend from 2021 base.
B43: Operating Margin % | C43: % | D43: =D39-D40-D41-D42 -> 21.327821 | E43: =E39-E40-E41-E42 -> 26.648969 | F43: =F39-F40-F41-F42 -> 29.413886 | G43: =G39-G40-G41-G42 -> 30.809743 | H43: =H39-H40-H41-H42 -> 33.163952 | I43: =I39-I40-I41-I42 -> 34 | J43: =J39-J40-J41-J42 -> 34.25 | K43: =K39-K40-K41-K42 -> 35 | ... M43: =M39-M40-M41-M42 -> 35.5 | O43: Formula: Gross Margin - R&D% - S&M% - G&A%. Should match IS operating margin.
B44: Effective Tax Rate | C44: % | D44: 20.6 | E44: 19.2 | F44: 15.2 | G44: 17.2 | H44: 19.7 | I44: 20 | J44: 20 | K44: 20 | L44: 20 | M44: 20 | O44: 2023 low (15.2%) due to IRS foreign tax credit rule change. 2025 higher (19.7%) due to OBBBA. Normalized at 20%.
B45: Check | D45: ='Income Statement'!D29-D43 -> 0 | E45: ='Income Statement'!E29-E43 -> 0 | F45: ='Income Statement'!F29-F43 -> 0 | G45: ='Income Statement'!G29-G43 -> 0 | H45: ='Income Statement'!H29-H43 -> 0 | I45: ='Income Statement'!I29-I43 -> 0 | J45: ='Income Statement'!J29-J43 -> 0 | K45: ='Income Statement'!K29-K43 -> 0 | ... M45: ='Income Statement'!M29-M43 -> 0
B47: BALANCE SHEET DRIVERS
B48: Days Sales Outstanding (DSO) | C48: days | E48: ='Balance Sheet'!E11/'Income Statement'!E9*365 -> 90.784154 | F48: ='Balance Sheet'!F11/'Income Statement'!F9*365 -> 96.236249 | G48: ='Balance Sheet'!G11/'Income Statement'!G9*365 -> 98.879197 | H48: ='Balance Sheet'!H11/'Income Statement'!H9*365 -> 93.282021 | I48: 93 | J48: 93 | K48: 93 | L48: 93 | M48: 93 | O48: Actuals = AR / Revenue × 365. Fluctuates with billing timing. Held flat at FY25 level. No disclosed trend in collection terms.
B49: Deferred Revenue % of Revenue | C49: % | E49: =('Balance Sheet'!E25+'Balance Sheet'!E30)/'Income Statement'!E9*100 -> 64.774352 | F49: =('Balance Sheet'!F25+'Balance Sheet'!F30)/'Income Statement'!F9*100 -> 65.825068 | G49: =('Balance Sheet'!G25+'Balance Sheet'!G30)/'Income Statement'!G9*100 -> 65.14154 | H49: =('Balance Sheet'!H25+'Balance Sheet'!H30)/'Income Statement'!H9*100 -> 62.382305 | I49: 60 | J49: 60 | K49: 60 | L49: 60 | M49: 60 | O49: Most likely DR is decreasing because they are switching from multiyear upfront to annual billing
...

Sheet Revenue Build
B2: Revenue Build
B3: Qualys, Inc. (QLYS)
B4: All amounts in $ millions unless noted
C6: Units | D6: 2021A | E6: 2022A | F6: 2023A | G6: 2024A | H6: 2025A | I6: 2026E | J6: 2027E | K6: 2028E | L6: 2029E | M6: 2030E | O6: Notes
B8: EXISTING CUSTOMER REVENUE
B9: Prior Year Revenue | C9: $M | E9: 411.2 | F9: 489.7 | G9: 554.5 | H9: 607.6 | I9: =H21 -> 669.1 | J9: =I21 -> 734.673 | K9: =J21 -> 798.53982 | L9: =K21 -> 860.01062 | M9: =L21 -> 918.41078
B10: Net Dollar Expansion Rate | C10: % | E10: 109 | F10: 105 | G10: 103 | H10: 103 | I10: =Assumptions!$D$10 -> 103 | J10: =Assumptions!$D$10+(INDEX(Assumptions!$E$10:$G$10,MATCH(Assumptions!$H$10,Assumptions!$E$9:$G$9,0))-Assumptions!$D$10)*1/4 -> 102.5 | K10: =Assumptions!$D$10+(INDEX(Assumptions!$E$10:$G$10,MATCH(Assumptions!$H$10,Assumptions!$E$9:$G$9,0))-Assumptions!$D$10)*2/4 -> 102 | L10: =Assumptions!$D$10+(INDEX(Assumptions!$E$10:$G$10,MATCH(Assumptions!$H$10,Assumptions!$E$9:$G$9,0))-Assumptions!$D$10)*3/4 -> 101.5 | M10: =Assumptions!$D$10+(INDEX(Assumptions!$E$10:$G$10,MATCH(Assumptions!$H$10,Assumptions!$E$9:$G$9,0))-Assumptions!$D$10)*4/4 -> 101 | O10: Found in 10-K MD&A. Risk: has been flat at 103% for 3 years. Deceleration below 100% would mean net contraction of existing revenue.
B11: Existing Customer Revenue | C11: $M | E11: =E9*E10/100 -> 448.208 | F11: =F9*F10/100 -> 514.185 | G11: =G9*G10/100 -> 571.135 | H11: =H9*H10/100 -> 625.828 | I11: =I9*I10/100 -> 689.173 | J11: =J9*J10/100 -> 753.03982 | K11: =K9*K10/100 -> 814.51062 | L11: =L9*L10/100 -> 872.91078 | M11: =M9*M10/100 -> 927.59489
B12: Existing as % of Total Revenue | C12: % | E12: =IF(E21=0,"",E11/E21*100) -> 91.527057 | F12: =IF(F21=0,"",F11/F21*100) -> 92.729486 | G12: =IF(G21=0,"",G11/G21*100) -> 93.998519 | H12: =IF(H21=0,"",H11/H21*100) -> 93.532805 | I12: =I11/I21*100 -> 93.806768 | J12: =J11/J21*100 -> 94.3021 | K12: =K11/K21*100 -> 94.709368 | L12: =L11/L21*100 -> 95.04579 | M12: =M11/M21*100 -> 95.324197 | O12: High concentration on existing customers is both a strength (predictable) and a risk (dependent on NDER staying above 100%).
B14: NEW CUSTOMER REVENUE
B15: New Customer Logos Added | C15: # | E15: 1200 | F15: 1100 | G15: 1300 | H15: 1300 | I15: =Assumptions!$D$11 -> 1300 | J15: =Assumptions!$D$11+(INDEX(Assumptions!$E$11:$G$11,MATCH(Assumptions!$H$11,Assumptions!$E$9:$G$9,0))-Assumptions!$D$11)*1/4 -> 1300 | K15: =Assumptions!$D$11+(INDEX(Assumptions!$E$11:$G$11,MATCH(Assumptions!$H$11,Assumptions!$E$9:$G$9,0))-Assumptions!$D$11)*2/4 -> 1300 | L15: =Assumptions!$D$11+(INDEX(Assumptions!$E$11:$G$11,MATCH(Assumptions!$H$11,Assumptions!$E$9:$G$9,0))-Assumptions!$D$11)*3/4 -> 1300 | M15: =Assumptions!$D$11+(INDEX(Assumptions!$E$11:$G$11,MATCH(Assumptions!$H$11,Assumptions!$E$9:$G$9,0))-Assumptions!$D$11)*4/4 -> 1300 | O15: New Revenue / New Customer ARPU. Backed into this based on New Customer ARPU Assumption.
B16: New Customer ARPU | C16: $K | E16: =IF(E15=0,"",(E21-E11)/E15*1000) -> 34.576667 | F16: =IF(F15=0,"",(F21-F11)/F15*1000) -> 36.65 | G16: =IF(G15=0,"",(G21-G11)/G15*1000) -> 28.05 | H16: =IF(H15=0,"",(H21-H11)/H15*1000) -> 33.286154 | I16: =Assumptions!$D$12 -> 35 | J16: =Assumptions!$D$12+(INDEX(Assumptions!$E$12:$G$12,MATCH(Assumptions!$H$12,Assumptions!$E$9:$G$9,0))-Assumptions!$D$12)*1/4 -> 35 | K16: =Assumptions!$D$12+(INDEX(Assumptions!$E$12:$G$12,MATCH(Assumptions!$H$12,Assumptions!$E$9:$G$9,0))-Assumptions!$D$12)*2/4 -> 35 | L16: =Assumptions!$D$12+(INDEX(Assumptions!$E$12:$G$12,MATCH(Assumptions!$H$12,Assumptions!$E$9:$G$9,0))-Assumptions!$D$12)*3/4 -> 35 | M16: =Assumptions!$D$12+(INDEX(Assumptions!$E$12:$G$12,MATCH(Assumptions!$H$12,Assumptions!$E$9:$G$9,0))-Assumptions!$D$12)*4/4 -> 35 | O16: Company says that customers usually start with 1-2 products. We have estimated this to be half Blended ARPU in Row 39.
B17: New Customer Revenue | C17: $M | E17: =E21-E11 -> 41.492 | F17: =F21-F11 -> 40.315 | G17: =G21-G11 -> 36.465 | H17: =H21-H11 -> 43.272 | I17: =I15*I16/1000 -> 45.5 | J17: =J15*J16/1000 -> 45.5 | K17: =K15*K16/1000 -> 45.5 | L17: =L15*L16/1000 -> 45.5 | M17: =M15*M16/1000 -> 45.5 | O17: New Customer Revenue = The residual revenue after existing customer expansion
B18: New as % of Total Revenue | C18: % | E18: =IF(E21=0,"",E17/E21*100) -> 8.4729426 | F18: =IF(F21=0,"",F17/F21*100) -> 7.270514 | G18: =IF(G21=0,"",G17/G21*100) -> 6.0014812 | H18: =IF(H21=0,"",H17/H21*100) -> 6.4671947 | I18: =I17/I21*100 -> 6.1932315 | J18: =J17/J21*100 -> 5.6978999 | K18: =K17/K21*100 -> 5.2906323 | L18: =L17/L21*100 -> 4.9542101 | M18: =M17/M21*100 -> 4.675803
B20: TOTAL REVENUE
B21: Total Revenue | C21: $M | D21: 411.2 | E21: 489.7 | F21: 554.5 | G21: 607.6 | H21: 669.1 | I21: =I11+I17 -> 734.673 | J21: =J11+J17 -> 798.53982 | K21: =K11+K17 -> 860.01062 | L21: =L11+L17 -> 918.41078 | M21: =M11+M17 -> 973.09489
B22: Revenue Growth % | C22: % | E22: =(E21/D21-1)*100 -> 19.090467 | F22: =(F21/E21-1)*100 -> 13.232591 | G22: =(G21/F21-1)*100 -> 9.5761948 | H22: =(H21/G21-1)*100 -> 10.121791 | I22: =(I21/H21-1)*100 -> 9.8001793 | J22: =(J21/I21-1)*100 -> 8.6932315 | K22: =(K21/J21-1)*100 -> 7.6978999 | L22: =(L21/K21-1)*100 -> 6.7906323 | M22: =(M21/L21-1)*100 -> 5.9542101
B23: Growth from Existing Customers | C23: % | E23: =(E11-E9)/D21*100 -> 9 | F23: =(F11-F9)/E21*100 -> 5 | G23: =(G11-G9)/F21*100 -> 3 | H23: =(H11-H9)/G21*100 -> 3 | I23: =(I11-I9)/H21*100 -> 3 | J23: =(J11-J9)/I21*100 -> 2.5 | K23: =(K11-K9)/J21*100 -> 2 | L23: =(L11-L9)/K21*100 -> 1.5 | M23: =(M11-M9)/L21*100 -> 1
B24: Growth from New Customers | C24: % | E24: =E17/D21*100 -> 10.090467 | F24: =F17/E21*100 -> 8.2325914 | G24: =G17/F21*100 -> 6.5761948 | H24: =H17/G21*100 -> 7.1217907 | I24: =I17/H21*100 -> 6.8001793 | J24: =J17/I21*100 -> 6.1932315 | K24: =K17/J21*100 -> 5.6978999 | L24: =L17/K21*100 -> 5.2906323 | M24: =M17/L21*100 -> 4.9542101
B26: CUSTOMER METRICS
B27: Beginning Customer Count | C27: # | D27: 10000 | E27: =D31 -> 10000 | F27: =E31 -> 10000 | G27: =F31 -> 10000 | H27: =G31 -> 10000 | I27: =H31 -> 10000 | J27: =I31 -> 10000 | K27: =J31 -> 10000 | L27: =K31 -> 10000 | M27: =L31 -> 10000 | O27: Company says in all Annual Reports "Customers are over 10,000". Held flat at 10,000 which is a key model limitation.
B28: (+) New Logos Added | C28: # | E28: =E15 -> 1200 | F28: =F15 -> 1100 | G28: =G15 -> 1300 | H28: =H15 -> 1300 | I28: =I15 -> 1300 | J28: =J15 -> 1300 | K28: =K15 -> 1300 | L28: =L15 -> 1300 | M28: =M15 -> 1300 | O28: If actual count is growing, model understates new logo ARPU. If shrinking, model overstates it. No way to verify with current disclosure.
B29: (-) Logos Churned (implied) | C29: # | E29: =E31-E27-E28 -> -1200 | F29: =F31-F27-F28 -> -1100 | G29: =G31-G27-G28 -> -1300 | H29: =H31-H27-H28 -> -1300 | I29: =I31-I27-I28 -> -1300 | J29: =J31-J27-J28 -> -1300 | K29: =K31-K27-K28 -> -1300 | L29: =L31-L27-L28 -> -1300 | M29: =M31-M27-M28 -> -1300
B30: Implied Logo Churn Rate | C30: % | E30: =IF(E27=0,"",ABS(E29)/E27*100) -> 12 | F30: =IF(F27=0,"",ABS(F29)/F27*100) -> 11 | G30: =IF(G27=0,"",ABS(G29)/G27*100) -> 13 | H30: =IF(H27=0,"",ABS(H29)/H27*100) -> 13 | I30: =IF(I27=0,"",ABS(I29)/I27*100) -> 13 | J30: =IF(J27=0,"",ABS(J29)/J27*100) -> 13 | K30: =IF(K27=0,"",ABS(K29)/K27*100) -> 13 | L30: =IF(L27=0,"",ABS(L29)/L27*100) -> 13 | M30: =IF(M27=0,"",ABS(M29)/M27*100) -> 13 | O30: Back-solved: ~13% annual logo churn. High vs. enterprise SaaS peers (~5-10%), but offset by strong NDER. QLYS loses small customers but expands larger ones.
B31: Ending Customer Count | C31: # | D31: 10000 | E31: 10000 | F31: 10000 | G31: 10000 | H31: 10000 | I31: 10000 | J31: 10000 | K31: 10000 | L31: 10000 | M31: 10000 | O31: Risk: if QLYS is quietly churning logos and masking it with NDER, growth is weaker than it appears.
B32: Blended ARPU | C32: $K | D32: =D21/D31*1000 -> 41.12 | E32: =E21/E31*1000 -> 48.97 | F32: =F21/F31*1000 -> 55.45 | G32: =G21/G31*1000 -> 60.76 | H32: =H21/H31*1000 -> 66.91 | I32: =I21/I31*1000 -> 73.4673 | J32: =J21/J31*1000 -> 79.853982 | K32: =K21/K31*1000 -> 86.001062 | ... M32: =M21/M31*1000 -> 97.309489
B33: ARPU Growth % | C33: % | E33: =(E32/D32-1)*100 -> 19.090467 | F33: =(F32/E32-1)*100 -> 13.232591 | G33: =(G32/F32-1)*100 -> 9.5761948 | H33: =(H32/G32-1)*100 -> 10.121791 | I33: =(I32/H32-1)*100 -> 9.8001793 | J33: =(J32/I32-1)*100 -> 8.6932315 | K33: =(K32/J32-1)*100 -> 7.6978999 | L33: =(L32/K32-1)*100 -> 6.7906323 | M33: =(M32/L32-1)*100 -> 5.9542101 | O33: ARPU growth ≈ revenue growth when customer count flat. Driven by upsell.

Sheet Income Statement
B2: Income Statement
B3: Qualys, Inc. (QLYS)
B4: All amounts in $ millions unless noted
C6: Units | D6: 2021A | E6: 2022A | F6: 2023A | G6: 2024A | H6: 2025A | I6: 2026E | J6: 2027E | K6: 2028E | L6: 2029E | M6: 2030E | O6: Notes
B8: REVENUE
B9: Total Revenue | C9: $M | D9: =Assumptions!D22 -> 411.2 | E9: =Assumptions!E22 -> 489.7 | F9: =Assumptions!F22 -> 554.5 | G9: =Assumptions!G22 -> 607.6 | H9: =Assumptions!H22 -> 669.1 | I9: =Assumptions!I22 -> 734.673 | J9: =Assumptions!J22 -> 798.53982 | K9: =Assumptions!K22 -> 860.01062 | ... M9: =Assumptions!M22 -> 973.09489 | O9: Driven by Revenue Build page (NDER on existing base + new logo acquisition). Not a top-line growth rate assumption.
B10: Revenue Growth % | C10: % | E10: =(E9/D9-1)*100 -> 19.090467 | F10: =(F9/E9-1)*100 -> 13.232591 | G10: =(G9/F9-1)*100 -> 9.5761948 | H10: =(H9/G9-1)*100 -> 10.121791 | I10: =(I9/H9-1)*100 -> 9.8001793 | J10: =(J9/I9-1)*100 -> 8.6932315 | K10: =(K9/J9-1)*100 -> 7.6978999 | L10: =(L9/K9-1)*100 -> 6.7906323 | M10: =(M9/L9-1)*100 -> 5.9542101
B12: COST OF REVENUE
B13: Cost of Revenue | C13: $M | D13: 89.4 | E13: 102.8 | F13: 107.5 | G13: 111.5 | H13: 114.8 | I13: =I9*(100-Assumptions!I39)/100 -> 124.89441 | J13: =J9*(100-Assumptions!J39)/100 -> 132.75725 | K13: =K9*(100-Assumptions!K39)/100 -> 139.75173 | L13: =L9*(100-Assumptions!L39)/100 -> 145.79771 | M13: =M9*(100-Assumptions!M39)/100 -> 150.82971 | O13: Actuals from 10-K. Forward = Revenue × (1 - Gross Margin %).
B14: Gross Profit | C14: $M | D14: =D9-D13 -> 321.8 | E14: =E9-E13 -> 386.9 | F14: =F9-F13 -> 447 | G14: =G9-G13 -> 496.1 | H14: =H9-H13 -> 554.3 | I14: =I9-I13 -> 609.77859 | J14: =J9-J13 -> 665.78258 | K14: =K9-K13 -> 720.2589 | ... M14: =M9-M13 -> 822.26518
B15: Gross Margin % | C15: % | D15: =D14/D9*100 -> 78.258755 | E15: =E14/E9*100 -> 79.007556 | F15: =F14/F9*100 -> 80.613165 | G15: =G14/G9*100 -> 81.649111 | H15: =H14/H9*100 -> 82.842624 | I15: =I14/I9*100 -> 83 | J15: =J14/J9*100 -> 83.375 | K15: =K14/K9*100 -> 83.75 | ... M15: =M14/M9*100 -> 84.5 | O15: Forward from Assumptions page scenario toggle. Reflects scale leverage on cloud hosting costs.
B17: OPERATING EXPENSES
B18: Research & Development | C18: $M | D18: 81.3 | E18: 101.2 | F18: 110.5 | G18: 111.9 | H18: 117.3 | I18: =I9*Assumptions!I40/100 -> 128.56778 | J18: =J9*Assumptions!J40/100 -> 139.74447 | K18: =K9*Assumptions!K40/100 -> 150.50186 | L18: =L9*Assumptions!L40/100 -> 160.72189 | M18: =M9*Assumptions!M40/100 -> 170.29161
B19: R&D % of Revenue | C19: % | D19: =D18/D9*100 -> 19.771401 | E19: =E18/E9*100 -> 20.665714 | F19: =F18/F9*100 -> 19.927863 | G19: =G18/G9*100 -> 18.416722 | H19: =H18/H9*100 -> 17.531012 | I19: =I18/I9*100 -> 17.5 | J19: =J18/J9*100 -> 17.5 | K19: =K18/K9*100 -> 17.5 | ... M19: =M18/M9*100 -> 17.5 | O19: From Assumptions scenario toggle. Largest opex line. Driven by headcount growth.
B20: Sales & Marketing | C20: $M | D20: 76.5 | E20: 97.2 | F20: 111.7 | G20: 128.3 | H20: 143.5 | I20: =I9*Assumptions!I41/100 -> 154.28133 | J20: =J9*Assumptions!J41/100 -> 168.69154 | K20: =K9*Assumptions!K41/100 -> 182.75226 | L20: =L9*Assumptions!L41/100 -> 196.3103 | M20: =M9*Assumptions!M41/100 -> 209.2154
B21: S&M % of Revenue | C21: % | D21: =D20/D9*100 -> 18.604086 | E21: =E20/E9*100 -> 19.848887 | F21: =F20/F9*100 -> 20.144274 | G21: =G20/G9*100 -> 21.115866 | H21: =H20/H9*100 -> 21.446719 | I21: =I20/I9*100 -> 21 | J21: =J20/J9*100 -> 21.125 | K21: =K20/K9*100 -> 21.25 | ... M21: =M20/M9*100 -> 21.5 | O21: From Assumptions scenario toggle. Key lever. Thesis question is whether S&M leverage is real.
B22: General & Administrative | C22: $M | D22: 76.3 | E22: 58 | F22: 61.7 | G22: 68.7 | H22: 71.6 | I22: =I9*Assumptions!I42/100 -> 77.140665 | J22: =J9*Assumptions!J42/100 -> 83.846682 | K22: =K9*Assumptions!K42/100 -> 86.001062 | L22: =L9*Assumptions!L42/100 -> 91.841078 | M22: =M9*Assumptions!M42/100 -> 97.309489
B23: G&A % of Revenue | C23: % | D23: =D22/D9*100 -> 18.555447 | E23: =E22/E9*100 -> 11.843986 | F23: =F22/F9*100 -> 11.127142 | G23: =G22/G9*100 -> 11.306781 | H23: =H22/H9*100 -> 10.700942 | I23: =I22/I9*100 -> 10.5 | J23: =J22/J9*100 -> 10.5 | K23: =K22/K9*100 -> 10 | ... M23: =M22/M9*100 -> 10 | O23: Hardcoded at 10%. Not in scenario toggle. Stable metric, not a key uncertainty.
B24: Total Operating Expenses | C24: $M | D24: =D18+D20+D22 -> 234.1 | E24: =E18+E20+E22 -> 256.4 | F24: =F18+F20+F22 -> 283.9 | G24: =G18+G20+G22 -> 308.9 | H24: =H18+H20+H22 -> 332.4 | I24: =I18+I20+I22 -> 359.98977 | J24: =J18+J20+J22 -> 392.28269 | K24: =K18+K20+K22 -> 419.25518 | ... M24: =M18+M20+M22 -> 476.8165
B25: OpEx % of Revenue | C25: % | D25: =D24/D9*100 -> 56.930934 | E25: =E24/E9*100 -> 52.358587 | F25: =F24/F9*100 -> 51.199279 | G25: =G24/G9*100 -> 50.839368 | H25: =H24/H9*100 -> 49.678673 | I25: =I24/I9*100 -> 49 | J25: =J24/J9*100 -> 49.125 | K25: =K24/K9*100 -> 48.75 | ... M25: =M24/M9*100 -> 49
B27: OPERATING INCOME
B28: Operating Income (EBIT) | C28: $M | D28: =D14-D24 -> 87.7 | E28: =E14-E24 -> 130.5 | F28: =F14-F24 -> 163.1 | G28: =G14-G24 -> 187.2 | H28: =H14-H24 -> 221.9 | I28: =I14-I24 -> 249.78882 | J28: =J14-J24 -> 273.49989 | K28: =K14-K24 -> 301.00372 | ... M28: =M14-M24 -> 345.44869
B29: Operating Margin % | C29: % | D29: =D28/D9*100 -> 21.327821 | E29: =E28/E9*100 -> 26.648969 | F29: =F28/F9*100 -> 29.413886 | G29: =G28/G9*100 -> 30.809743 | H29: =H28/H9*100 -> 33.163952 | I29: =I28/I9*100 -> 34 | J29: =J28/J9*100 -> 34.25 | K29: =K28/K9*100 -> 35 | ... M29: =M28/M9*100 -> 35.5
B31: BELOW THE LINE
B32: Interest Income | C32: $M | D32: 2.3 | E32: 5.2 | F32: 16.9 | G32: 25.8 | H32: 25.3 | I32: 23.5 | J32: 22 | K32: 20.5 | L32: 19 | M32: 17.5 | O32: QLYS has zero debt, so there's no interest expense. This is purely interest earned on their cash balance that is invested in low risk securities
B33: Other Income / (Expense) | C33: $M | D33: -0.6 | E33: -2 | F33: -1.3 | G33: -3.2 | H33: -0.4 | I33: -0.5 | J33: -0.5 | K33: -0.5 | L33: -0.5 | M33: -0.5 | O33: Mostly due to FX gains and losses
B34: Pre-Tax Income | C34: $M | D34: =D28+D32+D33 -> 89.4 | E34: =E28+E32+E33 -> 133.7 | F34: =F28+F32+F33 -> 178.7 | G34: =G28+G32+G33 -> 209.8 | H34: =H28+H32+H33 -> 246.8 | I34: =I28+I32+I33 -> 272.78882 | J34: =J28+J32+J33 -> 294.99989 | K34: =K28+K32+K33 -> 321.00372 | ... M34: =M28+M32+M33 -> 362.44869
B35: Income Tax Expense | C35: $M | D35: =D34*D36/100 -> 18.4164 | E35: =E34*E36/100 -> 25.6704 | F35: =F34*F36/100 -> 27.1624 | G35: =G34*G36/100 -> 36.0856 | H35: =H34*H36/100 -> 48.6196 | I35: =I34*I36/100 -> 54.557764 | J35: =J34*J36/100 -> 58.999978 | K35: =K34*K36/100 -> 64.200744 | ... M35: =M34*M36/100 -> 72.489737
B36: Effective Tax Rate | C36: % | D36: =Assumptions!D44 -> 20.6 | E36: =Assumptions!E44 -> 19.2 | F36: =Assumptions!F44 -> 15.2 | G36: =Assumptions!G44 -> 17.2 | H36: =Assumptions!H44 -> 19.7 | I36: =Assumptions!I44 -> 20 | J36: =Assumptions!J44 -> 20 | K36: =Assumptions!K44 -> 20 | ... M36: =Assumptions!M44 -> 20 | O36: Held flat at 20% in forward periods. Actuals fluctuate (15-21%) due to stock comp tax benefits and R&D credits.
B37: Net Income | C37: $M | D37: =D34-D35 -> 70.9836 | E37: =E34-E35 -> 108.0296 | F37: =F34-F35 -> 151.5376 | G37: =G34-G35 -> 173.7144 | H37: =H34-H35 -> 198.1804 | I37: =I34-I35 -> 218.23106 | J37: =J34-J35 -> 235.99991 | K37: =K34-K35 -> 256.80297 | ... M37: =M34-M35 -> 289.95895
B38: Net Margin % | C38: % | D38: =D37/D9*100 -> 17.262549 | E38: =E37/E9*100 -> 22.060363 | F38: =F37/F9*100 -> 27.328693 | G38: =G37/G9*100 -> 28.590257 | H38: =H37/H9*100 -> 29.618951 | I38: =I37/I9*100 -> 29.704516 | J38: =J37/J9*100 -> 29.553931 | K38: =K37/K9*100 -> 29.860442 | ... M38: =M37/M9*100 -> 29.797603
B40: PER SHARE
B41: Diluted Shares Outstanding | C41: M | D41: =Assumptions!D58 -> 40.1 | E41: =Assumptions!E58 -> 39.3 | F41: =Assumptions!F58 -> 37.6 | G41: =Assumptions!G58 -> 37.4 | H41: =Assumptions!H58 -> 36.5 | I41: =Assumptions!I58 -> 35.5 | J41: =Assumptions!J58 -> 34.8 | K41: =Assumptions!K58 -> 34.1 | ... M41: =Assumptions!M58 -> 32.9 | O41: Declines annually with ~$200M/year buyback on CF page, partially offset by SBC dilution.
B42: EPS (Diluted) | C42: $/sh | D42: =D37/D41 -> 1.7701646 | E42: =E37/E41 -> 2.7488448 | F42: =F37/F41 -> 4.0302553 | G42: =G37/G41 -> 4.6447701 | H42: =H37/H41 -> 5.4296 | I42: =I37/I41 -> 6.1473537 | J42: =J37/J41 -> 6.7816067 | K42: =K37/K41 -> 7.530879 | ... M42: =M37/M41 -> 8.8133419
B43: EPS Growth % | C43: % | E43: =(E42/D42-1)*100 -> 55.287525 | F43: =(F42/E42-1)*100 -> 46.616329 | G43: =(G42/F42-1)*100 -> 15.247539 | H43: =(H42/G42-1)*100 -> 16.897068 | I43: =(I42/H42-1)*100 -> 13.219274 | J43: =(J42/I42-1)*100 -> 10.317496 | K43: =(K42/J42-1)*100 -> 11.048596 | L43: =(L42/K42-1)*100 -> 8.5250573 | M43: =(M42/L42-1)*100 -> 7.8362866
B45: SUPPLEMENTAL
B46: Depreciation & Amortization | C46: $M | D46: 35.9 | E46: 34.6 | F46: 27 | G46: 18.5 | H46: 14.5 | I46: =I9*Assumptions!I51/100 -> 13.224114 | J46: =J9*Assumptions!J51/100 -> 11.978097 | K46: =K9*Assumptions!K51/100 -> 11.180138 | L46: =L9*Assumptions!L51/100 -> 11.020929 | M46: =M9*Assumptions!M51/100 -> 10.704044 | O46: Embedded inside Cost of Revenue, R&D, S&M, and G&A on the GAAP income statement. Broken out individually in CF Statement as Non-Cash Exp.
B47: EBITDA | C47: $M | D47: =D28+D46 -> 123.6 | E47: =E28+E46 -> 165.1 | F47: =F28+F46 -> 190.1 | G47: =G28+G46 -> 205.7 | H47: =H28+H46 -> 236.4 | I47: =I28+I46 -> 263.01293 | J47: =J28+J46 -> 285.47799 | K47: =K28+K46 -> 312.18386 | ... M47: =M28+M46 -> 356.15273
B48: EBITDA Margin % | C48: % | D48: =D47/D9*100 -> 30.058366 | E48: =E47/E9*100 -> 33.714519 | F48: =F47/F9*100 -> 34.283138 | G48: =G47/G9*100 -> 33.85451 | H48: =H47/H9*100 -> 35.331042 | I48: =I47/I9*100 -> 35.8 | J48: =J47/J9*100 -> 35.75 | K48: =K47/K9*100 -> 36.3 | ... M48: =M47/M9*100 -> 36.6
B49: Stock-Based Compensation | C49: $M | D49: 67.6 | E49: 53.4 | F49: 69.1 | G49: 77.1 | H49: 77 | I49: =I9*Assumptions!I52/100 -> 84.487395 | J49: =J9*Assumptions!J52/100 -> 87.839381 | K49: =K9*Assumptions!K52/100 -> 90.301115 | L49: =L9*Assumptions!L52/100 -> 91.841078 | M49: =M9*Assumptions!M52/100 -> 97.309489 | O49: Embedded inside Cost of Revenue, R&D, S&M, and G&A on the GAAP income statement. Broken out individually in CF Statement as Non-Cash Exp.
...

Sheet Balance Sheet
B2: Balance Sheet
B3: Qualys, Inc. (QLYS)
B4: All amounts in $ millions unless noted
C6: Units | D6: 2021A | E6: 2022A | F6: 2023A | G6: 2024A | H6: 2025A | I6: 2026E | J6: 2027E | K6: 2028E | L6: 2029E | M6: 2030E | O6: Notes
B8: CURRENT ASSETS
B9: Cash | C9: $M | E9: 176.5 | F9: 206.3 | G9: 233.4 | H9: 251.5 | I9: =H9+'Cash Flow'!I31 -> 321.12156 | J9: =I9+'Cash Flow'!J31 -> 413.93637 | K9: =J9+'Cash Flow'!K31 -> 520.60482 | L9: =K9+'Cash Flow'!L31 -> 635.90604 | M9: =L9+'Cash Flow'!M31 -> 767.22605 | O9: Cash + cash equiv + restricted cash (current) + ST marketable securities.
B10: Short-Term Investments | C10: $M | E10: 144.8 | F10: 220.8 | G10: 148 | H10: 194.4 | I10: =H10 -> 194.4 | J10: =I10 -> 194.4 | K10: =J10 -> 194.4 | L10: =K10 -> 194.4 | M10: =L10 -> 194.4
B11: Accounts Receivable | C11: $M | E11: 121.8 | F11: 146.2 | G11: 164.6 | H11: 171 | I11: ='Income Statement'!I9*Assumptions!I48/365 -> 187.19065 | J11: ='Income Statement'!J9*Assumptions!J48/365 -> 203.46357 | K11: ='Income Statement'!K9*Assumptions!K48/365 -> 219.12599 | L11: ='Income Statement'!L9*Assumptions!L48/365 -> 234.00603 | M11: ='Income Statement'!M9*Assumptions!M48/365 -> 247.93925 | O11: Forward: Revenue × DSO / 365.
B12: Prepaid & Other Current Assets | C12: $M | E12: 30.2 | F12: 26.7 | G12: 39.7 | H12: 40.7 | I12: 40.7 | J12: 40.7 | K12: 40.7 | L12: 40.7 | M12: 40.7 | O12: Held flat. Prepaid expenses and other. Stable at ~$40M.
B13: Total Current Assets | C13: $M | E13: =E9+E10+E11+E12 -> 473.3 | F13: =F9+F10+F11+F12 -> 600 | G13: =G9+G10+G11+G12 -> 585.7 | H13: =H9+H10+H11+H12 -> 657.6 | I13: =I9+I10+I11+I12 -> 743.41221 | J13: =J9+J10+J11+J12 -> 852.49995 | K13: =K9+K10+K11+K12 -> 974.83081 | L13: =L9+L10+L11+L12 -> 1105.0121 | M13: =M9+M10+M11+M12 -> 1250.2653
B15: NON-CURRENT ASSETS
B16: PP&E, net | C16: $M | E16: 47.4 | F16: 32.6 | G16: 30.3 | H16: 23.2 | I16: =H16+'Income Statement'!I9*Assumptions!I50/100-'Income Statement'!I46 -> 18.791962 | J16: =I16+'Income Statement'!J9*Assumptions!J50/100-'Income Statement'!J46 -> 16.396343 | K16: =J16+'Income Statement'!K9*Assumptions!K50/100-'Income Statement'!K46 -> 13.816311 | L16: =K16+'Income Statement'!L9*Assumptions!L50/100-'Income Statement'!L46 -> 11.979489 | M16: =L16+'Income Statement'!M9*Assumptions!M50/100-'Income Statement'!M46 -> 11.006394
B17: Goodwill & Intangibles | C17: $M | E17: 20.2 | F17: 17.2 | G17: 14.3 | H17: 11.7 | I17: 11.7 | J17: 11.7 | K17: 11.7 | L17: 11.7 | M17: 11.7 | O17: Held flat. No acquisitions assumed. Intangibles amortize down slightly but immaterial.
B18: Operating Lease ROU Assets | C18: $M | E18: 33.8 | F18: 22.4 | G18: 41 | H18: 46 | I18: 46 | J18: 46 | K18: 46 | L18: 46 | M18: 46 | O18: Held flat. Mirror of lease liabilities. Changes only with new lease agreements.
B19: Marketable Securities | C19: $M | E19: 126.2 | F19: 140.4 | G19: 302.3 | H19: 356.6 | I19: =H19-'Cash Flow'!I20 -> 403.97135 | J19: =I19-'Cash Flow'!J20 -> 456.45322 | K19: =J19-'Cash Flow'!K20 -> 512.08885 | L19: =K19-'Cash Flow'!L20 -> 570.23332 | M19: =L19-'Cash Flow'!M20 -> 631.30114 | O19: Includes long-term marketable securities, deferred tax assets, and other. Forward years grow as excess cash is invested in marketable securities (linked to CF net purchases).
B20: Total Assets | C20: $M | E20: 700.9 | F20: 812.6 | G20: 973.5 | H20: 1095.1 | I20: =I13+I16+I17+I18+I19 -> 1223.8755 | J20: =J13+J16+J17+J18+J19 -> 1383.0495 | K20: =K13+K16+K17+K18+K19 -> 1558.436 | L20: =L13+L16+L17+L18+L19 -> 1744.9249 | M20: =M13+M16+M17+M18+M19 -> 1950.2728
B22: CURRENT LIABILITIES
B23: Accounts Payable | C23: $M | E23: 2.8 | F23: 1 | G23: 1.3 | H23: 1.2 | I23: 1.2 | J23: 1.2 | K23: 1.2 | L23: 1.2 | M23: 1.2 | O23: Held flat. Minimal for a SaaS company with no inventory or physical supply chain.
B24: Accrued Liabilities | C24: $M | E24: 42.6 | F24: 43.1 | G24: 45.9 | H24: 57.7 | I24: =H24+(1*'Cash Flow'!I14) -> 50.35327 | J24: =I24+(1*'Cash Flow'!J14) -> 42.367872 | K24: =J24+(1*'Cash Flow'!K14) -> 33.767766 | L24: =K24+(1*'Cash Flow'!L14) -> 24.583658 | M24: =L24+(1*'Cash Flow'!M14) -> 14.852709 | O24: Linked to CF Other Working Capital Changes (prior period + CF change). Forward reflects small net cash outflows from accrued expenses, tax payables, and other accruals.
B25: Deferred Revenue (Current) | C25: $M | E25: 293.7 | F25: 333.3 | G25: 371.5 | H25: 401.1 | I25: ='Income Statement'!I9*Assumptions!I49/100*Assumptions!I53/100 -> 423.17165 | J25: ='Income Statement'!J9*Assumptions!J49/100*Assumptions!J53/100 -> 459.95894 | K25: ='Income Statement'!K9*Assumptions!K49/100*Assumptions!K53/100 -> 495.36612 | L25: ='Income Statement'!L9*Assumptions!L49/100*Assumptions!L53/100 -> 529.00461 | M25: ='Income Statement'!M9*Assumptions!M49/100*Assumptions!M53/100 -> 560.50266 | O25: BS = prior period + CF Change in Deferred Revenue. Represents billings collected but not yet recognized. Grows with subscription base.
B26: Current Lease Liabilities | C26: $M | E26: 13.1 | F26: 11.9 | G26: 9.7 | H26: 7.3 | I26: 7.4 | J26: 7.4 | K26: 7.4 | L26: 7.4 | M26: 7.4 | O26: Held flat. Annual lease payment obligations. Stable unless they sign or exit major leases.
B27: Total Current Liabilities | C27: $M | E27: 352.2 | F27: 389.2 | G27: 428.4 | H27: 467.3 | I27: =I23+I24+I25+I26 -> 482.12492 | J27: =J23+J24+J25+J26 -> 510.92681 | K27: =K23+K24+K25+K26 -> 537.73388 | L27: =L23+L24+L25+L26 -> 562.18827 | M27: =M23+M24+M25+M26 -> 583.95536
B29: NON-CURRENT LIABILITIES
B30: Deferred Revenue (Non-Current) | C30: $M | E30: 23.5 | F30: 31.7 | G30: 24.3 | H30: 16.3 | I30: ='Income Statement'!I9*Assumptions!I49/100*(1-Assumptions!I53/100) -> 17.632152 | J30: ='Income Statement'!J9*Assumptions!J49/100*(1-Assumptions!J53/100) -> 19.164956 | K30: ='Income Statement'!K9*Assumptions!K49/100*(1-Assumptions!K53/100) -> 20.640255 | L30: ='Income Statement'!L9*Assumptions!L49/100*(1-Assumptions!L53/100) -> 22.041859 | M30: ='Income Statement'!M9*Assumptions!M49/100*(1-Assumptions!M53/100) -> 23.354277 | O30: Multi-year prepaid subscriptions recognized beyond 12 months. Small relative to current DR. Most QLYS contracts are annual.
B31: Non-Current Lease Liabilities | C31: $M | E31: 29.1 | F31: 16.9 | G31: 37.5 | H31: 45 | I31: 45 | J31: 45 | K31: 45 | L31: 45 | M31: 45 | O31: Held flat. Long-term portion of operating leases (primarily offices). Jumped in 2024 from a new lease, now stable.
B32: Long-Term Debt | C32: $M | E32: 0 | F32: 0 | G32: 0 | H32: 0 | I32: 0 | J32: 0 | K32: 0 | L32: 0 | M32: 0 | O32: QLYS has zero debt across all periods.
B33: Other Non-Current Liabilities | C33: $M | E33: 7 | F33: 6.7 | G33: 6.3 | H33: 5.3 | I33: 5.3 | J33: 5.3 | K33: 5.3 | L33: 5.3 | M33: 5.3 | O33: Held flat. Declining slightly over time ($7M → $5.3M). Likely includes uncertain tax positions and other small items
B34: Total Liabilities | C34: $M | E34: 411.8 | F34: 444.4 | G34: 496.4 | H34: 533.9 | I34: =I27+I30+I31+I32+I33 -> 550.05707 | J34: =J27+J30+J31+J32+J33 -> 580.39177 | K34: =K27+K30+K31+K32+K33 -> 608.67414 | L34: =L27+L30+L31+L32+L33 -> 634.53013 | M34: =M27+M30+M31+M32+M33 -> 657.60964
B36: SHAREHOLDERS' EQUITY
B37: Common Stock & APIC | C37: $M | E37: 512.5 | F37: 598 | G37: 664.9 | H37: 731.8 | I37: =H37+'Income Statement'!I49+'Cash Flow'!I27 -> 811.28739 | J37: =I37+'Income Statement'!J49+'Cash Flow'!J27 -> 894.12678 | K37: =J37+'Income Statement'!K49+'Cash Flow'!K27 -> 979.42789 | L37: =K37+'Income Statement'!L49+'Cash Flow'!L27 -> 1066.269 | M37: =L37+'Income Statement'!M49+'Cash Flow'!M27 -> 1158.5785 | O37: Prior period + SBC + Other Financing (tax withholding on RSU vesting). Grows primarily with stock-based compensation, which is the main driver of APIC increases.
B38: Accumulated Deficit / Retained Earnings | C38: $M | E38: -221.4 | F38: -228.1 | G38: -189.2 | H38: -166.7 | I38: =H38+'Income Statement'!I37-Assumptions!I57 -> -133.46894 | J38: =I38+'Income Statement'!J37-Assumptions!J57 -> -87.469032 | K38: =J38+'Income Statement'!K37-Assumptions!K57 -> -25.666058 | L38: =K38+'Income Statement'!L37-Assumptions!L57 -> 48.125782 | M38: =L38+'Income Statement'!M37-Assumptions!M57 -> 138.08473 | O38: Repurchased shares retired (no treasury). Deficit shrinking as NI > buyback impact.
B39: Other Comprehensive Income/(Loss) | C39: $M | E39: -1.9 | F39: -1.7 | G39: 1.4 | H39: -4 | I39: -4 | J39: -4 | K39: -4 | L39: -4 | M39: -4 | O39: Held flat. FX translation adjustments on foreign subsidiaries. Small and volatile, not worth projecting.
B40: Total Shareholders' Equity | C40: $M | E40: 289.1 | F40: 368.2 | G40: 477.1 | H40: 561.2 | I40: =I37+I38+I39 -> 673.81845 | J40: =J37+J38+J39 -> 802.65774 | K40: =K37+K38+K39 -> 949.76183 | L40: =L37+L38+L39 -> 1110.3948 | M40: =M37+M38+M39 -> 1292.6632
B42: Total Liabilities + Equity | C42: $M | E42: =E34+E40 -> 700.9 | F42: =F34+F40 -> 812.6 | G42: =G34+G40 -> 973.5 | H42: =H34+H40 -> 1095.1 | I42: =I34+I40 -> 1223.8755 | J42: =J34+J40 -> 1383.0495 | K42: =K34+K40 -> 1558.436 | L42: =L34+L40 -> 1744.9249 | M42: =M34+M40 -> 1950.2728
B44: CHECK: Assets - (L+E) | E44: =E20-E42 -> 0 | F44: =F20-F42 -> 0 | G44: =G20-G42 -> 0 | H44: =H20-H42 -> 0 | I44: =I20-I42 -> 0 | J44: =J20-J42 -> 0 | K44: =K20-K42 -> 0 | L44: =L20-L42 -> 0 | M44: =M20-M42 -> 0
B45: CHECK: BS Cash vs CFS Ending Cash | E45: =E9-'Cash Flow'!E33 -> 0 | F45: =F9-'Cash Flow'!F33 -> 0 | G45: =G9-'Cash Flow'!G33 -> 0 | H45: =H9-'Cash Flow'!H33 -> 0 | I45: =I9-'Cash Flow'!I33 -> 0 | J45: =J9-'Cash Flow'!J33 -> 0 | K45: =K9-'Cash Flow'!K33 -> 0 | L45: =L9-'Cash Flow'!L33 -> 0 | M45: =M9-'Cash Flow'!M33 -> 0

Sheet Cash Flow
B2: Cash Flow Statement
B3: Qualys, Inc. (QLYS)
B4: All amounts in $ millions unless noted
C6: Units | D6: 2021A | E6: 2022A | F6: 2023A | G6: 2024A | H6: 2025A | I6: 2026E | J6: 2027E | K6: 2028E | L6: 2029E | M6: 2030E | O6: Notes
B8: OPERATING ACTIVITIES
B9: Net Income | C9: $M | D9: ='Income Statement'!D37 -> 70.9836 | E9: ='Income Statement'!E37 -> 108.0296 | F9: ='Income Statement'!F37 -> 151.5376 | G9: ='Income Statement'!G37 -> 173.7144 | H9: ='Income Statement'!H37 -> 198.1804 | I9: ='Income Statement'!I37 -> 218.23106 | J9: ='Income Statement'!J37 -> 235.99991 | K9: ='Income Statement'!K37 -> 256.80297 | ... M9: ='Income Statement'!M37 -> 289.95895
B10: Depreciation & Amortization | C10: $M | D10: ='Income Statement'!D46 -> 35.9 | E10: ='Income Statement'!E46 -> 34.6 | F10: ='Income Statement'!F46 -> 27 | G10: ='Income Statement'!G46 -> 18.5 | H10: ='Income Statement'!H46 -> 14.5 | I10: ='Income Statement'!I46 -> 13.224114 | J10: ='Income Statement'!J46 -> 11.978097 | K10: ='Income Statement'!K46 -> 11.180138 | ... M10: ='Income Statement'!M46 -> 10.704044 | O10: Forward grows with PP&E and capitalized software. Linked to Assumptions page.
B11: Stock-Based Compensation | C11: $M | D11: ='Income Statement'!D49 -> 67.6 | E11: ='Income Statement'!E49 -> 53.4 | F11: ='Income Statement'!F49 -> 69.1 | G11: ='Income Statement'!G49 -> 77.1 | H11: ='Income Statement'!H49 -> 77 | I11: ='Income Statement'!I49 -> 84.487395 | J11: ='Income Statement'!J49 -> 87.839381 | K11: ='Income Statement'!K49 -> 90.301115 | ... M11: ='Income Statement'!M49 -> 97.309489 | O11: Forward as % of revenue from Assumptions page. ~11% of revenue. Treated as real cost (FCF ex-SBC used in DCF).
B12: Change in Accounts Receivable | C12: $M | D12: -9.2 | E12: -13.4 | F12: -25 | G12: -19.1 | H12: -7.7 | I12: =-('Balance Sheet'!I11-'Balance Sheet'!H11) -> -16.190655 | J12: =-('Balance Sheet'!J11-'Balance Sheet'!I11) -> -16.272917 | K12: =-('Balance Sheet'!K11-'Balance Sheet'!J11) -> -15.662422 | L12: =-('Balance Sheet'!L11-'Balance Sheet'!K11) -> -14.880041 | M12: =-('Balance Sheet'!M11-'Balance Sheet'!L11) -> -13.933211 | O12: Actuals from 10-K CF. Forward estimated at ~1.3% of revenue.
B13: Change in Deferred Revenue | C13: $M | D13: 46.6 | E13: 25.2 | F13: 47.7 | G13: 30.8 | H13: 21.7 | I13: =('Balance Sheet'!I25+'Balance Sheet'!I30)-('Balance Sheet'!H25+'Balance Sheet'!H30) -> 23.4038 | J13: =('Balance Sheet'!J25+'Balance Sheet'!J30)-('Balance Sheet'!I25+'Balance Sheet'!I30) -> 38.320095 | K13: =('Balance Sheet'!K25+'Balance Sheet'!K30)-('Balance Sheet'!J25+'Balance Sheet'!J30) -> 36.882478 | L13: =('Balance Sheet'!L25+'Balance Sheet'!L30)-('Balance Sheet'!K25+'Balance Sheet'!K30) -> 35.040096 | M13: =('Balance Sheet'!M25+'Balance Sheet'!M30)-('Balance Sheet'!L25+'Balance Sheet'!L30) -> 32.810465 | O13: Actuals from 10-K CF. Forward estimated at ~3% of revenue.
B14: Other Working Capital Changes | C14: $M | D14: =D15-D9-D10-D11-D12-D13 -> -11.2836 | E14: =E15-E9-E10-E11-E12-E13 -> -8.9296 | F14: =F15-F9-F10-F11-F12-F13 -> -25.7376 | G14: =G15-G9-G10-G11-G12-G13 -> -36.9144 | H14: =H15-H9-H10-H11-H12-H13 -> 5.7196 | I14: ='Income Statement'!I9*-0.01 -> -7.34673 | J14: ='Income Statement'!J9*-0.01 -> -7.9853982 | K14: ='Income Statement'!K9*-0.01 -> -8.6001062 | L14: ='Income Statement'!L9*-0.01 -> -9.1841078 | M14: ='Income Statement'!M9*-0.01 -> -9.7309489 | O14: Actuals = CFO residual (accrued expenses, tax payables, etc.). Forward = -1% of revenue; offset flows through Accrued Liabilities on BS
B15: Cash from Operations (CFO) | C15: $M | D15: 200.6 | E15: 198.9 | F15: 244.6 | G15: 244.1 | H15: 309.4 | I15: =I9+I10+I11+I12+I13+I14 -> 315.80898 | J15: =J9+J10+J11+J12+J13+J14 -> 349.87917 | K15: =K9+K10+K11+K12+K13+K14 -> 370.90418 | L15: =L9+L10+L11+L12+L13+L14 -> 387.62979 | M15: =M9+M10+M11+M12+M13+M14 -> 407.11879 | O15: Actuals from 10-K. Forward = sum of components above.
B17: INVESTING ACTIVITIES
B18: Capital Expenditures | C18: $M | D18: -24.4 | E18: -15.4 | F18: -8.8 | G18: -12.3 | H18: -5 | I18: =-'Income Statement'!I9*Assumptions!I50/100 -> -8.816076 | J18: =-'Income Statement'!J9*Assumptions!J50/100 -> -9.5824779 | K18: =-'Income Statement'!K9*Assumptions!K50/100 -> -8.6001062 | L18: =-'Income Statement'!L9*Assumptions!L50/100 -> -9.1841078 | M18: =-'Income Statement'!M9*Assumptions!M50/100 -> -9.7309489 | O18: Actuals from 10-K. Forward = Revenue × Capex% assumption.
B19: Acquisitions | C19: $M | D19: -1.2 | E19: -8.6 | F19: 0 | G19: 0 | H19: 0 | I19: 0 | J19: 0 | K19: 0 | L19: 0 | M19: 0
B20: Net Purchases of Marketable Securities | C20: $M | D20: =D21-D18-D19 -> -3.9 | E20: =E21-E18-E19 -> 169.1 | F20: =F21-F18-F19 -> -64.4 | G20: =G21-G18-G19 -> -59.1 | H20: =H21-H18-H19 -> -100.9 | I20: =-I15*0.15 -> -47.371347 | J20: =-J15*0.15 -> -52.481875 | K20: =-K15*0.15 -> -55.635627 | L20: =-L15*0.15 -> -58.144469 | M20: =-M15*0.15 -> -61.067818 | O20: Actuals volatile — depends on treasury decisions. Forward = ~15% of CFO reinvested in securities (smoothing assumption).
B21: Cash from Investing (CFI) | C21: $M | D21: -29.5 | E21: 145.1 | F21: -73.2 | G21: -71.4 | H21: -105.9 | I21: =I18+I19+I20 -> -56.187423 | J21: =J18+J19+J20 -> -62.064353 | K21: =K18+K19+K20 -> -64.235733 | L21: =L18+L19+L20 -> -67.328577 | M21: =M18+M19+M20 -> -70.798767
B23: FINANCING ACTIVITIES
B24: Share Buybacks | C24: $M | D24: =-Assumptions!D57 -> -130 | E24: =-Assumptions!E57 -> -317.3 | F24: =-Assumptions!F57 -> -170.8 | G24: =-Assumptions!G57 -> -139.9 | H24: =-Assumptions!H57 -> -183.4 | I24: =-Assumptions!I57 -> -185 | J24: =-Assumptions!J57 -> -190 | K24: =-Assumptions!K57 -> -195 | ... M24: =-Assumptions!M57 -> -200 | O24: Forward held flat at ~$200M/year. QLYS has been a consistent repurchaser; no disclosed buyback program size to anchor to.
B25: Dividends Paid | C25: $M | D25: 0 | E25: 0 | F25: 0 | G25: 0 | H25: 0 | I25: 0 | J25: 0 | K25: 0 | L25: 0 | M25: 0 | O25: No Dividends - Use Buybacks to return $ to shareholders
B26: Debt Issuance / (Repayment) | C26: $M | D26: 0 | E26: 0 | F26: 0 | G26: 0 | H26: 0 | I26: 0 | J26: 0 | K26: 0 | L26: 0 | M26: 0 | O26: No Debt
B27: Other Financing (Options/ESPP/Tax Withholding) | C27: $M | D27: 22.1 | E27: 11.3 | F27: 29.3 | G27: -5.8 | H27: -2 | I27: -5 | J27: -5 | K27: -5 | L27: -5 | M27: -5 | O27: Net of option proceeds, ESPP proceeds, and tax withholding on RSU vesting.
B28: Cash from Financing (CFF) | C28: $M | D28: =D24+D25+D26+D27 -> -107.9 | E28: =E24+E25+E26+E27 -> -306 | F28: =F24+F25+F26+F27 -> -141.5 | G28: =G24+G25+G26+G27 -> -145.7 | H28: =H24+H25+H26+H27 -> -185.4 | I28: =I24+I25+I26+I27 -> -190 | J28: =J24+J25+J26+J27 -> -195 | K28: =K24+K25+K26+K27 -> -200 | ... M28: =M24+M25+M26+M27 -> -205
B30: SUMMARY
B31: Net Change in Cash | C31: $M | D31: =D15+D21+D28 -> 63.2 | E31: =E15+E21+E28 -> 38 | F31: =F15+F21+F28 -> 29.9 | G31: =G15+G21+G28 -> 27 | H31: =H15+H21+H28 -> 18.1 | I31: =I15+I21+I28 -> 69.621557 | J31: =J15+J21+J28 -> 92.814816 | K31: =K15+K21+K28 -> 106.66844 | ... M31: =M15+M21+M28 -> 131.32002
B32: Beginning Cash | C32: $M | D32: 75.3 | E32: 138.5 | F32: 176.4 | G32: 206.4 | H32: 233.4 | I32: =H33 -> 251.5 | J32: =I33 -> 321.12156 | K32: =J33 -> 413.93637 | L32: =K33 -> 520.60482 | M32: =L33 -> 635.90604
B33: Ending Cash | C33: $M | D33: =D32+D31 -> 138.5 | E33: =E32+E31 -> 176.5 | F33: =F32+F31 -> 206.3 | G33: =G32+G31 -> 233.4 | H33: =H32+H31 -> 251.5 | I33: =I32+I31 -> 321.12156 | J33: =J32+J31 -> 413.93637 | K33: =K32+K31 -> 520.60482 | ... M33: =M32+M31 -> 767.22605 | O33: Actuals = Cash + cash equiv + restricted cash from 10-K CF reconciliation. Forward = Beginning Cash + Net Change in Cash.
B35: FREE CASH FLOW
B36: Cash from Operations | C36: $M | D36: =D15 -> 200.6 | E36: =E15 -> 198.9 | F36: =F15 -> 244.6 | G36: =G15 -> 244.1 | H36: =H15 -> 309.4 | I36: =I15 -> 315.80898 | J36: =J15 -> 349.87917 | K36: =K15 -> 370.90418 | ... M36: =M15 -> 407.11879
B37: Less: Capital Expenditures | C37: $M | D37: =D18 -> -24.4 | E37: =E18 -> -15.4 | F37: =F18 -> -8.8 | G37: =G18 -> -12.3 | H37: =H18 -> -5 | I37: =I18 -> -8.816076 | J37: =J18 -> -9.5824779 | K37: =K18 -> -8.6001062 | ... M37: =M18 -> -9.7309489
B38: Free Cash Flow | C38: $M | D38: =D36+D37 -> 176.2 | E38: =E36+E37 -> 183.5 | F38: =F36+F37 -> 235.8 | G38: =G36+G37 -> 231.8 | H38: =H36+H37 -> 304.4 | I38: =I36+I37 -> 306.9929 | J38: =J36+J37 -> 340.29669 | K38: =K36+K37 -> 362.30407 | ... M38: =M36+M37 -> 397.38784
B39: FCF Margin % | C39: % | D39: =D38/'Income Statement'!D9*100 -> 42.850195 | E39: =E38/'Income Statement'!E9*100 -> 37.471922 | F39: =F38/'Income Statement'!F9*100 -> 42.524797 | G39: =G38/'Income Statement'!G9*100 -> 38.150099 | H39: =H38/'Income Statement'!H9*100 -> 45.493947 | I39: =I38/'Income Statement'!I9*100 -> 41.786333 | J39: =J38/'Income Statement'!J9*100 -> 42.614868 | K39: =K38/'Income Statement'!K9*100 -> 42.12786 | ... M39: =M38/'Income Statement'!M9*100 -> 40.837522
B40: FCF per Share | C40: $/sh | D40: =D38/Assumptions!D58 -> 4.394015 | E40: =E38/Assumptions!E58 -> 4.6692112 | F40: =F38/Assumptions!F58 -> 6.2712766 | G40: =G38/Assumptions!G58 -> 6.197861 | H40: =H38/Assumptions!H58 -> 8.339726 | I40: =I38/Assumptions!I58 -> 8.6476874 | J40: =J38/Assumptions!J58 -> 9.7786406 | K40: =K38/Assumptions!K58 -> 10.624753 | ... M40: =M38/Assumptions!M58 -> 12.078658 | O40: FCF / diluted shares outstanding. Share count declines with buybacks.
B42: FCF (ex-SBC) | C42: $M | D42: =D38-D11 -> 108.6 | E42: =E38-E11 -> 130.1 | F42: =F38-F11 -> 166.7 | G42: =G38-G11 -> 154.7 | H42: =H38-H11 -> 227.4 | I42: =I38-I11 -> 222.50551 | J42: =J38-J11 -> 252.45731 | K42: =K38-K11 -> 272.00296 | ... M42: =M38-M11 -> 300.07835 | O42: FCF minus stock-based compensation. Conservative measure for DCF.
B43: FCF (ex-SBC) Margin % | C43: % | D43: =D42/'Income Statement'!D9*100 -> 26.410506 | E43: =E42/'Income Statement'!E9*100 -> 26.567286 | F43: =F42/'Income Statement'!F9*100 -> 30.06312 | G43: =G42/'Income Statement'!G9*100 -> 25.460829 | H43: =H42/'Income Statement'!H9*100 -> 33.985951 | I43: =I42/'Income Statement'!I9*100 -> 30.286333 | J43: =J42/'Income Statement'!J9*100 -> 31.614868 | K43: =K42/'Income Statement'!K9*100 -> 31.62786 | ... M43: =M42/'Income Statement'!M9*100 -> 30.837522

Sheet DCF & Sensitivity
B2: DCF Valuation & Sensitivity Analysis
B3: Qualys, Inc. (QLYS)
B4: All amounts in $ millions unless noted
B6: TAKEAWAY
B7: At $80.52, the market implies EV of ~$2,241M, or 3.4x EV/Revenue, 9.5x EV/EBITDA, and 7.4x EV/FCF. This is a meaningful discount to cyber peers (24x EV/EBITDA median).
B8: Even the Bear scenario (NDER 95%, S&M deleverage, GM compression) implies $87–$98 / share, a 8–21% upside. Base case is $124–$169 (55–110% upside). To justify $80.52, you'd need a future scenario worse than the Bear: NDER below 95%, meaningful logo churn, or competitive displacement by PANW/CRWD.
B10: WACC CALCULATION
B11: Risk-Free Rate | C11: % | D11: =Assumptions!D60 -> 4.31
B12: Equity Risk Premium | C12: % | D12: =Assumptions!D61 -> 5.5
B13: Beta (Adjusted, peer-median) | C13: x | D13: =Assumptions!D63 -> 1
B14: Cost of Equity | C14: % | D14: =Assumptions!D64 -> 9.81
B15: Cost of Debt (pre-tax) | C15: % | D15: =Assumptions!D65 -> 0
B16: Tax Rate | C16: % | D16: =Assumptions!I44 -> 20
B17: Cost of Debt (after-tax) | C17: % | D17: =D15*(1-D16/100) -> 0
B18: Debt / Total Capital | C18: % | D18: =Assumptions!D66 -> 0
B19: Equity / Total Capital | C19: % | D19: =100-D18 -> 100
B20: WACC | C20: % | D20: =Assumptions!D67 -> 9.81
B22: FCF PROJECTION | C22: Units | D22: 2021A | E22: 2022A | F22: 2023A | G22: 2024A | H22: 2025A | I22: 2026E | J22: 2027E | K22: 2028E | L22: 2029E | M22: 2030E | O22: Notes
B23: Free Cash Flow (ex-SBC) | C23: $M | I23: ='Cash Flow'!I42 -> 222.50551 | J23: ='Cash Flow'!J42 -> 252.45731 | K23: ='Cash Flow'!K42 -> 272.00296 | L23: ='Cash Flow'!L42 -> 286.60461 | M23: ='Cash Flow'!M42 -> 300.07835 | O23: Uses FCF ex-SBC, not headline FCF. SBC is ~11% of revenue. Treating it as a real economic cost to shareholders.
B24: Discount Period | C24: # | I24: 1 | J24: 2 | K24: 3 | L24: 4 | M24: 5
B25: Discount Factor | C25: x | I25: =1/(1+$D$20/100)^I24 -> 0.91066387 | J25: =1/(1+$D$20/100)^J24 -> 0.82930869 | K25: =1/(1+$D$20/100)^K24 -> 0.75522147 | L25: =1/(1+$D$20/100)^L24 -> 0.68775291 | M25: =1/(1+$D$20/100)^M24 -> 0.62631173
B26: Present Value of FCF | C26: $M | I26: =I23*I25 -> 202.62773 | J26: =J23*J25 -> 209.36504 | K26: =K23*K25 -> 205.42247 | L26: =L23*L25 -> 197.11315 | M26: =M23*M25 -> 187.94259
B28: TERMINAL VALUE
B29: Method 1: Perpetuity Growth
B30: Terminal Growth Rate | C30: % | D30: =Assumptions!D68 -> 3
B31: Terminal FCF (ex-SBC) | C31: $M | D31: =M23 -> 300.07835
